0ms: PROCESS 8 ADDED TO READY QUEUE
0ms: PROCESS 82 ADDED TO READY QUEUE
0ms: PROCESS 82 DISPATCHED TO CPU
4ms: PROCESS 43 ADDED TO READY QUEUE
7ms: PROCESS 29 ADDED TO READY QUEUE
8ms: PROCESS 67 ADDED TO READY QUEUE
8ms: PROCESS 82 PREMPTED
8ms: PROCESS 67 DISPATCHED TO CPU
8ms: PROCESS 82 ADDED TO READY QUEUE
11ms: PROCESS 21 ADDED TO READY QUEUE
11ms: PROCESS 57 ADDED TO READY QUEUE
15ms: PROCESS 93 ADDED TO READY QUEUE
18ms: PROCESS 44 ADDED TO READY QUEUE
21ms: PROCESS 0 ADDED TO READY QUEUE
21ms: PROCESS 28 ADDED TO READY QUEUE
23ms: PROCESS 67 SENT TO IO QUEUE
23ms: PROCESS 57 DISPATCHED TO CPU
31ms: PROCESS 67 ADDED TO READY QUEUE
31ms: PROCESS 67 DONE WITH IO
32ms: PROCESS 61 ADDED TO READY QUEUE
33ms: PROCESS 87 ADDED TO READY QUEUE
34ms: PROCESS 37 ADDED TO READY QUEUE
36ms: PROCESS 57 SENT TO IO QUEUE
36ms: PROCESS 67 DISPATCHED TO CPU
42ms: PROCESS 57 ADDED TO READY QUEUE
42ms: PROCESS 57 DONE WITH IO
43ms: PROCESS 22 ADDED TO READY QUEUE
50ms: PROCESS 56 ADDED TO READY QUEUE
55ms: PROCESS 6 ADDED TO READY QUEUE
59ms: PROCESS 63 ADDED TO READY QUEUE
59ms: PROCESS 79 ADDED TO READY QUEUE
59ms: PROCESS 89 ADDED TO READY QUEUE
59ms: PROCESS 67 PREMPTED
59ms: PROCESS 63 DISPATCHED TO CPU
59ms: PROCESS 67 ADDED TO READY QUEUE
62ms: PROCESS 94 ADDED TO READY QUEUE
64ms: PROCESS 33 ADDED TO READY QUEUE
69ms: PROCESS 3 ADDED TO READY QUEUE
73ms: PROCESS 9 ADDED TO READY QUEUE
73ms: PROCESS 20 ADDED TO READY QUEUE
74ms: PROCESS 10 ADDED TO READY QUEUE
74ms: PROCESS 11 ADDED TO READY QUEUE
74ms: PROCESS 86 ADDED TO READY QUEUE
75ms: PROCESS 63 SENT TO IO QUEUE
75ms: PROCESS 79 DISPATCHED TO CPU
76ms: PROCESS 74 ADDED TO READY QUEUE
77ms: PROCESS 71 ADDED TO READY QUEUE
80ms: PROCESS 66 ADDED TO READY QUEUE
83ms: PROCESS 7 ADDED TO READY QUEUE
84ms: PROCESS 79 SENT TO IO QUEUE
84ms: PROCESS 57 DISPATCHED TO CPU
88ms: PROCESS 26 ADDED TO READY QUEUE
90ms: PROCESS 13 ADDED TO READY QUEUE
92ms: PROCESS 60 ADDED TO READY QUEUE
92ms: PROCESS 63 ADDED TO READY QUEUE
92ms: PROCESS 63 DONE WITH IO
93ms: PROCESS 57 PREMPTED
93ms: PROCESS 63 DISPATCHED TO CPU
93ms: PROCESS 57 ADDED TO READY QUEUE
94ms: PROCESS 40 ADDED TO READY QUEUE
94ms: PROCESS 79 ADDED TO READY QUEUE
94ms: PROCESS 79 DONE WITH IO
95ms: PROCESS 39 ADDED TO READY QUEUE
103ms: PROCESS 47 ADDED TO READY QUEUE
106ms: PROCESS 48 ADDED TO READY QUEUE
107ms: PROCESS 50 ADDED TO READY QUEUE
109ms: PROCESS 41 ADDED TO READY QUEUE
110ms: PROCESS 49 ADDED TO READY QUEUE
110ms: PROCESS 63 SENT TO IO QUEUE
110ms: PROCESS 79 DISPATCHED TO CPU
119ms: PROCESS 58 ADDED TO READY QUEUE
120ms: PROCESS 77 ADDED TO READY QUEUE
125ms: PROCESS 35 ADDED TO READY QUEUE
125ms: PROCESS 95 ADDED TO READY QUEUE
126ms: PROCESS 30 ADDED TO READY QUEUE
126ms: PROCESS 79 SENT TO IO QUEUE
126ms: PROCESS 48 DISPATCHED TO CPU
132ms: PROCESS 38 ADDED TO READY QUEUE
132ms: PROCESS 59 ADDED TO READY QUEUE
133ms: PROCESS 54 ADDED TO READY QUEUE
134ms: PROCESS 63 ADDED TO READY QUEUE
134ms: PROCESS 63 DONE WITH IO
139ms: PROCESS 84 ADDED TO READY QUEUE
142ms: PROCESS 79 ADDED TO READY QUEUE
142ms: PROCESS 79 DONE WITH IO
143ms: PROCESS 92 ADDED TO READY QUEUE
145ms: PROCESS 81 ADDED TO READY QUEUE
146ms: PROCESS 4 ADDED TO READY QUEUE
149ms: PROCESS 85 ADDED TO READY QUEUE
149ms: PROCESS 97 ADDED TO READY QUEUE
149ms: PROCESS 48 SENT TO IO QUEUE
149ms: PROCESS 63 DISPATCHED TO CPU
152ms: PROCESS 72 ADDED TO READY QUEUE
153ms: PROCESS 25 ADDED TO READY QUEUE
154ms: PROCESS 64 ADDED TO READY QUEUE
154ms: PROCESS 73 ADDED TO READY QUEUE
154ms: PROCESS 98 ADDED TO READY QUEUE
158ms: PROCESS 14 ADDED TO READY QUEUE
160ms: PROCESS 75 ADDED TO READY QUEUE
161ms: PROCESS 78 ADDED TO READY QUEUE
164ms: PROCESS 48 ADDED TO READY QUEUE
164ms: PROCESS 48 DONE WITH IO
165ms: PROCESS 42 ADDED TO READY QUEUE
166ms: PROCESS 2 ADDED TO READY QUEUE
166ms: PROCESS 90 ADDED TO READY QUEUE
167ms: PROCESS 24 ADDED TO READY QUEUE
167ms: PROCESS 88 ADDED TO READY QUEUE
170ms: PROCESS 31 ADDED TO READY QUEUE
171ms: PROCESS 63 SENT TO IO QUEUE
171ms: PROCESS 84 DISPATCHED TO CPU
172ms: PROCESS 80 ADDED TO READY QUEUE
175ms: PROCESS 68 ADDED TO READY QUEUE
179ms: PROCESS 63 ADDED TO READY QUEUE
179ms: PROCESS 63 DONE WITH IO
182ms: PROCESS 32 ADDED TO READY QUEUE
186ms: PROCESS 36 ADDED TO READY QUEUE
193ms: PROCESS 69 ADDED TO READY QUEUE
193ms: PROCESS 84 SENT TO IO QUEUE
193ms: PROCESS 79 DISPATCHED TO CPU
194ms: PROCESS 12 ADDED TO READY QUEUE
195ms: PROCESS 17 ADDED TO READY QUEUE
195ms: PROCESS 84 ADDED TO READY QUEUE
195ms: PROCESS 84 DONE WITH IO
196ms: PROCESS 65 ADDED TO READY QUEUE
197ms: PROCESS 83 ADDED TO READY QUEUE
200ms: PROCESS 18 ADDED TO READY QUEUE
200ms: PROCESS 70 ADDED TO READY QUEUE
202ms: PROCESS 79 SENT TO IO QUEUE
202ms: PROCESS 73 DISPATCHED TO CPU
206ms: PROCESS 79 ADDED TO READY QUEUE
206ms: PROCESS 79 DONE WITH IO
207ms: PROCESS 1 ADDED TO READY QUEUE
213ms: PROCESS 53 ADDED TO READY QUEUE
213ms: PROCESS 55 ADDED TO READY QUEUE
217ms: PROCESS 51 ADDED TO READY QUEUE
217ms: PROCESS 96 ADDED TO READY QUEUE
218ms: PROCESS 19 ADDED TO READY QUEUE
218ms: PROCESS 73 SENT TO IO QUEUE
218ms: PROCESS 48 DISPATCHED TO CPU
219ms: PROCESS 16 ADDED TO READY QUEUE
224ms: PROCESS 91 ADDED TO READY QUEUE
225ms: PROCESS 45 ADDED TO READY QUEUE
226ms: PROCESS 52 ADDED TO READY QUEUE
228ms: PROCESS 34 ADDED TO READY QUEUE
228ms: PROCESS 48 SENT TO IO QUEUE
228ms: PROCESS 63 DISPATCHED TO CPU
233ms: PROCESS 62 ADDED TO READY QUEUE
233ms: PROCESS 99 ADDED TO READY QUEUE
234ms: PROCESS 63 FINISHED, TURNAROUND: 0ms, CPU WAIT: 66ms, IO WAIT: 49ms
234ms: PROCESS 32 DISPATCHED TO CPU
235ms: PROCESS 27 ADDED TO READY QUEUE
235ms: PROCESS 32 SENT TO IO QUEUE
235ms: PROCESS 84 DISPATCHED TO CPU
236ms: PROCESS 15 ADDED TO READY QUEUE
238ms: PROCESS 5 ADDED TO READY QUEUE
239ms: PROCESS 46 ADDED TO READY QUEUE
239ms: PROCESS 73 ADDED TO READY QUEUE
239ms: PROCESS 73 DONE WITH IO
241ms: PROCESS 23 ADDED TO READY QUEUE
242ms: PROCESS 76 ADDED TO READY QUEUE
249ms: PROCESS 48 ADDED TO READY QUEUE
249ms: PROCESS 48 DONE WITH IO
257ms: PROCESS 84 SENT TO IO QUEUE
257ms: PROCESS 79 DISPATCHED TO CPU
260ms: PROCESS 79 SENT TO IO QUEUE
260ms: PROCESS 73 DISPATCHED TO CPU
261ms: PROCESS 73 SENT TO IO QUEUE
261ms: PROCESS 48 DISPATCHED TO CPU
265ms: PROCESS 32 ADDED TO READY QUEUE
265ms: PROCESS 32 DONE WITH IO
278ms: PROCESS 48 SENT TO IO QUEUE
278ms: PROCESS 32 DISPATCHED TO CPU
279ms: PROCESS 84 ADDED TO READY QUEUE
279ms: PROCESS 84 DONE WITH IO
282ms: PROCESS 79 ADDED TO READY QUEUE
282ms: PROCESS 79 DONE WITH IO
290ms: PROCESS 73 ADDED TO READY QUEUE
290ms: PROCESS 73 DONE WITH IO
302ms: PROCESS 32 SENT TO IO QUEUE
302ms: PROCESS 84 DISPATCHED TO CPU
308ms: PROCESS 48 ADDED TO READY QUEUE
308ms: PROCESS 48 DONE WITH IO
317ms: PROCESS 84 SENT TO IO QUEUE
317ms: PROCESS 79 DISPATCHED TO CPU
327ms: PROCESS 79 SENT TO IO QUEUE
327ms: PROCESS 73 DISPATCHED TO CPU
327ms: PROCESS 32 ADDED TO READY QUEUE
327ms: PROCESS 32 DONE WITH IO
343ms: PROCESS 73 SENT TO IO QUEUE
343ms: PROCESS 48 DISPATCHED TO CPU
345ms: PROCESS 48 SENT TO IO QUEUE
345ms: PROCESS 32 DISPATCHED TO CPU
348ms: PROCESS 84 ADDED TO READY QUEUE
348ms: PROCESS 84 DONE WITH IO
355ms: PROCESS 79 ADDED TO READY QUEUE
355ms: PROCESS 79 DONE WITH IO
365ms: PROCESS 73 ADDED TO READY QUEUE
365ms: PROCESS 73 DONE WITH IO
369ms: PROCESS 48 ADDED TO READY QUEUE
369ms: PROCESS 48 DONE WITH IO
370ms: PROCESS 32 SENT TO IO QUEUE
370ms: PROCESS 84 DISPATCHED TO CPU
380ms: PROCESS 84 SENT TO IO QUEUE
380ms: PROCESS 79 DISPATCHED TO CPU
388ms: PROCESS 32 ADDED TO READY QUEUE
388ms: PROCESS 32 DONE WITH IO
402ms: PROCESS 79 SENT TO IO QUEUE
402ms: PROCESS 73 DISPATCHED TO CPU
407ms: PROCESS 84 ADDED TO READY QUEUE
407ms: PROCESS 84 DONE WITH IO
413ms: PROCESS 73 SENT TO IO QUEUE
413ms: PROCESS 48 DISPATCHED TO CPU
423ms: PROCESS 48 SENT TO IO QUEUE
423ms: PROCESS 32 DISPATCHED TO CPU
427ms: PROCESS 79 ADDED TO READY QUEUE
427ms: PROCESS 79 DONE WITH IO
448ms: PROCESS 32 SENT TO IO QUEUE
448ms: PROCESS 84 DISPATCHED TO CPU
451ms: PROCESS 73 ADDED TO READY QUEUE
451ms: PROCESS 73 DONE WITH IO
460ms: PROCESS 48 ADDED TO READY QUEUE
460ms: PROCESS 48 DONE WITH IO
462ms: PROCESS 84 SENT TO IO QUEUE
462ms: PROCESS 79 DISPATCHED TO CPU
470ms: PROCESS 32 ADDED TO READY QUEUE
470ms: PROCESS 32 DONE WITH IO
474ms: PROCESS 79 SENT TO IO QUEUE
474ms: PROCESS 73 DISPATCHED TO CPU
483ms: PROCESS 73 SENT TO IO QUEUE
483ms: PROCESS 48 DISPATCHED TO CPU
490ms: PROCESS 84 ADDED TO READY QUEUE
490ms: PROCESS 84 DONE WITH IO
492ms: PROCESS 79 ADDED TO READY QUEUE
492ms: PROCESS 79 DONE WITH IO
508ms: PROCESS 48 SENT TO IO QUEUE
508ms: PROCESS 32 DISPATCHED TO CPU
509ms: PROCESS 73 ADDED TO READY QUEUE
509ms: PROCESS 73 DONE WITH IO
511ms: PROCESS 32 SENT TO IO QUEUE
511ms: PROCESS 84 DISPATCHED TO CPU
513ms: PROCESS 48 ADDED TO READY QUEUE
513ms: PROCESS 48 DONE WITH IO
519ms: PROCESS 32 ADDED TO READY QUEUE
519ms: PROCESS 32 DONE WITH IO
523ms: PROCESS 84 FINISHED, TURNAROUND: 0ms, CPU WAIT: 180ms, IO WAIT: 110ms
523ms: PROCESS 79 DISPATCHED TO CPU
534ms: PROCESS 79 SENT TO IO QUEUE
534ms: PROCESS 73 DISPATCHED TO CPU
538ms: PROCESS 79 ADDED TO READY QUEUE
538ms: PROCESS 79 DONE WITH IO
548ms: PROCESS 73 SENT TO IO QUEUE
548ms: PROCESS 48 DISPATCHED TO CPU
549ms: PROCESS 48 SENT TO IO QUEUE
549ms: PROCESS 32 DISPATCHED TO CPU
565ms: PROCESS 32 SENT TO IO QUEUE
565ms: PROCESS 79 DISPATCHED TO CPU
568ms: PROCESS 73 ADDED TO READY QUEUE
568ms: PROCESS 73 DONE WITH IO
581ms: PROCESS 48 ADDED TO READY QUEUE
581ms: PROCESS 48 DONE WITH IO
585ms: PROCESS 79 SENT TO IO QUEUE
585ms: PROCESS 73 DISPATCHED TO CPU
596ms: PROCESS 32 ADDED TO READY QUEUE
596ms: PROCESS 32 DONE WITH IO
605ms: PROCESS 73 FINISHED, TURNAROUND: 0ms, CPU WAIT: 209ms, IO WAIT: 156ms
605ms: PROCESS 48 DISPATCHED TO CPU
614ms: PROCESS 79 ADDED TO READY QUEUE
614ms: PROCESS 79 DONE WITH IO
623ms: PROCESS 48 SENT TO IO QUEUE
623ms: PROCESS 32 DISPATCHED TO CPU
636ms: PROCESS 32 SENT TO IO QUEUE
636ms: PROCESS 79 DISPATCHED TO CPU
646ms: PROCESS 48 ADDED TO READY QUEUE
646ms: PROCESS 48 DONE WITH IO
651ms: PROCESS 79 SENT TO IO QUEUE
651ms: PROCESS 48 DISPATCHED TO CPU
651ms: PROCESS 32 ADDED TO READY QUEUE
651ms: PROCESS 32 DONE WITH IO
652ms: PROCESS 48 SENT TO IO QUEUE
652ms: PROCESS 32 DISPATCHED TO CPU
656ms: PROCESS 79 ADDED TO READY QUEUE
656ms: PROCESS 79 DONE WITH IO
661ms: PROCESS 32 SENT TO IO QUEUE
661ms: PROCESS 79 DISPATCHED TO CPU
670ms: PROCESS 48 ADDED TO READY QUEUE
670ms: PROCESS 48 DONE WITH IO
675ms: PROCESS 79 FINISHED, TURNAROUND: 0ms, CPU WAIT: 315ms, IO WAIT: 161ms
675ms: PROCESS 48 DISPATCHED TO CPU
680ms: PROCESS 32 ADDED TO READY QUEUE
680ms: PROCESS 32 DONE WITH IO
697ms: PROCESS 48 SENT TO IO QUEUE
697ms: PROCESS 32 DISPATCHED TO CPU
699ms: PROCESS 32 SENT TO IO QUEUE
699ms: PROCESS 67 DISPATCHED TO CPU
701ms: PROCESS 67 SENT TO IO QUEUE
701ms: PROCESS 94 DISPATCHED TO CPU
717ms: PROCESS 94 SENT TO IO QUEUE
717ms: PROCESS 10 DISPATCHED TO CPU
720ms: PROCESS 48 ADDED TO READY QUEUE
720ms: PROCESS 48 DONE WITH IO
721ms: PROCESS 10 PREMPTED
721ms: PROCESS 48 DISPATCHED TO CPU
721ms: PROCESS 10 ADDED TO READY QUEUE
734ms: PROCESS 48 FINISHED, TURNAROUND: 0ms, CPU WAIT: 259ms, IO WAIT: 228ms
734ms: PROCESS 11 DISPATCHED TO CPU
736ms: PROCESS 32 ADDED TO READY QUEUE
736ms: PROCESS 32 DONE WITH IO
737ms: PROCESS 11 PREMPTED
737ms: PROCESS 32 DISPATCHED TO CPU
737ms: PROCESS 11 ADDED TO READY QUEUE
750ms: PROCESS 32 FINISHED, TURNAROUND: 0ms, CPU WAIT: 233ms, IO WAIT: 205ms
750ms: PROCESS 57 DISPATCHED TO CPU
750ms: PROCESS 67 ADDED TO READY QUEUE
750ms: PROCESS 67 DONE WITH IO
767ms: PROCESS 57 SENT TO IO QUEUE
767ms: PROCESS 36 DISPATCHED TO CPU
769ms: PROCESS 94 ADDED TO READY QUEUE
769ms: PROCESS 94 DONE WITH IO
774ms: PROCESS 57 ADDED TO READY QUEUE
774ms: PROCESS 57 DONE WITH IO
785ms: PROCESS 36 SENT TO IO QUEUE
785ms: PROCESS 70 DISPATCHED TO CPU
789ms: PROCESS 36 ADDED TO READY QUEUE
789ms: PROCESS 36 DONE WITH IO
808ms: PROCESS 70 SENT TO IO QUEUE
808ms: PROCESS 53 DISPATCHED TO CPU
815ms: PROCESS 53 SENT TO IO QUEUE
815ms: PROCESS 23 DISPATCHED TO CPU
818ms: PROCESS 70 ADDED TO READY QUEUE
818ms: PROCESS 70 DONE WITH IO
823ms: PROCESS 53 ADDED TO READY QUEUE
823ms: PROCESS 53 DONE WITH IO
827ms: PROCESS 23 SENT TO IO QUEUE
827ms: PROCESS 76 DISPATCHED TO CPU
830ms: PROCESS 23 ADDED TO READY QUEUE
830ms: PROCESS 23 DONE WITH IO
847ms: PROCESS 76 SENT TO IO QUEUE
847ms: PROCESS 10 DISPATCHED TO CPU
867ms: PROCESS 10 SENT TO IO QUEUE
867ms: PROCESS 11 DISPATCHED TO CPU
871ms: PROCESS 76 ADDED TO READY QUEUE
871ms: PROCESS 76 DONE WITH IO
881ms: PROCESS 11 SENT TO IO QUEUE
881ms: PROCESS 67 DISPATCHED TO CPU
892ms: PROCESS 67 SENT TO IO QUEUE
892ms: PROCESS 94 DISPATCHED TO CPU
894ms: PROCESS 94 SENT TO IO QUEUE
894ms: PROCESS 57 DISPATCHED TO CPU
894ms: PROCESS 10 ADDED TO READY QUEUE
894ms: PROCESS 10 DONE WITH IO
907ms: PROCESS 57 SENT TO IO QUEUE
907ms: PROCESS 36 DISPATCHED TO CPU
913ms: PROCESS 36 FINISHED, TURNAROUND: 0ms, CPU WAIT: 700ms, IO WAIT: 4ms
913ms: PROCESS 70 DISPATCHED TO CPU
919ms: PROCESS 11 ADDED TO READY QUEUE
919ms: PROCESS 11 DONE WITH IO
922ms: PROCESS 70 SENT TO IO QUEUE
922ms: PROCESS 53 DISPATCHED TO CPU
930ms: PROCESS 53 SENT TO IO QUEUE
930ms: PROCESS 23 DISPATCHED TO CPU
932ms: PROCESS 23 SENT TO IO QUEUE
932ms: PROCESS 76 DISPATCHED TO CPU
942ms: PROCESS 76 SENT TO IO QUEUE
942ms: PROCESS 10 DISPATCHED TO CPU
943ms: PROCESS 67 ADDED TO READY QUEUE
943ms: PROCESS 67 DONE WITH IO
953ms: PROCESS 10 SENT TO IO QUEUE
953ms: PROCESS 11 DISPATCHED TO CPU
961ms: PROCESS 94 ADDED TO READY QUEUE
961ms: PROCESS 94 DONE WITH IO
971ms: PROCESS 11 SENT TO IO QUEUE
971ms: PROCESS 67 DISPATCHED TO CPU
974ms: PROCESS 57 ADDED TO READY QUEUE
974ms: PROCESS 57 DONE WITH IO
979ms: PROCESS 67 SENT TO IO QUEUE
979ms: PROCESS 94 DISPATCHED TO CPU
989ms: PROCESS 70 ADDED TO READY QUEUE
989ms: PROCESS 70 DONE WITH IO
996ms: PROCESS 53 ADDED TO READY QUEUE
996ms: PROCESS 53 DONE WITH IO
1000ms: PROCESS 23 ADDED TO READY QUEUE
1000ms: PROCESS 23 DONE WITH IO
1003ms: PROCESS 94 SENT TO IO QUEUE
1003ms: PROCESS 57 DISPATCHED TO CPU
1008ms: PROCESS 76 ADDED TO READY QUEUE
1008ms: PROCESS 76 DONE WITH IO
1016ms: PROCESS 10 ADDED TO READY QUEUE
1016ms: PROCESS 10 DONE WITH IO
1026ms: PROCESS 11 ADDED TO READY QUEUE
1026ms: PROCESS 11 DONE WITH IO
1028ms: PROCESS 57 SENT TO IO QUEUE
1028ms: PROCESS 70 DISPATCHED TO CPU
1031ms: PROCESS 67 ADDED TO READY QUEUE
1031ms: PROCESS 67 DONE WITH IO
1036ms: PROCESS 70 SENT TO IO QUEUE
1036ms: PROCESS 53 DISPATCHED TO CPU
1040ms: PROCESS 53 SENT TO IO QUEUE
1040ms: PROCESS 23 DISPATCHED TO CPU
1044ms: PROCESS 94 ADDED TO READY QUEUE
1044ms: PROCESS 94 DONE WITH IO
1053ms: PROCESS 57 ADDED TO READY QUEUE
1053ms: PROCESS 57 DONE WITH IO
1056ms: PROCESS 70 ADDED TO READY QUEUE
1056ms: PROCESS 70 DONE WITH IO
1064ms: PROCESS 53 ADDED TO READY QUEUE
1064ms: PROCESS 53 DONE WITH IO
1065ms: PROCESS 23 SENT TO IO QUEUE
1065ms: PROCESS 76 DISPATCHED TO CPU
1072ms: PROCESS 23 ADDED TO READY QUEUE
1072ms: PROCESS 23 DONE WITH IO
1074ms: PROCESS 76 FINISHED, TURNAROUND: 0ms, CPU WAIT: 704ms, IO WAIT: 90ms
1074ms: PROCESS 10 DISPATCHED TO CPU
1097ms: PROCESS 10 FINISHED, TURNAROUND: 0ms, CPU WAIT: 876ms, IO WAIT: 90ms
1097ms: PROCESS 11 DISPATCHED TO CPU
1102ms: PROCESS 11 SENT TO IO QUEUE
1102ms: PROCESS 67 DISPATCHED TO CPU
1110ms: PROCESS 67 SENT TO IO QUEUE
1110ms: PROCESS 94 DISPATCHED TO CPU
1113ms: PROCESS 11 ADDED TO READY QUEUE
1113ms: PROCESS 11 DONE WITH IO
1124ms: PROCESS 67 ADDED TO READY QUEUE
1124ms: PROCESS 67 DONE WITH IO
1130ms: PROCESS 94 SENT TO IO QUEUE
1130ms: PROCESS 57 DISPATCHED TO CPU
1138ms: PROCESS 94 ADDED TO READY QUEUE
1138ms: PROCESS 94 DONE WITH IO
1143ms: PROCESS 57 SENT TO IO QUEUE
1143ms: PROCESS 70 DISPATCHED TO CPU
1152ms: PROCESS 57 ADDED TO READY QUEUE
1152ms: PROCESS 57 DONE WITH IO
1166ms: PROCESS 70 SENT TO IO QUEUE
1166ms: PROCESS 53 DISPATCHED TO CPU
1180ms: PROCESS 70 ADDED TO READY QUEUE
1180ms: PROCESS 70 DONE WITH IO
1189ms: PROCESS 53 SENT TO IO QUEUE
1189ms: PROCESS 23 DISPATCHED TO CPU
1197ms: PROCESS 53 ADDED TO READY QUEUE
1197ms: PROCESS 53 DONE WITH IO
1213ms: PROCESS 23 SENT TO IO QUEUE
1213ms: PROCESS 11 DISPATCHED TO CPU
1217ms: PROCESS 11 FINISHED, TURNAROUND: 0ms, CPU WAIT: 996ms, IO WAIT: 104ms
1217ms: PROCESS 67 DISPATCHED TO CPU
1228ms: PROCESS 23 ADDED TO READY QUEUE
1228ms: PROCESS 23 DONE WITH IO
1230ms: PROCESS 67 SENT TO IO QUEUE
1230ms: PROCESS 94 DISPATCHED TO CPU
1248ms: PROCESS 67 ADDED TO READY QUEUE
1248ms: PROCESS 67 DONE WITH IO
1253ms: PROCESS 94 SENT TO IO QUEUE
1253ms: PROCESS 57 DISPATCHED TO CPU
1255ms: PROCESS 94 ADDED TO READY QUEUE
1255ms: PROCESS 94 DONE WITH IO
1277ms: PROCESS 57 SENT TO IO QUEUE
1277ms: PROCESS 70 DISPATCHED TO CPU
1279ms: PROCESS 70 SENT TO IO QUEUE
1279ms: PROCESS 53 DISPATCHED TO CPU
1292ms: PROCESS 53 SENT TO IO QUEUE
1292ms: PROCESS 23 DISPATCHED TO CPU
1299ms: PROCESS 23 SENT TO IO QUEUE
1299ms: PROCESS 67 DISPATCHED TO CPU
1301ms: PROCESS 57 ADDED TO READY QUEUE
1301ms: PROCESS 57 DONE WITH IO
1307ms: PROCESS 67 FINISHED, TURNAROUND: 0ms, CPU WAIT: 1020ms, IO WAIT: 192ms
1307ms: PROCESS 94 DISPATCHED TO CPU
1309ms: PROCESS 70 ADDED TO READY QUEUE
1309ms: PROCESS 70 DONE WITH IO
1312ms: PROCESS 94 SENT TO IO QUEUE
1312ms: PROCESS 57 DISPATCHED TO CPU
1329ms: PROCESS 53 ADDED TO READY QUEUE
1329ms: PROCESS 53 DONE WITH IO
1332ms: PROCESS 57 SENT TO IO QUEUE
1332ms: PROCESS 70 DISPATCHED TO CPU
1340ms: PROCESS 23 ADDED TO READY QUEUE
1340ms: PROCESS 23 DONE WITH IO
1354ms: PROCESS 70 FINISHED, TURNAROUND: 0ms, CPU WAIT: 927ms, IO WAIT: 141ms
1354ms: PROCESS 53 DISPATCHED TO CPU
1354ms: PROCESS 94 ADDED TO READY QUEUE
1354ms: PROCESS 94 DONE WITH IO
1364ms: PROCESS 57 ADDED TO READY QUEUE
1364ms: PROCESS 57 DONE WITH IO
1370ms: PROCESS 53 SENT TO IO QUEUE
1370ms: PROCESS 23 DISPATCHED TO CPU
1374ms: PROCESS 53 ADDED TO READY QUEUE
1374ms: PROCESS 53 DONE WITH IO
1394ms: PROCESS 23 SENT TO IO QUEUE
1394ms: PROCESS 94 DISPATCHED TO CPU
1405ms: PROCESS 94 SENT TO IO QUEUE
1405ms: PROCESS 57 DISPATCHED TO CPU
1411ms: PROCESS 23 ADDED TO READY QUEUE
1411ms: PROCESS 23 DONE WITH IO
1412ms: PROCESS 57 FINISHED, TURNAROUND: 0ms, CPU WAIT: 1091ms, IO WAIT: 170ms
1412ms: PROCESS 53 DISPATCHED TO CPU
1422ms: PROCESS 94 ADDED TO READY QUEUE
1422ms: PROCESS 94 DONE WITH IO
1425ms: PROCESS 53 FINISHED, TURNAROUND: 0ms, CPU WAIT: 982ms, IO WAIT: 147ms
1425ms: PROCESS 23 DISPATCHED TO CPU
1443ms: PROCESS 23 SENT TO IO QUEUE
1443ms: PROCESS 94 DISPATCHED TO CPU
1449ms: PROCESS 23 ADDED TO READY QUEUE
1449ms: PROCESS 23 DONE WITH IO
1453ms: PROCESS 94 SENT TO IO QUEUE
1453ms: PROCESS 23 DISPATCHED TO CPU
1469ms: PROCESS 94 ADDED TO READY QUEUE
1469ms: PROCESS 94 DONE WITH IO
1470ms: PROCESS 23 SENT TO IO QUEUE
1470ms: PROCESS 94 DISPATCHED TO CPU
1483ms: PROCESS 23 ADDED TO READY QUEUE
1483ms: PROCESS 23 DONE WITH IO
1485ms: PROCESS 94 FINISHED, TURNAROUND: 0ms, CPU WAIT: 1053ms, IO WAIT: 245ms
1485ms: PROCESS 23 DISPATCHED TO CPU
1498ms: PROCESS 23 SENT TO IO QUEUE
1498ms: PROCESS 82 DISPATCHED TO CPU
1508ms: PROCESS 82 SENT TO IO QUEUE
1508ms: PROCESS 7 DISPATCHED TO CPU
1510ms: PROCESS 7 FINISHED, TURNAROUND: 0ms, CPU WAIT: 1426ms, IO WAIT: 0ms
1510ms: PROCESS 39 DISPATCHED TO CPU
1510ms: PROCESS 23 ADDED TO READY QUEUE
1510ms: PROCESS 23 DONE WITH IO
1511ms: PROCESS 39 PREMPTED
1511ms: PROCESS 23 DISPATCHED TO CPU
1511ms: PROCESS 39 ADDED TO READY QUEUE
1512ms: PROCESS 23 FINISHED, TURNAROUND: 0ms, CPU WAIT: 947ms, IO WAIT: 182ms
1512ms: PROCESS 47 DISPATCHED TO CPU
1512ms: PROCESS 82 ADDED TO READY QUEUE
1512ms: PROCESS 82 DONE WITH IO
1520ms: PROCESS 47 SENT TO IO QUEUE
1520ms: PROCESS 14 DISPATCHED TO CPU
1525ms: PROCESS 47 ADDED TO READY QUEUE
1525ms: PROCESS 47 DONE WITH IO
1539ms: PROCESS 14 SENT TO IO QUEUE
1539ms: PROCESS 24 DISPATCHED TO CPU
1550ms: PROCESS 24 SENT TO IO QUEUE
1550ms: PROCESS 12 DISPATCHED TO CPU
1551ms: PROCESS 14 ADDED TO READY QUEUE
1551ms: PROCESS 14 DONE WITH IO
1552ms: PROCESS 12 SENT TO IO QUEUE
1552ms: PROCESS 55 DISPATCHED TO CPU
1554ms: PROCESS 55 SENT TO IO QUEUE
1554ms: PROCESS 39 DISPATCHED TO CPU
1555ms: PROCESS 39 SENT TO IO QUEUE
1555ms: PROCESS 82 DISPATCHED TO CPU
1562ms: PROCESS 24 ADDED TO READY QUEUE
1562ms: PROCESS 24 DONE WITH IO
1571ms: PROCESS 82 SENT TO IO QUEUE
1571ms: PROCESS 47 DISPATCHED TO CPU
1577ms: PROCESS 12 ADDED TO READY QUEUE
1577ms: PROCESS 12 DONE WITH IO
1586ms: PROCESS 55 ADDED TO READY QUEUE
1586ms: PROCESS 55 DONE WITH IO
1596ms: PROCESS 47 SENT TO IO QUEUE
1596ms: PROCESS 14 DISPATCHED TO CPU
1600ms: PROCESS 39 ADDED TO READY QUEUE
1600ms: PROCESS 39 DONE WITH IO
1603ms: PROCESS 82 ADDED TO READY QUEUE
1603ms: PROCESS 82 DONE WITH IO
1616ms: PROCESS 14 SENT TO IO QUEUE
1616ms: PROCESS 24 DISPATCHED TO CPU
1622ms: PROCESS 47 ADDED TO READY QUEUE
1622ms: PROCESS 47 DONE WITH IO
1623ms: PROCESS 24 SENT TO IO QUEUE
1623ms: PROCESS 12 DISPATCHED TO CPU
1636ms: PROCESS 14 ADDED TO READY QUEUE
1636ms: PROCESS 14 DONE WITH IO
1645ms: PROCESS 12 SENT TO IO QUEUE
1645ms: PROCESS 55 DISPATCHED TO CPU
1650ms: PROCESS 55 FINISHED, TURNAROUND: 0ms, CPU WAIT: 1399ms, IO WAIT: 32ms
1650ms: PROCESS 39 DISPATCHED TO CPU
1653ms: PROCESS 24 ADDED TO READY QUEUE
1653ms: PROCESS 24 DONE WITH IO
1668ms: PROCESS 39 SENT TO IO QUEUE
1668ms: PROCESS 82 DISPATCHED TO CPU
1670ms: PROCESS 82 FINISHED, TURNAROUND: 0ms, CPU WAIT: 1599ms, IO WAIT: 36ms
1670ms: PROCESS 47 DISPATCHED TO CPU
1676ms: PROCESS 47 SENT TO IO QUEUE
1676ms: PROCESS 14 DISPATCHED TO CPU
1677ms: PROCESS 14 SENT TO IO QUEUE
1677ms: PROCESS 24 DISPATCHED TO CPU
1677ms: PROCESS 12 ADDED TO READY QUEUE
1677ms: PROCESS 12 DONE WITH IO
1684ms: PROCESS 39 ADDED TO READY QUEUE
1684ms: PROCESS 39 DONE WITH IO
1693ms: PROCESS 47 ADDED TO READY QUEUE
1693ms: PROCESS 47 DONE WITH IO
1695ms: PROCESS 14 ADDED TO READY QUEUE
1695ms: PROCESS 14 DONE WITH IO
1700ms: PROCESS 24 SENT TO IO QUEUE
1700ms: PROCESS 12 DISPATCHED TO CPU
1709ms: PROCESS 12 SENT TO IO QUEUE
1709ms: PROCESS 39 DISPATCHED TO CPU
1713ms: PROCESS 24 ADDED TO READY QUEUE
1713ms: PROCESS 24 DONE WITH IO
1714ms: PROCESS 12 ADDED TO READY QUEUE
1714ms: PROCESS 12 DONE WITH IO
1724ms: PROCESS 39 SENT TO IO QUEUE
1724ms: PROCESS 47 DISPATCHED TO CPU
1728ms: PROCESS 47 SENT TO IO QUEUE
1728ms: PROCESS 14 DISPATCHED TO CPU
1747ms: PROCESS 39 ADDED TO READY QUEUE
1747ms: PROCESS 39 DONE WITH IO
1748ms: PROCESS 14 SENT TO IO QUEUE
1748ms: PROCESS 24 DISPATCHED TO CPU
1759ms: PROCESS 24 SENT TO IO QUEUE
1759ms: PROCESS 12 DISPATCHED TO CPU
1770ms: PROCESS 47 ADDED TO READY QUEUE
1770ms: PROCESS 47 DONE WITH IO
1775ms: PROCESS 14 ADDED TO READY QUEUE
1775ms: PROCESS 14 DONE WITH IO
1779ms: PROCESS 12 SENT TO IO QUEUE
1779ms: PROCESS 39 DISPATCHED TO CPU
1787ms: PROCESS 24 ADDED TO READY QUEUE
1787ms: PROCESS 24 DONE WITH IO
1789ms: PROCESS 39 SENT TO IO QUEUE
1789ms: PROCESS 47 DISPATCHED TO CPU
1791ms: PROCESS 12 ADDED TO READY QUEUE
1791ms: PROCESS 12 DONE WITH IO
1811ms: PROCESS 47 SENT TO IO QUEUE
1811ms: PROCESS 14 DISPATCHED TO CPU
1815ms: PROCESS 39 ADDED TO READY QUEUE
1815ms: PROCESS 39 DONE WITH IO
1828ms: PROCESS 14 SENT TO IO QUEUE
1828ms: PROCESS 24 DISPATCHED TO CPU
1833ms: PROCESS 47 ADDED TO READY QUEUE
1833ms: PROCESS 47 DONE WITH IO
1835ms: PROCESS 24 SENT TO IO QUEUE
1835ms: PROCESS 12 DISPATCHED TO CPU
1840ms: PROCESS 14 ADDED TO READY QUEUE
1840ms: PROCESS 14 DONE WITH IO
1841ms: PROCESS 12 SENT TO IO QUEUE
1841ms: PROCESS 39 DISPATCHED TO CPU
1856ms: PROCESS 39 FINISHED, TURNAROUND: 0ms, CPU WAIT: 1592ms, IO WAIT: 110ms
1856ms: PROCESS 47 DISPATCHED TO CPU
1861ms: PROCESS 24 ADDED TO READY QUEUE
1861ms: PROCESS 24 DONE WITH IO
1863ms: PROCESS 12 ADDED TO READY QUEUE
1863ms: PROCESS 12 DONE WITH IO
1877ms: PROCESS 47 FINISHED, TURNAROUND: 0ms, CPU WAIT: 1577ms, IO WAIT: 112ms
1877ms: PROCESS 14 DISPATCHED TO CPU
1885ms: PROCESS 14 SENT TO IO QUEUE
1885ms: PROCESS 24 DISPATCHED TO CPU
1887ms: PROCESS 24 SENT TO IO QUEUE
1887ms: PROCESS 12 DISPATCHED TO CPU
1893ms: PROCESS 14 ADDED TO READY QUEUE
1893ms: PROCESS 14 DONE WITH IO
1906ms: PROCESS 12 SENT TO IO QUEUE
1906ms: PROCESS 14 DISPATCHED TO CPU
1911ms: PROCESS 24 ADDED TO READY QUEUE
1911ms: PROCESS 24 DONE WITH IO
1927ms: PROCESS 14 FINISHED, TURNAROUND: 0ms, CPU WAIT: 1567ms, IO WAIT: 97ms
1927ms: PROCESS 24 DISPATCHED TO CPU
1932ms: PROCESS 12 ADDED TO READY QUEUE
1932ms: PROCESS 12 DONE WITH IO
1945ms: PROCESS 24 SENT TO IO QUEUE
1945ms: PROCESS 12 DISPATCHED TO CPU
1947ms: PROCESS 24 ADDED TO READY QUEUE
1947ms: PROCESS 24 DONE WITH IO
1948ms: PROCESS 12 SENT TO IO QUEUE
1948ms: PROCESS 24 DISPATCHED TO CPU
1958ms: PROCESS 24 SENT TO IO QUEUE
1958ms: PROCESS 86 DISPATCHED TO CPU
1970ms: PROCESS 12 ADDED TO READY QUEUE
1970ms: PROCESS 12 DONE WITH IO
1971ms: PROCESS 86 PREMPTED
1971ms: PROCESS 12 DISPATCHED TO CPU
1971ms: PROCESS 86 ADDED TO READY QUEUE
1979ms: PROCESS 24 ADDED TO READY QUEUE
1979ms: PROCESS 24 DONE WITH IO
1988ms: PROCESS 12 FINISHED, TURNAROUND: 0ms, CPU WAIT: 1553ms, IO WAIT: 144ms
1988ms: PROCESS 24 DISPATCHED TO CPU
2003ms: PROCESS 24 SENT TO IO QUEUE
2003ms: PROCESS 74 DISPATCHED TO CPU
2008ms: PROCESS 74 SENT TO IO QUEUE
2008ms: PROCESS 59 DISPATCHED TO CPU
2020ms: PROCESS 24 ADDED TO READY QUEUE
2020ms: PROCESS 24 DONE WITH IO
2021ms: PROCESS 59 PREMPTED
2021ms: PROCESS 24 DISPATCHED TO CPU
2021ms: PROCESS 59 ADDED TO READY QUEUE
2023ms: PROCESS 24 SENT TO IO QUEUE
2023ms: PROCESS 72 DISPATCHED TO CPU
2024ms: PROCESS 74 ADDED TO READY QUEUE
2024ms: PROCESS 74 DONE WITH IO
2030ms: PROCESS 72 SENT TO IO QUEUE
2030ms: PROCESS 52 DISPATCHED TO CPU
2030ms: PROCESS 24 ADDED TO READY QUEUE
2030ms: PROCESS 24 DONE WITH IO
2031ms: PROCESS 52 PREMPTED
2031ms: PROCESS 24 DISPATCHED TO CPU
2031ms: PROCESS 52 ADDED TO READY QUEUE
2031ms: PROCESS 24 FINISHED, TURNAROUND: 0ms, CPU WAIT: 1579ms, IO WAIT: 180ms
2031ms: PROCESS 27 DISPATCHED TO CPU
2033ms: PROCESS 27 SENT TO IO QUEUE
2033ms: PROCESS 5 DISPATCHED TO CPU
2036ms: PROCESS 5 SENT TO IO QUEUE
2036ms: PROCESS 86 DISPATCHED TO CPU
2037ms: PROCESS 72 ADDED TO READY QUEUE
2037ms: PROCESS 72 DONE WITH IO
2040ms: PROCESS 86 SENT TO IO QUEUE
2040ms: PROCESS 59 DISPATCHED TO CPU
2042ms: PROCESS 59 SENT TO IO QUEUE
2042ms: PROCESS 74 DISPATCHED TO CPU
2053ms: PROCESS 27 ADDED TO READY QUEUE
2053ms: PROCESS 27 DONE WITH IO
2059ms: PROCESS 5 ADDED TO READY QUEUE
2059ms: PROCESS 5 DONE WITH IO
2064ms: PROCESS 74 SENT TO IO QUEUE
2064ms: PROCESS 52 DISPATCHED TO CPU
2076ms: PROCESS 86 ADDED TO READY QUEUE
2076ms: PROCESS 86 DONE WITH IO
2085ms: PROCESS 52 SENT TO IO QUEUE
2085ms: PROCESS 72 DISPATCHED TO CPU
2085ms: PROCESS 59 ADDED TO READY QUEUE
2085ms: PROCESS 59 DONE WITH IO
2094ms: PROCESS 74 ADDED TO READY QUEUE
2094ms: PROCESS 74 DONE WITH IO
2097ms: PROCESS 72 SENT TO IO QUEUE
2097ms: PROCESS 27 DISPATCHED TO CPU
2104ms: PROCESS 27 FINISHED, TURNAROUND: 0ms, CPU WAIT: 1841ms, IO WAIT: 20ms
2104ms: PROCESS 5 DISPATCHED TO CPU
2113ms: PROCESS 52 ADDED TO READY QUEUE
2113ms: PROCESS 52 DONE WITH IO
2114ms: PROCESS 5 SENT TO IO QUEUE
2114ms: PROCESS 86 DISPATCHED TO CPU
2118ms: PROCESS 72 ADDED TO READY QUEUE
2118ms: PROCESS 72 DONE WITH IO
2120ms: PROCESS 86 SENT TO IO QUEUE
2120ms: PROCESS 59 DISPATCHED TO CPU
2121ms: PROCESS 59 SENT TO IO QUEUE
2121ms: PROCESS 74 DISPATCHED TO CPU
2126ms: PROCESS 5 ADDED TO READY QUEUE
2126ms: PROCESS 5 DONE WITH IO
2130ms: PROCESS 86 ADDED TO READY QUEUE
2130ms: PROCESS 86 DONE WITH IO
2137ms: PROCESS 74 SENT TO IO QUEUE
2137ms: PROCESS 52 DISPATCHED TO CPU
2138ms: PROCESS 52 SENT TO IO QUEUE
2138ms: PROCESS 72 DISPATCHED TO CPU
2151ms: PROCESS 59 ADDED TO READY QUEUE
2151ms: PROCESS 59 DONE WITH IO
2159ms: PROCESS 72 FINISHED, TURNAROUND: 0ms, CPU WAIT: 1940ms, IO WAIT: 28ms
2159ms: PROCESS 5 DISPATCHED TO CPU
2169ms: PROCESS 5 SENT TO IO QUEUE
2169ms: PROCESS 86 DISPATCHED TO CPU
2172ms: PROCESS 86 FINISHED, TURNAROUND: 0ms, CPU WAIT: 2027ms, IO WAIT: 46ms
2172ms: PROCESS 59 DISPATCHED TO CPU
2173ms: PROCESS 74 ADDED TO READY QUEUE
2173ms: PROCESS 74 DONE WITH IO
2175ms: PROCESS 52 ADDED TO READY QUEUE
2175ms: PROCESS 52 DONE WITH IO
2195ms: PROCESS 59 SENT TO IO QUEUE
2195ms: PROCESS 74 DISPATCHED TO CPU
2196ms: PROCESS 5 ADDED TO READY QUEUE
2196ms: PROCESS 5 DONE WITH IO
2203ms: PROCESS 59 ADDED TO READY QUEUE
2203ms: PROCESS 59 DONE WITH IO
2214ms: PROCESS 74 SENT TO IO QUEUE
2214ms: PROCESS 52 DISPATCHED TO CPU
2215ms: PROCESS 74 ADDED TO READY QUEUE
2215ms: PROCESS 74 DONE WITH IO
2217ms: PROCESS 52 SENT TO IO QUEUE
2217ms: PROCESS 5 DISPATCHED TO CPU
2234ms: PROCESS 52 ADDED TO READY QUEUE
2234ms: PROCESS 52 DONE WITH IO
2242ms: PROCESS 5 SENT TO IO QUEUE
2242ms: PROCESS 59 DISPATCHED TO CPU
2250ms: PROCESS 5 ADDED TO READY QUEUE
2250ms: PROCESS 5 DONE WITH IO
2267ms: PROCESS 59 SENT TO IO QUEUE
2267ms: PROCESS 74 DISPATCHED TO CPU
2286ms: PROCESS 74 SENT TO IO QUEUE
2286ms: PROCESS 52 DISPATCHED TO CPU
2289ms: PROCESS 59 ADDED TO READY QUEUE
2289ms: PROCESS 59 DONE WITH IO
2294ms: PROCESS 74 ADDED TO READY QUEUE
2294ms: PROCESS 74 DONE WITH IO
2308ms: PROCESS 52 SENT TO IO QUEUE
2308ms: PROCESS 5 DISPATCHED TO CPU
2315ms: PROCESS 52 ADDED TO READY QUEUE
2315ms: PROCESS 52 DONE WITH IO
2333ms: PROCESS 5 SENT TO IO QUEUE
2333ms: PROCESS 59 DISPATCHED TO CPU
2352ms: PROCESS 59 SENT TO IO QUEUE
2352ms: PROCESS 74 DISPATCHED TO CPU
2356ms: PROCESS 5 ADDED TO READY QUEUE
2356ms: PROCESS 5 DONE WITH IO
2357ms: PROCESS 74 FINISHED, TURNAROUND: 0ms, CPU WAIT: 2105ms, IO WAIT: 91ms
2357ms: PROCESS 52 DISPATCHED TO CPU
2360ms: PROCESS 52 SENT TO IO QUEUE
2360ms: PROCESS 5 DISPATCHED TO CPU
2364ms: PROCESS 59 ADDED TO READY QUEUE
2364ms: PROCESS 59 DONE WITH IO
2369ms: PROCESS 5 SENT TO IO QUEUE
2369ms: PROCESS 59 DISPATCHED TO CPU
2372ms: PROCESS 52 ADDED TO READY QUEUE
2372ms: PROCESS 52 DONE WITH IO
2373ms: PROCESS 5 ADDED TO READY QUEUE
2373ms: PROCESS 5 DONE WITH IO
2394ms: PROCESS 59 FINISHED, TURNAROUND: 0ms, CPU WAIT: 2040ms, IO WAIT: 115ms
2394ms: PROCESS 52 DISPATCHED TO CPU
2406ms: PROCESS 52 SENT TO IO QUEUE
2406ms: PROCESS 5 DISPATCHED TO CPU
2417ms: PROCESS 5 SENT TO IO QUEUE
2417ms: PROCESS 43 DISPATCHED TO CPU
2426ms: PROCESS 43 SENT TO IO QUEUE
2426ms: PROCESS 21 DISPATCHED TO CPU
2429ms: PROCESS 52 ADDED TO READY QUEUE
2429ms: PROCESS 52 DONE WITH IO
2430ms: PROCESS 21 PREMPTED
2430ms: PROCESS 52 DISPATCHED TO CPU
2430ms: PROCESS 21 ADDED TO READY QUEUE
2438ms: PROCESS 52 SENT TO IO QUEUE
2438ms: PROCESS 77 DISPATCHED TO CPU
2450ms: PROCESS 77 SENT TO IO QUEUE
2450ms: PROCESS 35 DISPATCHED TO CPU
2452ms: PROCESS 5 ADDED TO READY QUEUE
2452ms: PROCESS 5 DONE WITH IO
2453ms: PROCESS 35 PREMPTED
2453ms: PROCESS 5 DISPATCHED TO CPU
2453ms: PROCESS 35 ADDED TO READY QUEUE
2457ms: PROCESS 5 SENT TO IO QUEUE
2457ms: PROCESS 18 DISPATCHED TO CPU
2472ms: PROCESS 43 ADDED TO READY QUEUE
2472ms: PROCESS 43 DONE WITH IO
2477ms: PROCESS 18 SENT TO IO QUEUE
2477ms: PROCESS 62 DISPATCHED TO CPU
2484ms: PROCESS 52 ADDED TO READY QUEUE
2484ms: PROCESS 52 DONE WITH IO
2485ms: PROCESS 62 PREMPTED
2485ms: PROCESS 52 DISPATCHED TO CPU
2485ms: PROCESS 62 ADDED TO READY QUEUE
2491ms: PROCESS 77 ADDED TO READY QUEUE
2491ms: PROCESS 77 DONE WITH IO
2495ms: PROCESS 52 SENT TO IO QUEUE
2495ms: PROCESS 21 DISPATCHED TO CPU
2502ms: PROCESS 21 SENT TO IO QUEUE
2502ms: PROCESS 35 DISPATCHED TO CPU
2502ms: PROCESS 5 ADDED TO READY QUEUE
2502ms: PROCESS 5 DONE WITH IO
2503ms: PROCESS 35 PREMPTED
2503ms: PROCESS 5 DISPATCHED TO CPU
2503ms: PROCESS 35 ADDED TO READY QUEUE
2507ms: PROCESS 5 SENT TO IO QUEUE
2507ms: PROCESS 43 DISPATCHED TO CPU
2519ms: PROCESS 18 ADDED TO READY QUEUE
2519ms: PROCESS 18 DONE WITH IO
2521ms: PROCESS 52 ADDED TO READY QUEUE
2521ms: PROCESS 52 DONE WITH IO
2522ms: PROCESS 43 PREMPTED
2522ms: PROCESS 52 DISPATCHED TO CPU
2522ms: PROCESS 43 ADDED TO READY QUEUE
2525ms: PROCESS 52 FINISHED, TURNAROUND: 0ms, CPU WAIT: 2020ms, IO WAIT: 196ms
2525ms: PROCESS 62 DISPATCHED TO CPU
2539ms: PROCESS 21 ADDED TO READY QUEUE
2539ms: PROCESS 21 DONE WITH IO
2540ms: PROCESS 62 SENT TO IO QUEUE
2540ms: PROCESS 77 DISPATCHED TO CPU
2548ms: PROCESS 77 SENT TO IO QUEUE
2548ms: PROCESS 35 DISPATCHED TO CPU
2552ms: PROCESS 5 ADDED TO READY QUEUE
2552ms: PROCESS 5 DONE WITH IO
2553ms: PROCESS 35 PREMPTED
2553ms: PROCESS 5 DISPATCHED TO CPU
2553ms: PROCESS 35 ADDED TO READY QUEUE
2555ms: PROCESS 5 SENT TO IO QUEUE
2555ms: PROCESS 18 DISPATCHED TO CPU
2555ms: PROCESS 62 ADDED TO READY QUEUE
2555ms: PROCESS 62 DONE WITH IO
2566ms: PROCESS 18 SENT TO IO QUEUE
2566ms: PROCESS 43 DISPATCHED TO CPU
2573ms: PROCESS 43 SENT TO IO QUEUE
2573ms: PROCESS 21 DISPATCHED TO CPU
2576ms: PROCESS 77 ADDED TO READY QUEUE
2576ms: PROCESS 77 DONE WITH IO
2590ms: PROCESS 5 ADDED TO READY QUEUE
2590ms: PROCESS 5 DONE WITH IO
2591ms: PROCESS 21 PREMPTED
2591ms: PROCESS 5 DISPATCHED TO CPU
2591ms: PROCESS 21 ADDED TO READY QUEUE
2608ms: PROCESS 5 FINISHED, TURNAROUND: 0ms, CPU WAIT: 1994ms, IO WAIT: 257ms
2608ms: PROCESS 35 DISPATCHED TO CPU
2608ms: PROCESS 18 ADDED TO READY QUEUE
2608ms: PROCESS 18 DONE WITH IO
2622ms: PROCESS 43 ADDED TO READY QUEUE
2622ms: PROCESS 43 DONE WITH IO
2623ms: PROCESS 35 SENT TO IO QUEUE
2623ms: PROCESS 62 DISPATCHED TO CPU
2638ms: PROCESS 62 SENT TO IO QUEUE
2638ms: PROCESS 77 DISPATCHED TO CPU
2640ms: PROCESS 35 ADDED TO READY QUEUE
2640ms: PROCESS 35 DONE WITH IO
2646ms: PROCESS 62 ADDED TO READY QUEUE
2646ms: PROCESS 62 DONE WITH IO
2651ms: PROCESS 77 SENT TO IO QUEUE
2651ms: PROCESS 21 DISPATCHED TO CPU
2655ms: PROCESS 21 SENT TO IO QUEUE
2655ms: PROCESS 18 DISPATCHED TO CPU
2663ms: PROCESS 77 ADDED TO READY QUEUE
2663ms: PROCESS 77 DONE WITH IO
2664ms: PROCESS 21 ADDED TO READY QUEUE
2664ms: PROCESS 21 DONE WITH IO
2670ms: PROCESS 18 SENT TO IO QUEUE
2670ms: PROCESS 43 DISPATCHED TO CPU
2691ms: PROCESS 18 ADDED TO READY QUEUE
2691ms: PROCESS 18 DONE WITH IO
2694ms: PROCESS 43 FINISHED, TURNAROUND: 0ms, CPU WAIT: 2541ms, IO WAIT: 95ms
2694ms: PROCESS 35 DISPATCHED TO CPU
2709ms: PROCESS 35 SENT TO IO QUEUE
2709ms: PROCESS 62 DISPATCHED TO CPU
2725ms: PROCESS 62 SENT TO IO QUEUE
2725ms: PROCESS 77 DISPATCHED TO CPU
2727ms: PROCESS 35 ADDED TO READY QUEUE
2727ms: PROCESS 35 DONE WITH IO
2729ms: PROCESS 62 ADDED TO READY QUEUE
2729ms: PROCESS 62 DONE WITH IO
2745ms: PROCESS 77 SENT TO IO QUEUE
2745ms: PROCESS 21 DISPATCHED TO CPU
2752ms: PROCESS 77 ADDED TO READY QUEUE
2752ms: PROCESS 77 DONE WITH IO
2767ms: PROCESS 21 FINISHED, TURNAROUND: 0ms, CPU WAIT: 2656ms, IO WAIT: 46ms
2767ms: PROCESS 18 DISPATCHED TO CPU
2777ms: PROCESS 18 SENT TO IO QUEUE
2777ms: PROCESS 35 DISPATCHED TO CPU
2782ms: PROCESS 35 SENT TO IO QUEUE
2782ms: PROCESS 62 DISPATCHED TO CPU
2783ms: PROCESS 62 SENT TO IO QUEUE
2783ms: PROCESS 77 DISPATCHED TO CPU
2785ms: PROCESS 18 ADDED TO READY QUEUE
2785ms: PROCESS 18 DONE WITH IO
2787ms: PROCESS 35 ADDED TO READY QUEUE
2787ms: PROCESS 35 DONE WITH IO
2789ms: PROCESS 62 ADDED TO READY QUEUE
2789ms: PROCESS 62 DONE WITH IO
2805ms: PROCESS 77 FINISHED, TURNAROUND: 0ms, CPU WAIT: 2523ms, IO WAIT: 88ms
2805ms: PROCESS 18 DISPATCHED TO CPU
2819ms: PROCESS 18 SENT TO IO QUEUE
2819ms: PROCESS 35 DISPATCHED TO CPU
2825ms: PROCESS 18 ADDED TO READY QUEUE
2825ms: PROCESS 18 DONE WITH IO
2842ms: PROCESS 35 SENT TO IO QUEUE
2842ms: PROCESS 62 DISPATCHED TO CPU
2848ms: PROCESS 62 FINISHED, TURNAROUND: 0ms, CPU WAIT: 2522ms, IO WAIT: 33ms
2848ms: PROCESS 18 DISPATCHED TO CPU
2855ms: PROCESS 18 SENT TO IO QUEUE
2855ms: PROCESS 28 DISPATCHED TO CPU
2858ms: PROCESS 28 SENT TO IO QUEUE
2858ms: PROCESS 22 DISPATCHED TO CPU
2860ms: PROCESS 35 ADDED TO READY QUEUE
2860ms: PROCESS 35 DONE WITH IO
2861ms: PROCESS 22 PREMPTED
2861ms: PROCESS 35 DISPATCHED TO CPU
2861ms: PROCESS 22 ADDED TO READY QUEUE
2863ms: PROCESS 18 ADDED TO READY QUEUE
2863ms: PROCESS 18 DONE WITH IO
2868ms: PROCESS 35 FINISHED, TURNAROUND: 0ms, CPU WAIT: 2612ms, IO WAIT: 58ms
2868ms: PROCESS 18 DISPATCHED TO CPU
2869ms: PROCESS 18 SENT TO IO QUEUE
2869ms: PROCESS 66 DISPATCHED TO CPU
2870ms: PROCESS 66 SENT TO IO QUEUE
2870ms: PROCESS 26 DISPATCHED TO CPU
2873ms: PROCESS 28 ADDED TO READY QUEUE
2873ms: PROCESS 28 DONE WITH IO
2881ms: PROCESS 18 ADDED TO READY QUEUE
2881ms: PROCESS 18 DONE WITH IO
2882ms: PROCESS 26 PREMPTED
2882ms: PROCESS 18 DISPATCHED TO CPU
2882ms: PROCESS 26 ADDED TO READY QUEUE
2893ms: PROCESS 66 ADDED TO READY QUEUE
2893ms: PROCESS 66 DONE WITH IO
2901ms: PROCESS 18 SENT TO IO QUEUE
2901ms: PROCESS 50 DISPATCHED TO CPU
2908ms: PROCESS 50 SENT TO IO QUEUE
2908ms: PROCESS 41 DISPATCHED TO CPU
2915ms: PROCESS 41 SENT TO IO QUEUE
2915ms: PROCESS 58 DISPATCHED TO CPU
2924ms: PROCESS 18 ADDED TO READY QUEUE
2924ms: PROCESS 18 DONE WITH IO
2925ms: PROCESS 58 PREMPTED
2925ms: PROCESS 18 DISPATCHED TO CPU
2925ms: PROCESS 58 ADDED TO READY QUEUE
2945ms: PROCESS 18 SENT TO IO QUEUE
2945ms: PROCESS 38 DISPATCHED TO CPU
2946ms: PROCESS 38 SENT TO IO QUEUE
2946ms: PROCESS 92 DISPATCHED TO CPU
2949ms: PROCESS 50 ADDED TO READY QUEUE
2949ms: PROCESS 50 DONE WITH IO
2971ms: PROCESS 92 SENT TO IO QUEUE
2971ms: PROCESS 97 DISPATCHED TO CPU
2971ms: PROCESS 41 ADDED TO READY QUEUE
2971ms: PROCESS 41 DONE WITH IO
2975ms: PROCESS 18 ADDED TO READY QUEUE
2975ms: PROCESS 18 DONE WITH IO
2976ms: PROCESS 97 PREMPTED
2976ms: PROCESS 18 DISPATCHED TO CPU
2976ms: PROCESS 97 ADDED TO READY QUEUE
2987ms: PROCESS 38 ADDED TO READY QUEUE
2987ms: PROCESS 38 DONE WITH IO
2997ms: PROCESS 18 FINISHED, TURNAROUND: 0ms, CPU WAIT: 2468ms, IO WAIT: 192ms
2997ms: PROCESS 64 DISPATCHED TO CPU
2999ms: PROCESS 92 ADDED TO READY QUEUE
2999ms: PROCESS 92 DONE WITH IO
3013ms: PROCESS 64 SENT TO IO QUEUE
3013ms: PROCESS 98 DISPATCHED TO CPU
3026ms: PROCESS 98 SENT TO IO QUEUE
3026ms: PROCESS 78 DISPATCHED TO CPU
3029ms: PROCESS 64 ADDED TO READY QUEUE
3029ms: PROCESS 64 DONE WITH IO
3033ms: PROCESS 98 ADDED TO READY QUEUE
3033ms: PROCESS 98 DONE WITH IO
3034ms: PROCESS 78 SENT TO IO QUEUE
3034ms: PROCESS 2 DISPATCHED TO CPU
3039ms: PROCESS 78 ADDED TO READY QUEUE
3039ms: PROCESS 78 DONE WITH IO
3057ms: PROCESS 2 SENT TO IO QUEUE
3057ms: PROCESS 51 DISPATCHED TO CPU
3066ms: PROCESS 51 SENT TO IO QUEUE
3066ms: PROCESS 19 DISPATCHED TO CPU
3074ms: PROCESS 2 ADDED TO READY QUEUE
3074ms: PROCESS 2 DONE WITH IO
3078ms: PROCESS 19 SENT TO IO QUEUE
3078ms: PROCESS 22 DISPATCHED TO CPU
3079ms: PROCESS 22 SENT TO IO QUEUE
3079ms: PROCESS 28 DISPATCHED TO CPU
3080ms: PROCESS 51 ADDED TO READY QUEUE
3080ms: PROCESS 51 DONE WITH IO
3084ms: PROCESS 28 SENT TO IO QUEUE
3084ms: PROCESS 26 DISPATCHED TO CPU
3090ms: PROCESS 26 SENT TO IO QUEUE
3090ms: PROCESS 66 DISPATCHED TO CPU
3091ms: PROCESS 66 SENT TO IO QUEUE
3091ms: PROCESS 58 DISPATCHED TO CPU
3097ms: PROCESS 19 ADDED TO READY QUEUE
3097ms: PROCESS 19 DONE WITH IO
3100ms: PROCESS 58 SENT TO IO QUEUE
3100ms: PROCESS 50 DISPATCHED TO CPU
3114ms: PROCESS 22 ADDED TO READY QUEUE
3114ms: PROCESS 22 DONE WITH IO
3115ms: PROCESS 50 SENT TO IO QUEUE
3115ms: PROCESS 41 DISPATCHED TO CPU
3119ms: PROCESS 41 SENT TO IO QUEUE
3119ms: PROCESS 97 DISPATCHED TO CPU
3125ms: PROCESS 97 SENT TO IO QUEUE
3125ms: PROCESS 38 DISPATCHED TO CPU
3130ms: PROCESS 28 ADDED TO READY QUEUE
3130ms: PROCESS 28 DONE WITH IO
3142ms: PROCESS 26 ADDED TO READY QUEUE
3142ms: PROCESS 26 DONE WITH IO
3148ms: PROCESS 66 ADDED TO READY QUEUE
3148ms: PROCESS 66 DONE WITH IO
3150ms: PROCESS 38 SENT TO IO QUEUE
3150ms: PROCESS 92 DISPATCHED TO CPU
3154ms: PROCESS 92 FINISHED, TURNAROUND: 0ms, CPU WAIT: 2955ms, IO WAIT: 28ms
3154ms: PROCESS 64 DISPATCHED TO CPU
3160ms: PROCESS 64 SENT TO IO QUEUE
3160ms: PROCESS 98 DISPATCHED TO CPU
3165ms: PROCESS 58 ADDED TO READY QUEUE
3165ms: PROCESS 58 DONE WITH IO
3174ms: PROCESS 98 SENT TO IO QUEUE
3174ms: PROCESS 78 DISPATCHED TO CPU
3179ms: PROCESS 78 SENT TO IO QUEUE
3179ms: PROCESS 2 DISPATCHED TO CPU
3184ms: PROCESS 2 SENT TO IO QUEUE
3184ms: PROCESS 51 DISPATCHED TO CPU
3184ms: PROCESS 50 ADDED TO READY QUEUE
3184ms: PROCESS 50 DONE WITH IO
3195ms: PROCESS 41 ADDED TO READY QUEUE
3195ms: PROCESS 41 DONE WITH IO
3200ms: PROCESS 51 SENT TO IO QUEUE
3200ms: PROCESS 19 DISPATCHED TO CPU
3204ms: PROCESS 97 ADDED TO READY QUEUE
3204ms: PROCESS 97 DONE WITH IO
3207ms: PROCESS 19 SENT TO IO QUEUE
3207ms: PROCESS 22 DISPATCHED TO CPU
3214ms: PROCESS 22 SENT TO IO QUEUE
3214ms: PROCESS 28 DISPATCHED TO CPU
3223ms: PROCESS 38 ADDED TO READY QUEUE
3223ms: PROCESS 38 DONE WITH IO
3228ms: PROCESS 28 SENT TO IO QUEUE
3228ms: PROCESS 26 DISPATCHED TO CPU
3233ms: PROCESS 64 ADDED TO READY QUEUE
3233ms: PROCESS 64 DONE WITH IO
3235ms: PROCESS 98 ADDED TO READY QUEUE
3235ms: PROCESS 98 DONE WITH IO
3247ms: PROCESS 26 SENT TO IO QUEUE
3247ms: PROCESS 66 DISPATCHED TO CPU
3257ms: PROCESS 78 ADDED TO READY QUEUE
3257ms: PROCESS 78 DONE WITH IO
3259ms: PROCESS 2 ADDED TO READY QUEUE
3259ms: PROCESS 2 DONE WITH IO
3266ms: PROCESS 51 ADDED TO READY QUEUE
3266ms: PROCESS 51 DONE WITH IO
3267ms: PROCESS 66 SENT TO IO QUEUE
3267ms: PROCESS 58 DISPATCHED TO CPU
3276ms: PROCESS 58 SENT TO IO QUEUE
3276ms: PROCESS 50 DISPATCHED TO CPU
3284ms: PROCESS 19 ADDED TO READY QUEUE
3284ms: PROCESS 19 DONE WITH IO
3291ms: PROCESS 22 ADDED TO READY QUEUE
3291ms: PROCESS 22 DONE WITH IO
3298ms: PROCESS 50 SENT TO IO QUEUE
3298ms: PROCESS 41 DISPATCHED TO CPU
3302ms: PROCESS 28 ADDED TO READY QUEUE
3302ms: PROCESS 28 DONE WITH IO
3315ms: PROCESS 41 SENT TO IO QUEUE
3315ms: PROCESS 97 DISPATCHED TO CPU
3321ms: PROCESS 26 ADDED TO READY QUEUE
3321ms: PROCESS 26 DONE WITH IO
3331ms: PROCESS 97 SENT TO IO QUEUE
3331ms: PROCESS 38 DISPATCHED TO CPU
3343ms: PROCESS 66 ADDED TO READY QUEUE
3343ms: PROCESS 66 DONE WITH IO
3352ms: PROCESS 38 SENT TO IO QUEUE
3352ms: PROCESS 64 DISPATCHED TO CPU
3352ms: PROCESS 58 ADDED TO READY QUEUE
3352ms: PROCESS 58 DONE WITH IO
3362ms: PROCESS 50 ADDED TO READY QUEUE
3362ms: PROCESS 50 DONE WITH IO
3368ms: PROCESS 64 FINISHED, TURNAROUND: 0ms, CPU WAIT: 3088ms, IO WAIT: 89ms
3368ms: PROCESS 98 DISPATCHED TO CPU
3370ms: PROCESS 98 SENT TO IO QUEUE
3370ms: PROCESS 78 DISPATCHED TO CPU
3371ms: PROCESS 78 SENT TO IO QUEUE
3371ms: PROCESS 2 DISPATCHED TO CPU
3377ms: PROCESS 41 ADDED TO READY QUEUE
3377ms: PROCESS 41 DONE WITH IO
3384ms: PROCESS 2 SENT TO IO QUEUE
3384ms: PROCESS 51 DISPATCHED TO CPU
3385ms: PROCESS 97 ADDED TO READY QUEUE
3385ms: PROCESS 97 DONE WITH IO
3408ms: PROCESS 51 SENT TO IO QUEUE
3408ms: PROCESS 19 DISPATCHED TO CPU
3409ms: PROCESS 38 ADDED TO READY QUEUE
3409ms: PROCESS 38 DONE WITH IO
3417ms: PROCESS 19 SENT TO IO QUEUE
3417ms: PROCESS 22 DISPATCHED TO CPU
3424ms: PROCESS 98 ADDED TO READY QUEUE
3424ms: PROCESS 98 DONE WITH IO
3428ms: PROCESS 22 SENT TO IO QUEUE
3428ms: PROCESS 28 DISPATCHED TO CPU
3430ms: PROCESS 78 ADDED TO READY QUEUE
3430ms: PROCESS 78 DONE WITH IO
3435ms: PROCESS 2 ADDED TO READY QUEUE
3435ms: PROCESS 2 DONE WITH IO
3444ms: PROCESS 28 SENT TO IO QUEUE
3444ms: PROCESS 26 DISPATCHED TO CPU
3449ms: PROCESS 51 ADDED TO READY QUEUE
3449ms: PROCESS 51 DONE WITH IO
3461ms: PROCESS 26 SENT TO IO QUEUE
3461ms: PROCESS 66 DISPATCHED TO CPU
3467ms: PROCESS 19 ADDED TO READY QUEUE
3467ms: PROCESS 19 DONE WITH IO
3468ms: PROCESS 22 ADDED TO READY QUEUE
3468ms: PROCESS 22 DONE WITH IO
3472ms: PROCESS 28 ADDED TO READY QUEUE
3472ms: PROCESS 28 DONE WITH IO
3475ms: PROCESS 26 ADDED TO READY QUEUE
3475ms: PROCESS 26 DONE WITH IO
3479ms: PROCESS 66 SENT TO IO QUEUE
3479ms: PROCESS 58 DISPATCHED TO CPU
3491ms: PROCESS 66 ADDED TO READY QUEUE
3491ms: PROCESS 66 DONE WITH IO
3497ms: PROCESS 58 FINISHED, TURNAROUND: 0ms, CPU WAIT: 3192ms, IO WAIT: 141ms
3497ms: PROCESS 50 DISPATCHED TO CPU
3515ms: PROCESS 50 SENT TO IO QUEUE
3515ms: PROCESS 41 DISPATCHED TO CPU
3530ms: PROCESS 41 SENT TO IO QUEUE
3530ms: PROCESS 97 DISPATCHED TO CPU
3530ms: PROCESS 50 ADDED TO READY QUEUE
3530ms: PROCESS 50 DONE WITH IO
3531ms: PROCESS 41 ADDED TO READY QUEUE
3531ms: PROCESS 41 DONE WITH IO
3551ms: PROCESS 97 SENT TO IO QUEUE
3551ms: PROCESS 38 DISPATCHED TO CPU
3559ms: PROCESS 38 SENT TO IO QUEUE
3559ms: PROCESS 98 DISPATCHED TO CPU
3570ms: PROCESS 97 ADDED TO READY QUEUE
3570ms: PROCESS 97 DONE WITH IO
3578ms: PROCESS 98 SENT TO IO QUEUE
3578ms: PROCESS 78 DISPATCHED TO CPU
3583ms: PROCESS 78 FINISHED, TURNAROUND: 0ms, CPU WAIT: 3262ms, IO WAIT: 142ms
3583ms: PROCESS 2 DISPATCHED TO CPU
3583ms: PROCESS 38 ADDED TO READY QUEUE
3583ms: PROCESS 38 DONE WITH IO
3587ms: PROCESS 98 ADDED TO READY QUEUE
3587ms: PROCESS 98 DONE WITH IO
3597ms: PROCESS 2 SENT TO IO QUEUE
3597ms: PROCESS 51 DISPATCHED TO CPU
3606ms: PROCESS 51 SENT TO IO QUEUE
3606ms: PROCESS 19 DISPATCHED TO CPU
3615ms: PROCESS 2 ADDED TO READY QUEUE
3615ms: PROCESS 2 DONE WITH IO
3630ms: PROCESS 19 SENT TO IO QUEUE
3630ms: PROCESS 22 DISPATCHED TO CPU
3634ms: PROCESS 22 FINISHED, TURNAROUND: 0ms, CPU WAIT: 3414ms, IO WAIT: 152ms
3634ms: PROCESS 28 DISPATCHED TO CPU
3640ms: PROCESS 51 ADDED TO READY QUEUE
3640ms: PROCESS 51 DONE WITH IO
3642ms: PROCESS 28 SENT TO IO QUEUE
3642ms: PROCESS 26 DISPATCHED TO CPU
3647ms: PROCESS 19 ADDED TO READY QUEUE
3647ms: PROCESS 19 DONE WITH IO
3663ms: PROCESS 26 SENT TO IO QUEUE
3663ms: PROCESS 66 DISPATCHED TO CPU
3666ms: PROCESS 28 ADDED TO READY QUEUE
3666ms: PROCESS 28 DONE WITH IO
3673ms: PROCESS 66 SENT TO IO QUEUE
3673ms: PROCESS 50 DISPATCHED TO CPU
3690ms: PROCESS 26 ADDED TO READY QUEUE
3690ms: PROCESS 26 DONE WITH IO
3694ms: PROCESS 50 SENT TO IO QUEUE
3694ms: PROCESS 41 DISPATCHED TO CPU
3694ms: PROCESS 66 ADDED TO READY QUEUE
3694ms: PROCESS 66 DONE WITH IO
3703ms: PROCESS 41 SENT TO IO QUEUE
3703ms: PROCESS 97 DISPATCHED TO CPU
3705ms: PROCESS 50 ADDED TO READY QUEUE
3705ms: PROCESS 50 DONE WITH IO
3727ms: PROCESS 41 ADDED TO READY QUEUE
3727ms: PROCESS 41 DONE WITH IO
3728ms: PROCESS 97 SENT TO IO QUEUE
3728ms: PROCESS 38 DISPATCHED TO CPU
3744ms: PROCESS 97 ADDED TO READY QUEUE
3744ms: PROCESS 97 DONE WITH IO
3753ms: PROCESS 38 SENT TO IO QUEUE
3753ms: PROCESS 98 DISPATCHED TO CPU
3763ms: PROCESS 38 ADDED TO READY QUEUE
3763ms: PROCESS 38 DONE WITH IO
3764ms: PROCESS 98 SENT TO IO QUEUE
3764ms: PROCESS 2 DISPATCHED TO CPU
3771ms: PROCESS 98 ADDED TO READY QUEUE
3771ms: PROCESS 98 DONE WITH IO
3779ms: PROCESS 2 SENT TO IO QUEUE
3779ms: PROCESS 51 DISPATCHED TO CPU
3795ms: PROCESS 2 ADDED TO READY QUEUE
3795ms: PROCESS 2 DONE WITH IO
3801ms: PROCESS 51 SENT TO IO QUEUE
3801ms: PROCESS 19 DISPATCHED TO CPU
3819ms: PROCESS 51 ADDED TO READY QUEUE
3819ms: PROCESS 51 DONE WITH IO
3825ms: PROCESS 19 SENT TO IO QUEUE
3825ms: PROCESS 28 DISPATCHED TO CPU
3837ms: PROCESS 28 SENT TO IO QUEUE
3837ms: PROCESS 26 DISPATCHED TO CPU
3845ms: PROCESS 19 ADDED TO READY QUEUE
3845ms: PROCESS 19 DONE WITH IO
3853ms: PROCESS 28 ADDED TO READY QUEUE
3853ms: PROCESS 28 DONE WITH IO
3856ms: PROCESS 26 SENT TO IO QUEUE
3856ms: PROCESS 66 DISPATCHED TO CPU
3862ms: PROCESS 66 SENT TO IO QUEUE
3862ms: PROCESS 50 DISPATCHED TO CPU
3865ms: PROCESS 26 ADDED TO READY QUEUE
3865ms: PROCESS 26 DONE WITH IO
3867ms: PROCESS 66 ADDED TO READY QUEUE
3867ms: PROCESS 66 DONE WITH IO
3870ms: PROCESS 50 SENT TO IO QUEUE
3870ms: PROCESS 41 DISPATCHED TO CPU
3872ms: PROCESS 50 ADDED TO READY QUEUE
3872ms: PROCESS 50 DONE WITH IO
3889ms: PROCESS 41 SENT TO IO QUEUE
3889ms: PROCESS 97 DISPATCHED TO CPU
3906ms: PROCESS 97 SENT TO IO QUEUE
3906ms: PROCESS 38 DISPATCHED TO CPU
3908ms: PROCESS 41 ADDED TO READY QUEUE
3908ms: PROCESS 41 DONE WITH IO
3910ms: PROCESS 38 SENT TO IO QUEUE
3910ms: PROCESS 98 DISPATCHED TO CPU
3917ms: PROCESS 97 ADDED TO READY QUEUE
3917ms: PROCESS 97 DONE WITH IO
3924ms: PROCESS 98 SENT TO IO QUEUE
3924ms: PROCESS 2 DISPATCHED TO CPU
3926ms: PROCESS 38 ADDED TO READY QUEUE
3926ms: PROCESS 38 DONE WITH IO
3928ms: PROCESS 98 ADDED TO READY QUEUE
3928ms: PROCESS 98 DONE WITH IO
3930ms: PROCESS 2 SENT TO IO QUEUE
3930ms: PROCESS 51 DISPATCHED TO CPU
3940ms: PROCESS 2 ADDED TO READY QUEUE
3940ms: PROCESS 2 DONE WITH IO
3954ms: PROCESS 51 FINISHED, TURNAROUND: 0ms, CPU WAIT: 3461ms, IO WAIT: 173ms
3954ms: PROCESS 19 DISPATCHED TO CPU
3958ms: PROCESS 19 SENT TO IO QUEUE
3958ms: PROCESS 28 DISPATCHED TO CPU
3980ms: PROCESS 28 SENT TO IO QUEUE
3980ms: PROCESS 26 DISPATCHED TO CPU
3983ms: PROCESS 19 ADDED TO READY QUEUE
3983ms: PROCESS 19 DONE WITH IO
3993ms: PROCESS 26 SENT TO IO QUEUE
3993ms: PROCESS 66 DISPATCHED TO CPU
3993ms: PROCESS 28 ADDED TO READY QUEUE
3993ms: PROCESS 28 DONE WITH IO
3999ms: PROCESS 66 SENT TO IO QUEUE
3999ms: PROCESS 50 DISPATCHED TO CPU
4012ms: PROCESS 26 ADDED TO READY QUEUE
4012ms: PROCESS 26 DONE WITH IO
4018ms: PROCESS 50 SENT TO IO QUEUE
4018ms: PROCESS 41 DISPATCHED TO CPU
4020ms: PROCESS 66 ADDED TO READY QUEUE
4020ms: PROCESS 66 DONE WITH IO
4033ms: PROCESS 41 SENT TO IO QUEUE
4033ms: PROCESS 97 DISPATCHED TO CPU
4033ms: PROCESS 50 ADDED TO READY QUEUE
4033ms: PROCESS 50 DONE WITH IO
4034ms: PROCESS 41 ADDED TO READY QUEUE
4034ms: PROCESS 41 DONE WITH IO
4039ms: PROCESS 97 SENT TO IO QUEUE
4039ms: PROCESS 38 DISPATCHED TO CPU
4053ms: PROCESS 97 ADDED TO READY QUEUE
4053ms: PROCESS 97 DONE WITH IO
4060ms: PROCESS 38 SENT TO IO QUEUE
4060ms: PROCESS 98 DISPATCHED TO CPU
4069ms: PROCESS 38 ADDED TO READY QUEUE
4069ms: PROCESS 38 DONE WITH IO
4085ms: PROCESS 98 FINISHED, TURNAROUND: 0ms, CPU WAIT: 3692ms, IO WAIT: 142ms
4085ms: PROCESS 2 DISPATCHED TO CPU
4099ms: PROCESS 2 SENT TO IO QUEUE
4099ms: PROCESS 19 DISPATCHED TO CPU
4108ms: PROCESS 2 ADDED TO READY QUEUE
4108ms: PROCESS 2 DONE WITH IO
4110ms: PROCESS 19 SENT TO IO QUEUE
4110ms: PROCESS 28 DISPATCHED TO CPU
4112ms: PROCESS 19 ADDED TO READY QUEUE
4112ms: PROCESS 19 DONE WITH IO
4126ms: PROCESS 28 SENT TO IO QUEUE
4126ms: PROCESS 26 DISPATCHED TO CPU
4146ms: PROCESS 26 SENT TO IO QUEUE
4146ms: PROCESS 66 DISPATCHED TO CPU
4150ms: PROCESS 28 ADDED TO READY QUEUE
4150ms: PROCESS 28 DONE WITH IO
4159ms: PROCESS 26 ADDED TO READY QUEUE
4159ms: PROCESS 26 DONE WITH IO
4164ms: PROCESS 66 SENT TO IO QUEUE
4164ms: PROCESS 50 DISPATCHED TO CPU
4171ms: PROCESS 50 FINISHED, TURNAROUND: 0ms, CPU WAIT: 3731ms, IO WAIT: 217ms
4171ms: PROCESS 41 DISPATCHED TO CPU
4175ms: PROCESS 66 ADDED TO READY QUEUE
4175ms: PROCESS 66 DONE WITH IO
4176ms: PROCESS 41 FINISHED, TURNAROUND: 0ms, CPU WAIT: 3738ms, IO WAIT: 239ms
4176ms: PROCESS 97 DISPATCHED TO CPU
4182ms: PROCESS 97 SENT TO IO QUEUE
4182ms: PROCESS 38 DISPATCHED TO CPU
4185ms: PROCESS 97 ADDED TO READY QUEUE
4185ms: PROCESS 97 DONE WITH IO
4188ms: PROCESS 38 SENT TO IO QUEUE
4188ms: PROCESS 2 DISPATCHED TO CPU
4199ms: PROCESS 38 ADDED TO READY QUEUE
4199ms: PROCESS 38 DONE WITH IO
4208ms: PROCESS 2 SENT TO IO QUEUE
4208ms: PROCESS 19 DISPATCHED TO CPU
4229ms: PROCESS 2 ADDED TO READY QUEUE
4229ms: PROCESS 2 DONE WITH IO
4230ms: PROCESS 19 FINISHED, TURNAROUND: 0ms, CPU WAIT: 3690ms, IO WAIT: 210ms
4230ms: PROCESS 28 DISPATCHED TO CPU
4243ms: PROCESS 28 SENT TO IO QUEUE
4243ms: PROCESS 26 DISPATCHED TO CPU
4254ms: PROCESS 28 ADDED TO READY QUEUE
4254ms: PROCESS 28 DONE WITH IO
4265ms: PROCESS 26 SENT TO IO QUEUE
4265ms: PROCESS 66 DISPATCHED TO CPU
4274ms: PROCESS 26 ADDED TO READY QUEUE
4274ms: PROCESS 26 DONE WITH IO
4277ms: PROCESS 66 FINISHED, TURNAROUND: 0ms, CPU WAIT: 3880ms, IO WAIT: 226ms
4277ms: PROCESS 97 DISPATCHED TO CPU
4278ms: PROCESS 97 SENT TO IO QUEUE
4278ms: PROCESS 38 DISPATCHED TO CPU
4280ms: PROCESS 38 SENT TO IO QUEUE
4280ms: PROCESS 2 DISPATCHED TO CPU
4296ms: PROCESS 97 ADDED TO READY QUEUE
4296ms: PROCESS 97 DONE WITH IO
4304ms: PROCESS 2 SENT TO IO QUEUE
4304ms: PROCESS 28 DISPATCHED TO CPU
4316ms: PROCESS 38 ADDED TO READY QUEUE
4316ms: PROCESS 38 DONE WITH IO
4327ms: PROCESS 2 ADDED TO READY QUEUE
4327ms: PROCESS 2 DONE WITH IO
4329ms: PROCESS 28 FINISHED, TURNAROUND: 0ms, CPU WAIT: 3924ms, IO WAIT: 251ms
4329ms: PROCESS 26 DISPATCHED TO CPU
4338ms: PROCESS 26 FINISHED, TURNAROUND: 0ms, CPU WAIT: 3876ms, IO WAIT: 217ms
4338ms: PROCESS 97 DISPATCHED TO CPU
4359ms: PROCESS 97 SENT TO IO QUEUE
4359ms: PROCESS 38 DISPATCHED TO CPU
4375ms: PROCESS 38 FINISHED, TURNAROUND: 0ms, CPU WAIT: 3838ms, IO WAIT: 277ms
4375ms: PROCESS 2 DISPATCHED TO CPU
4381ms: PROCESS 97 ADDED TO READY QUEUE
4381ms: PROCESS 97 DONE WITH IO
4400ms: PROCESS 2 SENT TO IO QUEUE
4400ms: PROCESS 97 DISPATCHED TO CPU
4401ms: PROCESS 2 ADDED TO READY QUEUE
4401ms: PROCESS 2 DONE WITH IO
4409ms: PROCESS 97 SENT TO IO QUEUE
4409ms: PROCESS 2 DISPATCHED TO CPU
4413ms: PROCESS 2 FINISHED, TURNAROUND: 0ms, CPU WAIT: 3844ms, IO WAIT: 241ms
4413ms: PROCESS 44 DISPATCHED TO CPU
4414ms: PROCESS 97 ADDED TO READY QUEUE
4414ms: PROCESS 97 DONE WITH IO
4415ms: PROCESS 44 PREMPTED
4415ms: PROCESS 97 DISPATCHED TO CPU
4415ms: PROCESS 44 ADDED TO READY QUEUE
4434ms: PROCESS 97 FINISHED, TURNAROUND: 0ms, CPU WAIT: 3893ms, IO WAIT: 241ms
4434ms: PROCESS 0 DISPATCHED TO CPU
4442ms: PROCESS 0 SENT TO IO QUEUE
4442ms: PROCESS 56 DISPATCHED TO CPU
4446ms: PROCESS 56 SENT TO IO QUEUE
4446ms: PROCESS 3 DISPATCHED TO CPU
4454ms: PROCESS 3 SENT TO IO QUEUE
4454ms: PROCESS 13 DISPATCHED TO CPU
4458ms: PROCESS 0 ADDED TO READY QUEUE
4458ms: PROCESS 0 DONE WITH IO
4464ms: PROCESS 13 SENT TO IO QUEUE
4464ms: PROCESS 60 DISPATCHED TO CPU
4480ms: PROCESS 60 SENT TO IO QUEUE
4480ms: PROCESS 49 DISPATCHED TO CPU
4480ms: PROCESS 56 ADDED TO READY QUEUE
4480ms: PROCESS 56 DONE WITH IO
4493ms: PROCESS 3 ADDED TO READY QUEUE
4493ms: PROCESS 3 DONE WITH IO
4499ms: PROCESS 13 ADDED TO READY QUEUE
4499ms: PROCESS 13 DONE WITH IO
4500ms: PROCESS 49 SENT TO IO QUEUE
4500ms: PROCESS 42 DISPATCHED TO CPU
4516ms: PROCESS 60 ADDED TO READY QUEUE
4516ms: PROCESS 60 DONE WITH IO
4518ms: PROCESS 42 SENT TO IO QUEUE
4518ms: PROCESS 31 DISPATCHED TO CPU
4524ms: PROCESS 31 SENT TO IO QUEUE
4524ms: PROCESS 16 DISPATCHED TO CPU
4525ms: PROCESS 16 SENT TO IO QUEUE
4525ms: PROCESS 45 DISPATCHED TO CPU
4531ms: PROCESS 49 ADDED TO READY QUEUE
4531ms: PROCESS 49 DONE WITH IO
4540ms: PROCESS 42 ADDED TO READY QUEUE
4540ms: PROCESS 42 DONE WITH IO
4546ms: PROCESS 45 SENT TO IO QUEUE
4546ms: PROCESS 15 DISPATCHED TO CPU
4549ms: PROCESS 31 ADDED TO READY QUEUE
4549ms: PROCESS 31 DONE WITH IO
4558ms: PROCESS 16 ADDED TO READY QUEUE
4558ms: PROCESS 16 DONE WITH IO
4569ms: PROCESS 15 SENT TO IO QUEUE
4569ms: PROCESS 44 DISPATCHED TO CPU
4576ms: PROCESS 44 SENT TO IO QUEUE
4576ms: PROCESS 0 DISPATCHED TO CPU
4579ms: PROCESS 45 ADDED TO READY QUEUE
4579ms: PROCESS 45 DONE WITH IO
4583ms: PROCESS 15 ADDED TO READY QUEUE
4583ms: PROCESS 15 DONE WITH IO
4584ms: PROCESS 0 SENT TO IO QUEUE
4584ms: PROCESS 56 DISPATCHED TO CPU
4591ms: PROCESS 44 ADDED TO READY QUEUE
4591ms: PROCESS 44 DONE WITH IO
4608ms: PROCESS 56 SENT TO IO QUEUE
4608ms: PROCESS 3 DISPATCHED TO CPU
4609ms: PROCESS 0 ADDED TO READY QUEUE
4609ms: PROCESS 0 DONE WITH IO
4610ms: PROCESS 56 ADDED TO READY QUEUE
4610ms: PROCESS 56 DONE WITH IO
4628ms: PROCESS 3 SENT TO IO QUEUE
4628ms: PROCESS 13 DISPATCHED TO CPU
4632ms: PROCESS 3 ADDED TO READY QUEUE
4632ms: PROCESS 3 DONE WITH IO
4637ms: PROCESS 13 SENT TO IO QUEUE
4637ms: PROCESS 60 DISPATCHED TO CPU
4647ms: PROCESS 13 ADDED TO READY QUEUE
4647ms: PROCESS 13 DONE WITH IO
4662ms: PROCESS 60 SENT TO IO QUEUE
4662ms: PROCESS 49 DISPATCHED TO CPU
4667ms: PROCESS 60 ADDED TO READY QUEUE
4667ms: PROCESS 60 DONE WITH IO
4670ms: PROCESS 49 SENT TO IO QUEUE
4670ms: PROCESS 42 DISPATCHED TO CPU
4678ms: PROCESS 49 ADDED TO READY QUEUE
4678ms: PROCESS 49 DONE WITH IO
4694ms: PROCESS 42 SENT TO IO QUEUE
4694ms: PROCESS 31 DISPATCHED TO CPU
4703ms: PROCESS 42 ADDED TO READY QUEUE
4703ms: PROCESS 42 DONE WITH IO
4706ms: PROCESS 31 SENT TO IO QUEUE
4706ms: PROCESS 16 DISPATCHED TO CPU
4719ms: PROCESS 31 ADDED TO READY QUEUE
4719ms: PROCESS 31 DONE WITH IO
4725ms: PROCESS 16 SENT TO IO QUEUE
4725ms: PROCESS 45 DISPATCHED TO CPU
4736ms: PROCESS 45 SENT TO IO QUEUE
4736ms: PROCESS 15 DISPATCHED TO CPU
4750ms: PROCESS 16 ADDED TO READY QUEUE
4750ms: PROCESS 16 DONE WITH IO
4754ms: PROCESS 15 SENT TO IO QUEUE
4754ms: PROCESS 44 DISPATCHED TO CPU
4762ms: PROCESS 44 SENT TO IO QUEUE
4762ms: PROCESS 0 DISPATCHED TO CPU
4770ms: PROCESS 0 SENT TO IO QUEUE
4770ms: PROCESS 56 DISPATCHED TO CPU
4773ms: PROCESS 45 ADDED TO READY QUEUE
4773ms: PROCESS 45 DONE WITH IO
4791ms: PROCESS 56 SENT TO IO QUEUE
4791ms: PROCESS 3 DISPATCHED TO CPU
4794ms: PROCESS 15 ADDED TO READY QUEUE
4794ms: PROCESS 15 DONE WITH IO
4797ms: PROCESS 3 SENT TO IO QUEUE
4797ms: PROCESS 13 DISPATCHED TO CPU
4812ms: PROCESS 44 ADDED TO READY QUEUE
4812ms: PROCESS 44 DONE WITH IO
4819ms: PROCESS 13 SENT TO IO QUEUE
4819ms: PROCESS 60 DISPATCHED TO CPU
4821ms: PROCESS 0 ADDED TO READY QUEUE
4821ms: PROCESS 0 DONE WITH IO
4827ms: PROCESS 60 SENT TO IO QUEUE
4827ms: PROCESS 49 DISPATCHED TO CPU
4836ms: PROCESS 56 ADDED TO READY QUEUE
4836ms: PROCESS 56 DONE WITH IO
4846ms: PROCESS 49 SENT TO IO QUEUE
4846ms: PROCESS 42 DISPATCHED TO CPU
4848ms: PROCESS 3 ADDED TO READY QUEUE
4848ms: PROCESS 3 DONE WITH IO
4866ms: PROCESS 42 SENT TO IO QUEUE
4866ms: PROCESS 31 DISPATCHED TO CPU
4868ms: PROCESS 13 ADDED TO READY QUEUE
4868ms: PROCESS 13 DONE WITH IO
4874ms: PROCESS 31 SENT TO IO QUEUE
4874ms: PROCESS 16 DISPATCHED TO CPU
4879ms: PROCESS 16 FINISHED, TURNAROUND: 0ms, CPU WAIT: 4578ms, IO WAIT: 58ms
4879ms: PROCESS 45 DISPATCHED TO CPU
4881ms: PROCESS 45 SENT TO IO QUEUE
4881ms: PROCESS 15 DISPATCHED TO CPU
4889ms: PROCESS 60 ADDED TO READY QUEUE
4889ms: PROCESS 60 DONE WITH IO
4897ms: PROCESS 15 FINISHED, TURNAROUND: 0ms, CPU WAIT: 4551ms, IO WAIT: 54ms
4897ms: PROCESS 44 DISPATCHED TO CPU
4901ms: PROCESS 49 ADDED TO READY QUEUE
4901ms: PROCESS 49 DONE WITH IO
4908ms: PROCESS 44 SENT TO IO QUEUE
4908ms: PROCESS 0 DISPATCHED TO CPU
4913ms: PROCESS 0 SENT TO IO QUEUE
4913ms: PROCESS 56 DISPATCHED TO CPU
4915ms: PROCESS 42 ADDED TO READY QUEUE
4915ms: PROCESS 42 DONE WITH IO
4929ms: PROCESS 31 ADDED TO READY QUEUE
4929ms: PROCESS 31 DONE WITH IO
4931ms: PROCESS 56 FINISHED, TURNAROUND: 0ms, CPU WAIT: 4734ms, IO WAIT: 81ms
4931ms: PROCESS 3 DISPATCHED TO CPU
4931ms: PROCESS 45 ADDED TO READY QUEUE
4931ms: PROCESS 45 DONE WITH IO
4933ms: PROCESS 3 SENT TO IO QUEUE
4933ms: PROCESS 13 DISPATCHED TO CPU
4945ms: PROCESS 13 SENT TO IO QUEUE
4945ms: PROCESS 60 DISPATCHED TO CPU
4950ms: PROCESS 44 ADDED TO READY QUEUE
4950ms: PROCESS 44 DONE WITH IO
4957ms: PROCESS 60 SENT TO IO QUEUE
4957ms: PROCESS 49 DISPATCHED TO CPU
4957ms: PROCESS 0 ADDED TO READY QUEUE
4957ms: PROCESS 0 DONE WITH IO
4966ms: PROCESS 49 SENT TO IO QUEUE
4966ms: PROCESS 42 DISPATCHED TO CPU
4966ms: PROCESS 3 ADDED TO READY QUEUE
4966ms: PROCESS 3 DONE WITH IO
4969ms: PROCESS 13 ADDED TO READY QUEUE
4969ms: PROCESS 13 DONE WITH IO
4982ms: PROCESS 60 ADDED TO READY QUEUE
4982ms: PROCESS 60 DONE WITH IO
4983ms: PROCESS 42 SENT TO IO QUEUE
4983ms: PROCESS 31 DISPATCHED TO CPU
4983ms: PROCESS 49 ADDED TO READY QUEUE
4983ms: PROCESS 49 DONE WITH IO
4992ms: PROCESS 31 SENT TO IO QUEUE
4992ms: PROCESS 45 DISPATCHED TO CPU
4995ms: PROCESS 45 SENT TO IO QUEUE
4995ms: PROCESS 44 DISPATCHED TO CPU
4997ms: PROCESS 42 ADDED TO READY QUEUE
4997ms: PROCESS 42 DONE WITH IO
5007ms: PROCESS 44 SENT TO IO QUEUE
5007ms: PROCESS 0 DISPATCHED TO CPU
5009ms: PROCESS 31 ADDED TO READY QUEUE
5009ms: PROCESS 31 DONE WITH IO
5021ms: PROCESS 45 ADDED TO READY QUEUE
5021ms: PROCESS 45 DONE WITH IO
5029ms: PROCESS 0 SENT TO IO QUEUE
5029ms: PROCESS 3 DISPATCHED TO CPU
5046ms: PROCESS 44 ADDED TO READY QUEUE
5046ms: PROCESS 44 DONE WITH IO
5051ms: PROCESS 3 SENT TO IO QUEUE
5051ms: PROCESS 13 DISPATCHED TO CPU
5054ms: PROCESS 0 ADDED TO READY QUEUE
5054ms: PROCESS 0 DONE WITH IO
5067ms: PROCESS 3 ADDED TO READY QUEUE
5067ms: PROCESS 3 DONE WITH IO
5076ms: PROCESS 13 SENT TO IO QUEUE
5076ms: PROCESS 60 DISPATCHED TO CPU
5083ms: PROCESS 60 SENT TO IO QUEUE
5083ms: PROCESS 49 DISPATCHED TO CPU
5091ms: PROCESS 13 ADDED TO READY QUEUE
5091ms: PROCESS 13 DONE WITH IO
5103ms: PROCESS 49 SENT TO IO QUEUE
5103ms: PROCESS 42 DISPATCHED TO CPU
5107ms: PROCESS 60 ADDED TO READY QUEUE
5107ms: PROCESS 60 DONE WITH IO
5109ms: PROCESS 42 SENT TO IO QUEUE
5109ms: PROCESS 31 DISPATCHED TO CPU
5112ms: PROCESS 49 ADDED TO READY QUEUE
5112ms: PROCESS 49 DONE WITH IO
5115ms: PROCESS 31 SENT TO IO QUEUE
5115ms: PROCESS 45 DISPATCHED TO CPU
5115ms: PROCESS 42 ADDED TO READY QUEUE
5115ms: PROCESS 42 DONE WITH IO
5124ms: PROCESS 31 ADDED TO READY QUEUE
5124ms: PROCESS 31 DONE WITH IO
5139ms: PROCESS 45 SENT TO IO QUEUE
5139ms: PROCESS 44 DISPATCHED TO CPU
5140ms: PROCESS 44 SENT TO IO QUEUE
5140ms: PROCESS 0 DISPATCHED TO CPU
5147ms: PROCESS 0 SENT TO IO QUEUE
5147ms: PROCESS 3 DISPATCHED TO CPU
5156ms: PROCESS 45 ADDED TO READY QUEUE
5156ms: PROCESS 45 DONE WITH IO
5160ms: PROCESS 44 ADDED TO READY QUEUE
5160ms: PROCESS 44 DONE WITH IO
5166ms: PROCESS 0 ADDED TO READY QUEUE
5166ms: PROCESS 0 DONE WITH IO
5172ms: PROCESS 3 SENT TO IO QUEUE
5172ms: PROCESS 13 DISPATCHED TO CPU
5182ms: PROCESS 3 ADDED TO READY QUEUE
5182ms: PROCESS 3 DONE WITH IO
5186ms: PROCESS 13 SENT TO IO QUEUE
5186ms: PROCESS 60 DISPATCHED TO CPU
5201ms: PROCESS 60 SENT TO IO QUEUE
5201ms: PROCESS 49 DISPATCHED TO CPU
5210ms: PROCESS 13 ADDED TO READY QUEUE
5210ms: PROCESS 13 DONE WITH IO
5215ms: PROCESS 49 SENT TO IO QUEUE
5215ms: PROCESS 42 DISPATCHED TO CPU
5232ms: PROCESS 42 FINISHED, TURNAROUND: 0ms, CPU WAIT: 4866ms, IO WAIT: 100ms
5232ms: PROCESS 31 DISPATCHED TO CPU
5235ms: PROCESS 60 ADDED TO READY QUEUE
5235ms: PROCESS 60 DONE WITH IO
5236ms: PROCESS 31 SENT TO IO QUEUE
5236ms: PROCESS 45 DISPATCHED TO CPU
5237ms: PROCESS 45 SENT TO IO QUEUE
5237ms: PROCESS 44 DISPATCHED TO CPU
5258ms: PROCESS 49 ADDED TO READY QUEUE
5258ms: PROCESS 49 DONE WITH IO
5261ms: PROCESS 44 SENT TO IO QUEUE
5261ms: PROCESS 0 DISPATCHED TO CPU
5264ms: PROCESS 31 ADDED TO READY QUEUE
5264ms: PROCESS 31 DONE WITH IO
5281ms: PROCESS 0 SENT TO IO QUEUE
5281ms: PROCESS 3 DISPATCHED TO CPU
5281ms: PROCESS 45 ADDED TO READY QUEUE
5281ms: PROCESS 45 DONE WITH IO
5293ms: PROCESS 3 FINISHED, TURNAROUND: 0ms, CPU WAIT: 4977ms, IO WAIT: 153ms
5293ms: PROCESS 13 DISPATCHED TO CPU
5293ms: PROCESS 44 ADDED TO READY QUEUE
5293ms: PROCESS 44 DONE WITH IO
5296ms: PROCESS 0 ADDED TO READY QUEUE
5296ms: PROCESS 0 DONE WITH IO
5315ms: PROCESS 13 SENT TO IO QUEUE
5315ms: PROCESS 60 DISPATCHED TO CPU
5322ms: PROCESS 60 SENT TO IO QUEUE
5322ms: PROCESS 49 DISPATCHED TO CPU
5329ms: PROCESS 13 ADDED TO READY QUEUE
5329ms: PROCESS 13 DONE WITH IO
5330ms: PROCESS 49 FINISHED, TURNAROUND: 0ms, CPU WAIT: 4960ms, IO WAIT: 163ms
5330ms: PROCESS 31 DISPATCHED TO CPU
5334ms: PROCESS 60 ADDED TO READY QUEUE
5334ms: PROCESS 60 DONE WITH IO
5350ms: PROCESS 31 SENT TO IO QUEUE
5350ms: PROCESS 45 DISPATCHED TO CPU
5360ms: PROCESS 31 ADDED TO READY QUEUE
5360ms: PROCESS 31 DONE WITH IO
5364ms: PROCESS 45 SENT TO IO QUEUE
5364ms: PROCESS 44 DISPATCHED TO CPU
5365ms: PROCESS 44 SENT TO IO QUEUE
5365ms: PROCESS 0 DISPATCHED TO CPU
5366ms: PROCESS 0 SENT TO IO QUEUE
5366ms: PROCESS 13 DISPATCHED TO CPU
5377ms: PROCESS 13 SENT TO IO QUEUE
5377ms: PROCESS 60 DISPATCHED TO CPU
5383ms: PROCESS 60 FINISHED, TURNAROUND: 0ms, CPU WAIT: 4998ms, IO WAIT: 198ms
5383ms: PROCESS 31 DISPATCHED TO CPU
5387ms: PROCESS 45 ADDED TO READY QUEUE
5387ms: PROCESS 45 DONE WITH IO
5399ms: PROCESS 31 SENT TO IO QUEUE
5399ms: PROCESS 45 DISPATCHED TO CPU
5409ms: PROCESS 44 ADDED TO READY QUEUE
5409ms: PROCESS 44 DONE WITH IO
5423ms: PROCESS 45 SENT TO IO QUEUE
5423ms: PROCESS 44 DISPATCHED TO CPU
5428ms: PROCESS 44 SENT TO IO QUEUE
5428ms: PROCESS 8 DISPATCHED TO CPU
5433ms: PROCESS 0 ADDED TO READY QUEUE
5433ms: PROCESS 0 DONE WITH IO
5434ms: PROCESS 8 PREMPTED
5434ms: PROCESS 0 DISPATCHED TO CPU
5434ms: PROCESS 8 ADDED TO READY QUEUE
5438ms: PROCESS 13 ADDED TO READY QUEUE
5438ms: PROCESS 13 DONE WITH IO
5450ms: PROCESS 0 SENT TO IO QUEUE
5450ms: PROCESS 13 DISPATCHED TO CPU
5457ms: PROCESS 31 ADDED TO READY QUEUE
5457ms: PROCESS 31 DONE WITH IO
5458ms: PROCESS 45 ADDED TO READY QUEUE
5458ms: PROCESS 45 DONE WITH IO
5475ms: PROCESS 13 FINISHED, TURNAROUND: 0ms, CPU WAIT: 5004ms, IO WAIT: 232ms
5475ms: PROCESS 31 DISPATCHED TO CPU
5479ms: PROCESS 44 ADDED TO READY QUEUE
5479ms: PROCESS 44 DONE WITH IO
5490ms: PROCESS 31 SENT TO IO QUEUE
5490ms: PROCESS 45 DISPATCHED TO CPU
5493ms: PROCESS 0 ADDED TO READY QUEUE
5493ms: PROCESS 0 DONE WITH IO
5514ms: PROCESS 45 SENT TO IO QUEUE
5514ms: PROCESS 44 DISPATCHED TO CPU
5515ms: PROCESS 31 ADDED TO READY QUEUE
5515ms: PROCESS 31 DONE WITH IO
5524ms: PROCESS 44 FINISHED, TURNAROUND: 0ms, CPU WAIT: 5133ms, IO WAIT: 293ms
5524ms: PROCESS 0 DISPATCHED TO CPU
5540ms: PROCESS 45 ADDED TO READY QUEUE
5540ms: PROCESS 45 DONE WITH IO
5543ms: PROCESS 0 SENT TO IO QUEUE
5543ms: PROCESS 31 DISPATCHED TO CPU
5560ms: PROCESS 0 ADDED TO READY QUEUE
5560ms: PROCESS 0 DONE WITH IO
5562ms: PROCESS 31 SENT TO IO QUEUE
5562ms: PROCESS 45 DISPATCHED TO CPU
5573ms: PROCESS 31 ADDED TO READY QUEUE
5573ms: PROCESS 31 DONE WITH IO
5578ms: PROCESS 45 FINISHED, TURNAROUND: 0ms, CPU WAIT: 4923ms, IO WAIT: 291ms
5578ms: PROCESS 0 DISPATCHED TO CPU
5585ms: PROCESS 0 FINISHED, TURNAROUND: 0ms, CPU WAIT: 5122ms, IO WAIT: 322ms
5585ms: PROCESS 31 DISPATCHED TO CPU
5591ms: PROCESS 31 FINISHED, TURNAROUND: 0ms, CPU WAIT: 5050ms, IO WAIT: 251ms
5591ms: PROCESS 29 DISPATCHED TO CPU
5596ms: PROCESS 29 SENT TO IO QUEUE
5596ms: PROCESS 61 DISPATCHED TO CPU
5604ms: PROCESS 29 ADDED TO READY QUEUE
5604ms: PROCESS 29 DONE WITH IO
5605ms: PROCESS 61 SENT TO IO QUEUE
5605ms: PROCESS 6 DISPATCHED TO CPU
5607ms: PROCESS 61 ADDED TO READY QUEUE
5607ms: PROCESS 61 DONE WITH IO
5609ms: PROCESS 6 FINISHED, TURNAROUND: 0ms, CPU WAIT: 5551ms, IO WAIT: 0ms
5609ms: PROCESS 40 DISPATCHED TO CPU
5615ms: PROCESS 40 SENT TO IO QUEUE
5615ms: PROCESS 95 DISPATCHED TO CPU
5618ms: PROCESS 40 ADDED TO READY QUEUE
5618ms: PROCESS 40 DONE WITH IO
5631ms: PROCESS 95 SENT TO IO QUEUE
5631ms: PROCESS 25 DISPATCHED TO CPU
5634ms: PROCESS 95 ADDED TO READY QUEUE
5634ms: PROCESS 95 DONE WITH IO
5648ms: PROCESS 25 SENT TO IO QUEUE
5648ms: PROCESS 90 DISPATCHED TO CPU
5662ms: PROCESS 90 SENT TO IO QUEUE
5662ms: PROCESS 88 DISPATCHED TO CPU
5673ms: PROCESS 25 ADDED TO READY QUEUE
5673ms: PROCESS 25 DONE WITH IO
5684ms: PROCESS 90 ADDED TO READY QUEUE
5684ms: PROCESS 90 DONE WITH IO
5686ms: PROCESS 88 SENT TO IO QUEUE
5686ms: PROCESS 68 DISPATCHED TO CPU
5689ms: PROCESS 68 SENT TO IO QUEUE
5689ms: PROCESS 83 DISPATCHED TO CPU
5703ms: PROCESS 83 SENT TO IO QUEUE
5703ms: PROCESS 46 DISPATCHED TO CPU
5707ms: PROCESS 88 ADDED TO READY QUEUE
5707ms: PROCESS 88 DONE WITH IO
5716ms: PROCESS 46 SENT TO IO QUEUE
5716ms: PROCESS 8 DISPATCHED TO CPU
5723ms: PROCESS 68 ADDED TO READY QUEUE
5723ms: PROCESS 68 DONE WITH IO
5727ms: PROCESS 8 SENT TO IO QUEUE
5727ms: PROCESS 29 DISPATCHED TO CPU
5735ms: PROCESS 83 ADDED TO READY QUEUE
5735ms: PROCESS 83 DONE WITH IO
5739ms: PROCESS 29 SENT TO IO QUEUE
5739ms: PROCESS 61 DISPATCHED TO CPU
5741ms: PROCESS 46 ADDED TO READY QUEUE
5741ms: PROCESS 46 DONE WITH IO
5742ms: PROCESS 61 SENT TO IO QUEUE
5742ms: PROCESS 40 DISPATCHED TO CPU
5754ms: PROCESS 40 SENT TO IO QUEUE
5754ms: PROCESS 95 DISPATCHED TO CPU
5763ms: PROCESS 95 SENT TO IO QUEUE
5763ms: PROCESS 25 DISPATCHED TO CPU
5763ms: PROCESS 8 ADDED TO READY QUEUE
5763ms: PROCESS 8 DONE WITH IO
5785ms: PROCESS 29 ADDED TO READY QUEUE
5785ms: PROCESS 29 DONE WITH IO
5787ms: PROCESS 25 FINISHED, TURNAROUND: 0ms, CPU WAIT: 5569ms, IO WAIT: 25ms
5787ms: PROCESS 90 DISPATCHED TO CPU
5791ms: PROCESS 61 ADDED TO READY QUEUE
5791ms: PROCESS 61 DONE WITH IO
5792ms: PROCESS 40 ADDED TO READY QUEUE
5792ms: PROCESS 40 DONE WITH IO
5803ms: PROCESS 95 ADDED TO READY QUEUE
5803ms: PROCESS 95 DONE WITH IO
5811ms: PROCESS 90 SENT TO IO QUEUE
5811ms: PROCESS 88 DISPATCHED TO CPU
5812ms: PROCESS 90 ADDED TO READY QUEUE
5812ms: PROCESS 90 DONE WITH IO
5816ms: PROCESS 88 SENT TO IO QUEUE
5816ms: PROCESS 68 DISPATCHED TO CPU
5828ms: PROCESS 68 FINISHED, TURNAROUND: 0ms, CPU WAIT: 5605ms, IO WAIT: 34ms
5828ms: PROCESS 83 DISPATCHED TO CPU
5840ms: PROCESS 88 ADDED TO READY QUEUE
5840ms: PROCESS 88 DONE WITH IO
5847ms: PROCESS 83 SENT TO IO QUEUE
5847ms: PROCESS 46 DISPATCHED TO CPU
5849ms: PROCESS 46 SENT TO IO QUEUE
5849ms: PROCESS 8 DISPATCHED TO CPU
5854ms: PROCESS 83 ADDED TO READY QUEUE
5854ms: PROCESS 83 DONE WITH IO
5858ms: PROCESS 8 FINISHED, TURNAROUND: 0ms, CPU WAIT: 5797ms, IO WAIT: 36ms
5858ms: PROCESS 29 DISPATCHED TO CPU
5873ms: PROCESS 46 ADDED TO READY QUEUE
5873ms: PROCESS 46 DONE WITH IO
5878ms: PROCESS 29 FINISHED, TURNAROUND: 0ms, CPU WAIT: 5781ms, IO WAIT: 54ms
5878ms: PROCESS 61 DISPATCHED TO CPU
5885ms: PROCESS 61 SENT TO IO QUEUE
5885ms: PROCESS 40 DISPATCHED TO CPU
5888ms: PROCESS 40 SENT TO IO QUEUE
5888ms: PROCESS 95 DISPATCHED TO CPU
5890ms: PROCESS 95 SENT TO IO QUEUE
5890ms: PROCESS 90 DISPATCHED TO CPU
5904ms: PROCESS 61 ADDED TO READY QUEUE
5904ms: PROCESS 61 DONE WITH IO
5914ms: PROCESS 90 SENT TO IO QUEUE
5914ms: PROCESS 88 DISPATCHED TO CPU
5918ms: PROCESS 40 ADDED TO READY QUEUE
5918ms: PROCESS 40 DONE WITH IO
5921ms: PROCESS 88 SENT TO IO QUEUE
5921ms: PROCESS 83 DISPATCHED TO CPU
5924ms: PROCESS 95 ADDED TO READY QUEUE
5924ms: PROCESS 95 DONE WITH IO
5925ms: PROCESS 83 SENT TO IO QUEUE
5925ms: PROCESS 46 DISPATCHED TO CPU
5935ms: PROCESS 46 SENT TO IO QUEUE
5935ms: PROCESS 61 DISPATCHED TO CPU
5946ms: PROCESS 90 ADDED TO READY QUEUE
5946ms: PROCESS 90 DONE WITH IO
5948ms: PROCESS 88 ADDED TO READY QUEUE
5948ms: PROCESS 88 DONE WITH IO
5949ms: PROCESS 61 SENT TO IO QUEUE
5949ms: PROCESS 40 DISPATCHED TO CPU
5965ms: PROCESS 83 ADDED TO READY QUEUE
5965ms: PROCESS 83 DONE WITH IO
5973ms: PROCESS 40 SENT TO IO QUEUE
5973ms: PROCESS 95 DISPATCHED TO CPU
5974ms: PROCESS 46 ADDED TO READY QUEUE
5974ms: PROCESS 46 DONE WITH IO
5994ms: PROCESS 61 ADDED TO READY QUEUE
5994ms: PROCESS 61 DONE WITH IO
5995ms: PROCESS 95 SENT TO IO QUEUE
5995ms: PROCESS 90 DISPATCHED TO CPU
5997ms: PROCESS 40 ADDED TO READY QUEUE
5997ms: PROCESS 40 DONE WITH IO
6002ms: PROCESS 90 SENT TO IO QUEUE
6002ms: PROCESS 88 DISPATCHED TO CPU
6015ms: PROCESS 88 SENT TO IO QUEUE
6015ms: PROCESS 83 DISPATCHED TO CPU
6016ms: PROCESS 83 SENT TO IO QUEUE
6016ms: PROCESS 46 DISPATCHED TO CPU
6018ms: PROCESS 95 ADDED TO READY QUEUE
6018ms: PROCESS 95 DONE WITH IO
6024ms: PROCESS 46 SENT TO IO QUEUE
6024ms: PROCESS 61 DISPATCHED TO CPU
6027ms: PROCESS 61 SENT TO IO QUEUE
6027ms: PROCESS 40 DISPATCHED TO CPU
6041ms: PROCESS 40 SENT TO IO QUEUE
6041ms: PROCESS 95 DISPATCHED TO CPU
6043ms: PROCESS 90 ADDED TO READY QUEUE
6043ms: PROCESS 90 DONE WITH IO
6046ms: PROCESS 95 SENT TO IO QUEUE
6046ms: PROCESS 90 DISPATCHED TO CPU
6052ms: PROCESS 88 ADDED TO READY QUEUE
6052ms: PROCESS 88 DONE WITH IO
6056ms: PROCESS 90 SENT TO IO QUEUE
6056ms: PROCESS 88 DISPATCHED TO CPU
6064ms: PROCESS 88 SENT TO IO QUEUE
6064ms: PROCESS 87 DISPATCHED TO CPU
6070ms: PROCESS 87 SENT TO IO QUEUE
6070ms: PROCESS 37 DISPATCHED TO CPU
6077ms: PROCESS 83 ADDED TO READY QUEUE
6077ms: PROCESS 83 DONE WITH IO
6078ms: PROCESS 37 PREMPTED
6078ms: PROCESS 83 DISPATCHED TO CPU
6078ms: PROCESS 37 ADDED TO READY QUEUE
6088ms: PROCESS 83 SENT TO IO QUEUE
6088ms: PROCESS 89 DISPATCHED TO CPU
6091ms: PROCESS 89 SENT TO IO QUEUE
6091ms: PROCESS 9 DISPATCHED TO CPU
6100ms: PROCESS 46 ADDED TO READY QUEUE
6100ms: PROCESS 46 DONE WITH IO
6101ms: PROCESS 9 PREMPTED
6101ms: PROCESS 46 DISPATCHED TO CPU
6101ms: PROCESS 9 ADDED TO READY QUEUE
6106ms: PROCESS 61 ADDED TO READY QUEUE
6106ms: PROCESS 61 DONE WITH IO
6117ms: PROCESS 46 SENT TO IO QUEUE
6117ms: PROCESS 61 DISPATCHED TO CPU
6119ms: PROCESS 40 ADDED TO READY QUEUE
6119ms: PROCESS 40 DONE WITH IO
6130ms: PROCESS 95 ADDED TO READY QUEUE
6130ms: PROCESS 95 DONE WITH IO
6134ms: PROCESS 61 SENT TO IO QUEUE
6134ms: PROCESS 40 DISPATCHED TO CPU
6137ms: PROCESS 90 ADDED TO READY QUEUE
6137ms: PROCESS 90 DONE WITH IO
6148ms: PROCESS 40 FINISHED, TURNAROUND: 0ms, CPU WAIT: 5809ms, IO WAIT: 173ms
6148ms: PROCESS 95 DISPATCHED TO CPU
6152ms: PROCESS 88 ADDED TO READY QUEUE
6152ms: PROCESS 88 DONE WITH IO
6155ms: PROCESS 87 ADDED TO READY QUEUE
6155ms: PROCESS 87 DONE WITH IO
6161ms: PROCESS 95 SENT TO IO QUEUE
6161ms: PROCESS 90 DISPATCHED TO CPU
6168ms: PROCESS 83 ADDED TO READY QUEUE
6168ms: PROCESS 83 DONE WITH IO
6176ms: PROCESS 89 ADDED TO READY QUEUE
6176ms: PROCESS 89 DONE WITH IO
6178ms: PROCESS 90 SENT TO IO QUEUE
6178ms: PROCESS 88 DISPATCHED TO CPU
6178ms: PROCESS 46 ADDED TO READY QUEUE
6178ms: PROCESS 46 DONE WITH IO
6184ms: PROCESS 88 SENT TO IO QUEUE
6184ms: PROCESS 83 DISPATCHED TO CPU
6190ms: PROCESS 61 ADDED TO READY QUEUE
6190ms: PROCESS 61 DONE WITH IO
6201ms: PROCESS 95 ADDED TO READY QUEUE
6201ms: PROCESS 95 DONE WITH IO
6203ms: PROCESS 90 ADDED TO READY QUEUE
6203ms: PROCESS 90 DONE WITH IO
6204ms: PROCESS 83 SENT TO IO QUEUE
6204ms: PROCESS 46 DISPATCHED TO CPU
6212ms: PROCESS 88 ADDED TO READY QUEUE
6212ms: PROCESS 88 DONE WITH IO
6213ms: PROCESS 46 FINISHED, TURNAROUND: 0ms, CPU WAIT: 5692ms, IO WAIT: 225ms
6213ms: PROCESS 61 DISPATCHED TO CPU
6227ms: PROCESS 61 SENT TO IO QUEUE
6227ms: PROCESS 95 DISPATCHED TO CPU
6230ms: PROCESS 83 ADDED TO READY QUEUE
6230ms: PROCESS 83 DONE WITH IO
6248ms: PROCESS 95 FINISHED, TURNAROUND: 0ms, CPU WAIT: 5812ms, IO WAIT: 224ms
6248ms: PROCESS 90 DISPATCHED TO CPU
6250ms: PROCESS 90 FINISHED, TURNAROUND: 0ms, CPU WAIT: 5785ms, IO WAIT: 202ms
6250ms: PROCESS 88 DISPATCHED TO CPU
6253ms: PROCESS 61 ADDED TO READY QUEUE
6253ms: PROCESS 61 DONE WITH IO
6256ms: PROCESS 88 SENT TO IO QUEUE
6256ms: PROCESS 83 DISPATCHED TO CPU
6257ms: PROCESS 83 SENT TO IO QUEUE
6257ms: PROCESS 61 DISPATCHED TO CPU
6273ms: PROCESS 88 ADDED TO READY QUEUE
6273ms: PROCESS 88 DONE WITH IO
6274ms: PROCESS 61 SENT TO IO QUEUE
6274ms: PROCESS 88 DISPATCHED TO CPU
6282ms: PROCESS 88 FINISHED, TURNAROUND: 0ms, CPU WAIT: 5797ms, IO WAIT: 242ms
6282ms: PROCESS 20 DISPATCHED TO CPU
6292ms: PROCESS 83 ADDED TO READY QUEUE
6292ms: PROCESS 83 DONE WITH IO
6293ms: PROCESS 20 PREMPTED
6293ms: PROCESS 83 DISPATCHED TO CPU
6293ms: PROCESS 20 ADDED TO READY QUEUE
6307ms: PROCESS 61 ADDED TO READY QUEUE
6307ms: PROCESS 61 DONE WITH IO
6316ms: PROCESS 83 SENT TO IO QUEUE
6316ms: PROCESS 61 DISPATCHED TO CPU
6328ms: PROCESS 61 SENT TO IO QUEUE
6328ms: PROCESS 71 DISPATCHED TO CPU
6331ms: PROCESS 83 ADDED TO READY QUEUE
6331ms: PROCESS 83 DONE WITH IO
6332ms: PROCESS 71 PREMPTED
6332ms: PROCESS 83 DISPATCHED TO CPU
6332ms: PROCESS 71 ADDED TO READY QUEUE
6336ms: PROCESS 61 ADDED TO READY QUEUE
6336ms: PROCESS 61 DONE WITH IO
6347ms: PROCESS 83 SENT TO IO QUEUE
6347ms: PROCESS 61 DISPATCHED TO CPU
6360ms: PROCESS 61 FINISHED, TURNAROUND: 0ms, CPU WAIT: 5903ms, IO WAIT: 317ms
6360ms: PROCESS 54 DISPATCHED TO CPU
6372ms: PROCESS 83 ADDED TO READY QUEUE
6372ms: PROCESS 83 DONE WITH IO
6373ms: PROCESS 54 PREMPTED
6373ms: PROCESS 83 DISPATCHED TO CPU
6373ms: PROCESS 54 ADDED TO READY QUEUE
6392ms: PROCESS 83 SENT TO IO QUEUE
6392ms: PROCESS 80 DISPATCHED TO CPU
6406ms: PROCESS 83 ADDED TO READY QUEUE
6406ms: PROCESS 83 DONE WITH IO
6407ms: PROCESS 80 PREMPTED
6407ms: PROCESS 83 DISPATCHED TO CPU
6407ms: PROCESS 80 ADDED TO READY QUEUE
6431ms: PROCESS 83 FINISHED, TURNAROUND: 0ms, CPU WAIT: 5750ms, IO WAIT: 335ms
6431ms: PROCESS 69 DISPATCHED TO CPU
6446ms: PROCESS 69 SENT TO IO QUEUE
6446ms: PROCESS 1 DISPATCHED TO CPU
6447ms: PROCESS 1 SENT TO IO QUEUE
6447ms: PROCESS 96 DISPATCHED TO CPU
6453ms: PROCESS 69 ADDED TO READY QUEUE
6453ms: PROCESS 69 DONE WITH IO
6468ms: PROCESS 96 SENT TO IO QUEUE
6468ms: PROCESS 91 DISPATCHED TO CPU
6472ms: PROCESS 91 SENT TO IO QUEUE
6472ms: PROCESS 37 DISPATCHED TO CPU
6473ms: PROCESS 1 ADDED TO READY QUEUE
6473ms: PROCESS 1 DONE WITH IO
6477ms: PROCESS 37 SENT TO IO QUEUE
6477ms: PROCESS 9 DISPATCHED TO CPU
6477ms: PROCESS 96 ADDED TO READY QUEUE
6477ms: PROCESS 96 DONE WITH IO
6484ms: PROCESS 9 SENT TO IO QUEUE
6484ms: PROCESS 87 DISPATCHED TO CPU
6497ms: PROCESS 91 ADDED TO READY QUEUE
6497ms: PROCESS 91 DONE WITH IO
6499ms: PROCESS 37 ADDED TO READY QUEUE
6499ms: PROCESS 37 DONE WITH IO
6501ms: PROCESS 87 SENT TO IO QUEUE
6501ms: PROCESS 89 DISPATCHED TO CPU
6507ms: PROCESS 89 SENT TO IO QUEUE
6507ms: PROCESS 20 DISPATCHED TO CPU
6520ms: PROCESS 20 SENT TO IO QUEUE
6520ms: PROCESS 71 DISPATCHED TO CPU
6524ms: PROCESS 9 ADDED TO READY QUEUE
6524ms: PROCESS 9 DONE WITH IO
6532ms: PROCESS 71 SENT TO IO QUEUE
6532ms: PROCESS 54 DISPATCHED TO CPU
6539ms: PROCESS 54 SENT TO IO QUEUE
6539ms: PROCESS 80 DISPATCHED TO CPU
6546ms: PROCESS 87 ADDED TO READY QUEUE
6546ms: PROCESS 87 DONE WITH IO
6548ms: PROCESS 80 SENT TO IO QUEUE
6548ms: PROCESS 69 DISPATCHED TO CPU
6555ms: PROCESS 89 ADDED TO READY QUEUE
6555ms: PROCESS 89 DONE WITH IO
6566ms: PROCESS 69 SENT TO IO QUEUE
6566ms: PROCESS 1 DISPATCHED TO CPU
6568ms: PROCESS 20 ADDED TO READY QUEUE
6568ms: PROCESS 20 DONE WITH IO
6569ms: PROCESS 71 ADDED TO READY QUEUE
6569ms: PROCESS 71 DONE WITH IO
6590ms: PROCESS 1 SENT TO IO QUEUE
6590ms: PROCESS 96 DISPATCHED TO CPU
6593ms: PROCESS 54 ADDED TO READY QUEUE
6593ms: PROCESS 54 DONE WITH IO
6596ms: PROCESS 96 SENT TO IO QUEUE
6596ms: PROCESS 91 DISPATCHED TO CPU
6599ms: PROCESS 91 SENT TO IO QUEUE
6599ms: PROCESS 37 DISPATCHED TO CPU
6618ms: PROCESS 80 ADDED TO READY QUEUE
6618ms: PROCESS 80 DONE WITH IO
6621ms: PROCESS 37 FINISHED, TURNAROUND: 0ms, CPU WAIT: 6531ms, IO WAIT: 22ms
6621ms: PROCESS 9 DISPATCHED TO CPU
6628ms: PROCESS 9 SENT TO IO QUEUE
6628ms: PROCESS 87 DISPATCHED TO CPU
6640ms: PROCESS 69 ADDED TO READY QUEUE
6640ms: PROCESS 69 DONE WITH IO
6642ms: PROCESS 87 SENT TO IO QUEUE
6642ms: PROCESS 89 DISPATCHED TO CPU
6645ms: PROCESS 89 SENT TO IO QUEUE
6645ms: PROCESS 20 DISPATCHED TO CPU
6651ms: PROCESS 1 ADDED TO READY QUEUE
6651ms: PROCESS 1 DONE WITH IO
6662ms: PROCESS 96 ADDED TO READY QUEUE
6662ms: PROCESS 96 DONE WITH IO
6666ms: PROCESS 20 SENT TO IO QUEUE
6666ms: PROCESS 71 DISPATCHED TO CPU
6678ms: PROCESS 91 ADDED TO READY QUEUE
6678ms: PROCESS 91 DONE WITH IO
6690ms: PROCESS 71 SENT TO IO QUEUE
6690ms: PROCESS 54 DISPATCHED TO CPU
6693ms: PROCESS 9 ADDED TO READY QUEUE
6693ms: PROCESS 9 DONE WITH IO
6699ms: PROCESS 54 SENT TO IO QUEUE
6699ms: PROCESS 80 DISPATCHED TO CPU
6701ms: PROCESS 87 ADDED TO READY QUEUE
6701ms: PROCESS 87 DONE WITH IO
6716ms: PROCESS 80 SENT TO IO QUEUE
6716ms: PROCESS 69 DISPATCHED TO CPU
6720ms: PROCESS 89 ADDED TO READY QUEUE
6720ms: PROCESS 89 DONE WITH IO
6724ms: PROCESS 69 SENT TO IO QUEUE
6724ms: PROCESS 1 DISPATCHED TO CPU
6727ms: PROCESS 1 SENT TO IO QUEUE
6727ms: PROCESS 96 DISPATCHED TO CPU
6745ms: PROCESS 96 SENT TO IO QUEUE
6745ms: PROCESS 91 DISPATCHED TO CPU
6745ms: PROCESS 20 ADDED TO READY QUEUE
6745ms: PROCESS 20 DONE WITH IO
6761ms: PROCESS 91 SENT TO IO QUEUE
6761ms: PROCESS 9 DISPATCHED TO CPU
6768ms: PROCESS 71 ADDED TO READY QUEUE
6768ms: PROCESS 71 DONE WITH IO
6782ms: PROCESS 9 SENT TO IO QUEUE
6782ms: PROCESS 87 DISPATCHED TO CPU
6793ms: PROCESS 54 ADDED TO READY QUEUE
6793ms: PROCESS 54 DONE WITH IO
6798ms: PROCESS 87 FINISHED, TURNAROUND: 0ms, CPU WAIT: 6524ms, IO WAIT: 189ms
6798ms: PROCESS 89 DISPATCHED TO CPU
6817ms: PROCESS 80 ADDED TO READY QUEUE
6817ms: PROCESS 80 DONE WITH IO
6822ms: PROCESS 89 SENT TO IO QUEUE
6822ms: PROCESS 20 DISPATCHED TO CPU
6834ms: PROCESS 20 SENT TO IO QUEUE
6834ms: PROCESS 71 DISPATCHED TO CPU
6839ms: PROCESS 71 FINISHED, TURNAROUND: 0ms, CPU WAIT: 6603ms, IO WAIT: 115ms
6839ms: PROCESS 54 DISPATCHED TO CPU
6839ms: PROCESS 69 ADDED TO READY QUEUE
6839ms: PROCESS 69 DONE WITH IO
6851ms: PROCESS 54 SENT TO IO QUEUE
6851ms: PROCESS 80 DISPATCHED TO CPU
6857ms: PROCESS 1 ADDED TO READY QUEUE
6857ms: PROCESS 1 DONE WITH IO
6859ms: PROCESS 80 SENT TO IO QUEUE
6859ms: PROCESS 69 DISPATCHED TO CPU
6865ms: PROCESS 69 SENT TO IO QUEUE
6865ms: PROCESS 1 DISPATCHED TO CPU
6873ms: PROCESS 96 ADDED TO READY QUEUE
6873ms: PROCESS 96 DONE WITH IO
6884ms: PROCESS 91 ADDED TO READY QUEUE
6884ms: PROCESS 91 DONE WITH IO
6890ms: PROCESS 1 SENT TO IO QUEUE
6890ms: PROCESS 96 DISPATCHED TO CPU
6903ms: PROCESS 96 SENT TO IO QUEUE
6903ms: PROCESS 91 DISPATCHED TO CPU
6904ms: PROCESS 9 ADDED TO READY QUEUE
6904ms: PROCESS 9 DONE WITH IO
6905ms: PROCESS 91 SENT TO IO QUEUE
6905ms: PROCESS 9 DISPATCHED TO CPU
6907ms: PROCESS 89 ADDED TO READY QUEUE
6907ms: PROCESS 89 DONE WITH IO
6923ms: PROCESS 20 ADDED TO READY QUEUE
6923ms: PROCESS 20 DONE WITH IO
6930ms: PROCESS 9 SENT TO IO QUEUE
6930ms: PROCESS 89 DISPATCHED TO CPU
6935ms: PROCESS 54 ADDED TO READY QUEUE
6935ms: PROCESS 54 DONE WITH IO
6946ms: PROCESS 80 ADDED TO READY QUEUE
6946ms: PROCESS 80 DONE WITH IO
6947ms: PROCESS 89 SENT TO IO QUEUE
6947ms: PROCESS 20 DISPATCHED TO CPU
6956ms: PROCESS 20 SENT TO IO QUEUE
6956ms: PROCESS 54 DISPATCHED TO CPU
6969ms: PROCESS 69 ADDED TO READY QUEUE
6969ms: PROCESS 69 DONE WITH IO
6973ms: PROCESS 54 SENT TO IO QUEUE
6973ms: PROCESS 80 DISPATCHED TO CPU
6978ms: PROCESS 1 ADDED TO READY QUEUE
6978ms: PROCESS 1 DONE WITH IO
6993ms: PROCESS 80 SENT TO IO QUEUE
6993ms: PROCESS 69 DISPATCHED TO CPU
6999ms: PROCESS 96 ADDED TO READY QUEUE
6999ms: PROCESS 96 DONE WITH IO
7011ms: PROCESS 69 SENT TO IO QUEUE
7011ms: PROCESS 1 DISPATCHED TO CPU
7024ms: PROCESS 91 ADDED TO READY QUEUE
7024ms: PROCESS 91 DONE WITH IO
7030ms: PROCESS 9 ADDED TO READY QUEUE
7030ms: PROCESS 9 DONE WITH IO
7033ms: PROCESS 89 ADDED TO READY QUEUE
7033ms: PROCESS 89 DONE WITH IO
7036ms: PROCESS 1 SENT TO IO QUEUE
7036ms: PROCESS 96 DISPATCHED TO CPU
7043ms: PROCESS 20 ADDED TO READY QUEUE
7043ms: PROCESS 20 DONE WITH IO
7047ms: PROCESS 54 ADDED TO READY QUEUE
7047ms: PROCESS 54 DONE WITH IO
7054ms: PROCESS 96 SENT TO IO QUEUE
7054ms: PROCESS 91 DISPATCHED TO CPU
7061ms: PROCESS 80 ADDED TO READY QUEUE
7061ms: PROCESS 80 DONE WITH IO
7066ms: PROCESS 91 SENT TO IO QUEUE
7066ms: PROCESS 9 DISPATCHED TO CPU
7070ms: PROCESS 9 SENT TO IO QUEUE
7070ms: PROCESS 89 DISPATCHED TO CPU
7077ms: PROCESS 69 ADDED TO READY QUEUE
7077ms: PROCESS 69 DONE WITH IO
7078ms: PROCESS 89 SENT TO IO QUEUE
7078ms: PROCESS 20 DISPATCHED TO CPU
7078ms: PROCESS 1 ADDED TO READY QUEUE
7078ms: PROCESS 1 DONE WITH IO
7087ms: PROCESS 96 ADDED TO READY QUEUE
7087ms: PROCESS 96 DONE WITH IO
7090ms: PROCESS 91 ADDED TO READY QUEUE
7090ms: PROCESS 91 DONE WITH IO
7100ms: PROCESS 9 ADDED TO READY QUEUE
7100ms: PROCESS 9 DONE WITH IO
7102ms: PROCESS 20 SENT TO IO QUEUE
7102ms: PROCESS 54 DISPATCHED TO CPU
7111ms: PROCESS 89 ADDED TO READY QUEUE
7111ms: PROCESS 89 DONE WITH IO
7120ms: PROCESS 54 SENT TO IO QUEUE
7120ms: PROCESS 80 DISPATCHED TO CPU
7127ms: PROCESS 20 ADDED TO READY QUEUE
7127ms: PROCESS 20 DONE WITH IO
7128ms: PROCESS 54 ADDED TO READY QUEUE
7128ms: PROCESS 54 DONE WITH IO
7134ms: PROCESS 80 SENT TO IO QUEUE
7134ms: PROCESS 69 DISPATCHED TO CPU
7136ms: PROCESS 80 ADDED TO READY QUEUE
7136ms: PROCESS 80 DONE WITH IO
7151ms: PROCESS 69 FINISHED, TURNAROUND: 0ms, CPU WAIT: 6511ms, IO WAIT: 366ms
7151ms: PROCESS 1 DISPATCHED TO CPU
7163ms: PROCESS 1 SENT TO IO QUEUE
7163ms: PROCESS 96 DISPATCHED TO CPU
7173ms: PROCESS 1 ADDED TO READY QUEUE
7173ms: PROCESS 1 DONE WITH IO
7188ms: PROCESS 96 SENT TO IO QUEUE
7188ms: PROCESS 91 DISPATCHED TO CPU
7190ms: PROCESS 91 SENT TO IO QUEUE
7190ms: PROCESS 9 DISPATCHED TO CPU
7192ms: PROCESS 96 ADDED TO READY QUEUE
7192ms: PROCESS 96 DONE WITH IO
7211ms: PROCESS 91 ADDED TO READY QUEUE
7211ms: PROCESS 91 DONE WITH IO
7214ms: PROCESS 9 FINISHED, TURNAROUND: 0ms, CPU WAIT: 6687ms, IO WAIT: 357ms
7214ms: PROCESS 89 DISPATCHED TO CPU
7216ms: PROCESS 89 SENT TO IO QUEUE
7216ms: PROCESS 20 DISPATCHED TO CPU
7227ms: PROCESS 20 SENT TO IO QUEUE
7227ms: PROCESS 54 DISPATCHED TO CPU
7234ms: PROCESS 54 FINISHED, TURNAROUND: 0ms, CPU WAIT: 6705ms, IO WAIT: 314ms
7234ms: PROCESS 80 DISPATCHED TO CPU
7237ms: PROCESS 80 SENT TO IO QUEUE
7237ms: PROCESS 1 DISPATCHED TO CPU
7238ms: PROCESS 89 ADDED TO READY QUEUE
7238ms: PROCESS 89 DONE WITH IO
7240ms: PROCESS 1 SENT TO IO QUEUE
7240ms: PROCESS 96 DISPATCHED TO CPU
7240ms: PROCESS 20 ADDED TO READY QUEUE
7240ms: PROCESS 20 DONE WITH IO
7257ms: PROCESS 80 ADDED TO READY QUEUE
7257ms: PROCESS 80 DONE WITH IO
7263ms: PROCESS 96 SENT TO IO QUEUE
7263ms: PROCESS 91 DISPATCHED TO CPU
7274ms: PROCESS 1 ADDED TO READY QUEUE
7274ms: PROCESS 1 DONE WITH IO
7287ms: PROCESS 91 SENT TO IO QUEUE
7287ms: PROCESS 89 DISPATCHED TO CPU
7295ms: PROCESS 96 ADDED TO READY QUEUE
7295ms: PROCESS 96 DONE WITH IO
7300ms: PROCESS 91 ADDED TO READY QUEUE
7300ms: PROCESS 91 DONE WITH IO
7303ms: PROCESS 89 SENT TO IO QUEUE
7303ms: PROCESS 20 DISPATCHED TO CPU
7314ms: PROCESS 20 SENT TO IO QUEUE
7314ms: PROCESS 80 DISPATCHED TO CPU
7325ms: PROCESS 89 ADDED TO READY QUEUE
7325ms: PROCESS 89 DONE WITH IO
7331ms: PROCESS 20 ADDED TO READY QUEUE
7331ms: PROCESS 20 DONE WITH IO
7335ms: PROCESS 80 SENT TO IO QUEUE
7335ms: PROCESS 1 DISPATCHED TO CPU
7348ms: PROCESS 80 ADDED TO READY QUEUE
7348ms: PROCESS 80 DONE WITH IO
7360ms: PROCESS 1 FINISHED, TURNAROUND: 0ms, CPU WAIT: 6645ms, IO WAIT: 391ms
7360ms: PROCESS 96 DISPATCHED TO CPU
7366ms: PROCESS 96 SENT TO IO QUEUE
7366ms: PROCESS 91 DISPATCHED TO CPU
7371ms: PROCESS 91 FINISHED, TURNAROUND: 0ms, CPU WAIT: 6676ms, IO WAIT: 404ms
7371ms: PROCESS 89 DISPATCHED TO CPU
7372ms: PROCESS 96 ADDED TO READY QUEUE
7372ms: PROCESS 96 DONE WITH IO
7379ms: PROCESS 89 FINISHED, TURNAROUND: 0ms, CPU WAIT: 6778ms, IO WAIT: 456ms
7379ms: PROCESS 20 DISPATCHED TO CPU
7399ms: PROCESS 20 SENT TO IO QUEUE
7399ms: PROCESS 80 DISPATCHED TO CPU
7411ms: PROCESS 20 ADDED TO READY QUEUE
7411ms: PROCESS 20 DONE WITH IO
7419ms: PROCESS 80 SENT TO IO QUEUE
7419ms: PROCESS 96 DISPATCHED TO CPU
7430ms: PROCESS 96 SENT TO IO QUEUE
7430ms: PROCESS 20 DISPATCHED TO CPU
7443ms: PROCESS 80 ADDED TO READY QUEUE
7443ms: PROCESS 80 DONE WITH IO
7445ms: PROCESS 20 FINISHED, TURNAROUND: 0ms, CPU WAIT: 6856ms, IO WAIT: 370ms
7445ms: PROCESS 80 DISPATCHED TO CPU
7451ms: PROCESS 96 ADDED TO READY QUEUE
7451ms: PROCESS 96 DONE WITH IO
7467ms: PROCESS 80 FINISHED, TURNAROUND: 0ms, CPU WAIT: 6762ms, IO WAIT: 385ms
7467ms: PROCESS 96 DISPATCHED TO CPU
7490ms: PROCESS 96 FINISHED, TURNAROUND: 0ms, CPU WAIT: 6715ms, IO WAIT: 395ms
7490ms: PROCESS 93 DISPATCHED TO CPU
7509ms: PROCESS 93 SENT TO IO QUEUE
7509ms: PROCESS 33 DISPATCHED TO CPU
7513ms: PROCESS 33 SENT TO IO QUEUE
7513ms: PROCESS 30 DISPATCHED TO CPU
7517ms: PROCESS 93 ADDED TO READY QUEUE
7517ms: PROCESS 93 DONE WITH IO
7526ms: PROCESS 33 ADDED TO READY QUEUE
7526ms: PROCESS 33 DONE WITH IO
7531ms: PROCESS 30 SENT TO IO QUEUE
7531ms: PROCESS 81 DISPATCHED TO CPU
7533ms: PROCESS 30 ADDED TO READY QUEUE
7533ms: PROCESS 30 DONE WITH IO
7537ms: PROCESS 81 FINISHED, TURNAROUND: 0ms, CPU WAIT: 7387ms, IO WAIT: 0ms
7537ms: PROCESS 4 DISPATCHED TO CPU
7548ms: PROCESS 4 SENT TO IO QUEUE
7548ms: PROCESS 85 DISPATCHED TO CPU
7552ms: PROCESS 85 SENT TO IO QUEUE
7552ms: PROCESS 75 DISPATCHED TO CPU
7563ms: PROCESS 75 SENT TO IO QUEUE
7563ms: PROCESS 17 DISPATCHED TO CPU
7563ms: PROCESS 4 ADDED TO READY QUEUE
7563ms: PROCESS 4 DONE WITH IO
7568ms: PROCESS 17 SENT TO IO QUEUE
7568ms: PROCESS 65 DISPATCHED TO CPU
7579ms: PROCESS 65 SENT TO IO QUEUE
7579ms: PROCESS 34 DISPATCHED TO CPU
7579ms: PROCESS 85 ADDED TO READY QUEUE
7579ms: PROCESS 85 DONE WITH IO
7594ms: PROCESS 75 ADDED TO READY QUEUE
7594ms: PROCESS 75 DONE WITH IO
7597ms: PROCESS 34 SENT TO IO QUEUE
7597ms: PROCESS 99 DISPATCHED TO CPU
7598ms: PROCESS 17 ADDED TO READY QUEUE
7598ms: PROCESS 17 DONE WITH IO
7609ms: PROCESS 99 SENT TO IO QUEUE
7609ms: PROCESS 93 DISPATCHED TO CPU
7610ms: PROCESS 65 ADDED TO READY QUEUE
7610ms: PROCESS 65 DONE WITH IO
7618ms: PROCESS 93 SENT TO IO QUEUE
7618ms: PROCESS 33 DISPATCHED TO CPU
7629ms: PROCESS 34 ADDED TO READY QUEUE
7629ms: PROCESS 34 DONE WITH IO
7642ms: PROCESS 33 SENT TO IO QUEUE
7642ms: PROCESS 30 DISPATCHED TO CPU
7642ms: PROCESS 99 ADDED TO READY QUEUE
7642ms: PROCESS 99 DONE WITH IO
7661ms: PROCESS 30 SENT TO IO QUEUE
7661ms: PROCESS 4 DISPATCHED TO CPU
7661ms: PROCESS 93 ADDED TO READY QUEUE
7661ms: PROCESS 93 DONE WITH IO
7668ms: PROCESS 4 SENT TO IO QUEUE
7668ms: PROCESS 85 DISPATCHED TO CPU
7680ms: PROCESS 85 SENT TO IO QUEUE
7680ms: PROCESS 75 DISPATCHED TO CPU
7682ms: PROCESS 33 ADDED TO READY QUEUE
7682ms: PROCESS 33 DONE WITH IO
7686ms: PROCESS 75 SENT TO IO QUEUE
7686ms: PROCESS 17 DISPATCHED TO CPU
7693ms: PROCESS 17 FINISHED, TURNAROUND: 0ms, CPU WAIT: 7457ms, IO WAIT: 30ms
7693ms: PROCESS 65 DISPATCHED TO CPU
7706ms: PROCESS 65 SENT TO IO QUEUE
7706ms: PROCESS 34 DISPATCHED TO CPU
7706ms: PROCESS 30 ADDED TO READY QUEUE
7706ms: PROCESS 30 DONE WITH IO
7731ms: PROCESS 34 SENT TO IO QUEUE
7731ms: PROCESS 99 DISPATCHED TO CPU
7731ms: PROCESS 4 ADDED TO READY QUEUE
7731ms: PROCESS 4 DONE WITH IO
7738ms: PROCESS 99 SENT TO IO QUEUE
7738ms: PROCESS 93 DISPATCHED TO CPU
7746ms: PROCESS 85 ADDED TO READY QUEUE
7746ms: PROCESS 85 DONE WITH IO
7752ms: PROCESS 93 FINISHED, TURNAROUND: 0ms, CPU WAIT: 7645ms, IO WAIT: 51ms
7752ms: PROCESS 33 DISPATCHED TO CPU
7763ms: PROCESS 33 SENT TO IO QUEUE
7763ms: PROCESS 30 DISPATCHED TO CPU
7764ms: PROCESS 30 SENT TO IO QUEUE
7764ms: PROCESS 4 DISPATCHED TO CPU
7765ms: PROCESS 75 ADDED TO READY QUEUE
7765ms: PROCESS 75 DONE WITH IO
7771ms: PROCESS 65 ADDED TO READY QUEUE
7771ms: PROCESS 65 DONE WITH IO
7787ms: PROCESS 4 SENT TO IO QUEUE
7787ms: PROCESS 85 DISPATCHED TO CPU
7793ms: PROCESS 34 ADDED TO READY QUEUE
7793ms: PROCESS 34 DONE WITH IO
7797ms: PROCESS 85 SENT TO IO QUEUE
7797ms: PROCESS 75 DISPATCHED TO CPU
7801ms: PROCESS 99 ADDED TO READY QUEUE
7801ms: PROCESS 99 DONE WITH IO
7818ms: PROCESS 75 SENT TO IO QUEUE
7818ms: PROCESS 65 DISPATCHED TO CPU
7823ms: PROCESS 33 ADDED TO READY QUEUE
7823ms: PROCESS 33 DONE WITH IO
7828ms: PROCESS 65 SENT TO IO QUEUE
7828ms: PROCESS 34 DISPATCHED TO CPU
7842ms: PROCESS 34 FINISHED, TURNAROUND: 0ms, CPU WAIT: 7464ms, IO WAIT: 94ms
7842ms: PROCESS 99 DISPATCHED TO CPU
7847ms: PROCESS 30 ADDED TO READY QUEUE
7847ms: PROCESS 30 DONE WITH IO
7848ms: PROCESS 99 SENT TO IO QUEUE
7848ms: PROCESS 33 DISPATCHED TO CPU
7850ms: PROCESS 4 ADDED TO READY QUEUE
7850ms: PROCESS 4 DONE WITH IO
7855ms: PROCESS 33 SENT TO IO QUEUE
7855ms: PROCESS 30 DISPATCHED TO CPU
7855ms: PROCESS 85 ADDED TO READY QUEUE
7855ms: PROCESS 85 DONE WITH IO
7869ms: PROCESS 75 ADDED TO READY QUEUE
7869ms: PROCESS 75 DONE WITH IO
7878ms: PROCESS 30 SENT TO IO QUEUE
7878ms: PROCESS 4 DISPATCHED TO CPU
7883ms: PROCESS 65 ADDED TO READY QUEUE
7883ms: PROCESS 65 DONE WITH IO
7887ms: PROCESS 4 SENT TO IO QUEUE
7887ms: PROCESS 85 DISPATCHED TO CPU
7901ms: PROCESS 99 ADDED TO READY QUEUE
7901ms: PROCESS 99 DONE WITH IO
7904ms: PROCESS 85 SENT TO IO QUEUE
7904ms: PROCESS 75 DISPATCHED TO CPU
7905ms: PROCESS 33 ADDED TO READY QUEUE
7905ms: PROCESS 33 DONE WITH IO
7920ms: PROCESS 30 ADDED TO READY QUEUE
7920ms: PROCESS 30 DONE WITH IO
7924ms: PROCESS 75 SENT TO IO QUEUE
7924ms: PROCESS 65 DISPATCHED TO CPU
7931ms: PROCESS 65 SENT TO IO QUEUE
7931ms: PROCESS 99 DISPATCHED TO CPU
7936ms: PROCESS 4 ADDED TO READY QUEUE
7936ms: PROCESS 4 DONE WITH IO
7941ms: PROCESS 85 ADDED TO READY QUEUE
7941ms: PROCESS 85 DONE WITH IO
7943ms: PROCESS 99 SENT TO IO QUEUE
7943ms: PROCESS 33 DISPATCHED TO CPU
7945ms: PROCESS 33 SENT TO IO QUEUE
7945ms: PROCESS 30 DISPATCHED TO CPU
7953ms: PROCESS 30 FINISHED, TURNAROUND: 0ms, CPU WAIT: 7587ms, IO WAIT: 172ms
7953ms: PROCESS 4 DISPATCHED TO CPU
7957ms: PROCESS 4 FINISHED, TURNAROUND: 0ms, CPU WAIT: 7568ms, IO WAIT: 190ms
7957ms: PROCESS 85 DISPATCHED TO CPU
7965ms: PROCESS 75 ADDED TO READY QUEUE
7965ms: PROCESS 75 DONE WITH IO
7970ms: PROCESS 65 ADDED TO READY QUEUE
7970ms: PROCESS 65 DONE WITH IO
7972ms: PROCESS 85 SENT TO IO QUEUE
7972ms: PROCESS 75 DISPATCHED TO CPU
7983ms: PROCESS 75 SENT TO IO QUEUE
7983ms: PROCESS 65 DISPATCHED TO CPU
7992ms: PROCESS 99 ADDED TO READY QUEUE
7992ms: PROCESS 99 DONE WITH IO
7996ms: PROCESS 65 SENT TO IO QUEUE
7996ms: PROCESS 99 DISPATCHED TO CPU
8003ms: PROCESS 99 SENT TO IO QUEUE
8004ms: PROCESS 33 ADDED TO READY QUEUE
8004ms: PROCESS 33 DONE WITH IO
8005ms: PROCESS 33 DISPATCHED TO CPU
8015ms: PROCESS 85 ADDED TO READY QUEUE
8015ms: PROCESS 85 DONE WITH IO
8025ms: PROCESS 33 SENT TO IO QUEUE
8025ms: PROCESS 85 DISPATCHED TO CPU
8032ms: PROCESS 75 ADDED TO READY QUEUE
8032ms: PROCESS 75 DONE WITH IO
8042ms: PROCESS 85 SENT TO IO QUEUE
8042ms: PROCESS 75 DISPATCHED TO CPU
8045ms: PROCESS 65 ADDED TO READY QUEUE
8045ms: PROCESS 65 DONE WITH IO
8056ms: PROCESS 75 SENT TO IO QUEUE
8056ms: PROCESS 65 DISPATCHED TO CPU
8057ms: PROCESS 65 FINISHED, TURNAROUND: 0ms, CPU WAIT: 7568ms, IO WAIT: 239ms
8068ms: PROCESS 99 ADDED TO READY QUEUE
8068ms: PROCESS 99 DONE WITH IO
8069ms: PROCESS 99 DISPATCHED TO CPU
8078ms: PROCESS 99 FINISHED, TURNAROUND: 0ms, CPU WAIT: 7530ms, IO WAIT: 263ms
8080ms: PROCESS 33 ADDED TO READY QUEUE
8080ms: PROCESS 33 DONE WITH IO
8081ms: PROCESS 33 DISPATCHED TO CPU
8084ms: PROCESS 33 SENT TO IO QUEUE
8084ms: PROCESS 85 ADDED TO READY QUEUE
8084ms: PROCESS 85 DONE WITH IO
8085ms: PROCESS 85 DISPATCHED TO CPU
8100ms: PROCESS 85 SENT TO IO QUEUE
8106ms: PROCESS 75 ADDED TO READY QUEUE
8106ms: PROCESS 75 DONE WITH IO
8107ms: PROCESS 75 DISPATCHED TO CPU
8114ms: PROCESS 33 ADDED TO READY QUEUE
8114ms: PROCESS 33 DONE WITH IO
8122ms: PROCESS 85 ADDED TO READY QUEUE
8122ms: PROCESS 85 DONE WITH IO
8127ms: PROCESS 75 SENT TO IO QUEUE
8127ms: PROCESS 33 DISPATCHED TO CPU
8133ms: PROCESS 33 SENT TO IO QUEUE
8133ms: PROCESS 85 DISPATCHED TO CPU
8142ms: PROCESS 85 SENT TO IO QUEUE
8149ms: PROCESS 75 ADDED TO READY QUEUE
8149ms: PROCESS 75 DONE WITH IO
8150ms: PROCESS 75 DISPATCHED TO CPU
8163ms: PROCESS 33 ADDED TO READY QUEUE
8163ms: PROCESS 33 DONE WITH IO
8171ms: PROCESS 75 SENT TO IO QUEUE
8171ms: PROCESS 33 DISPATCHED TO CPU
8174ms: PROCESS 85 ADDED TO READY QUEUE
8174ms: PROCESS 85 DONE WITH IO
8177ms: PROCESS 75 ADDED TO READY QUEUE
8177ms: PROCESS 75 DONE WITH IO
8179ms: PROCESS 33 SENT TO IO QUEUE
8179ms: PROCESS 85 DISPATCHED TO CPU
8186ms: PROCESS 85 FINISHED, TURNAROUND: 0ms, CPU WAIT: 7605ms, IO WAIT: 327ms
8186ms: PROCESS 75 DISPATCHED TO CPU
8201ms: PROCESS 33 ADDED TO READY QUEUE
8201ms: PROCESS 33 DONE WITH IO
8205ms: PROCESS 75 SENT TO IO QUEUE
8205ms: PROCESS 33 DISPATCHED TO CPU
8223ms: PROCESS 75 ADDED TO READY QUEUE
8223ms: PROCESS 75 DONE WITH IO
8227ms: PROCESS 33 SENT TO IO QUEUE
8227ms: PROCESS 75 DISPATCHED TO CPU
8240ms: PROCESS 75 SENT TO IO QUEUE
8251ms: PROCESS 33 ADDED TO READY QUEUE
8251ms: PROCESS 33 DONE WITH IO
8252ms: PROCESS 33 DISPATCHED TO CPU
8252ms: PROCESS 75 ADDED TO READY QUEUE
8252ms: PROCESS 75 DONE WITH IO
8258ms: PROCESS 33 FINISHED, TURNAROUND: 0ms, CPU WAIT: 7699ms, IO WAIT: 383ms
8258ms: PROCESS 75 DISPATCHED TO CPU
8277ms: PROCESS 75 FINISHED, TURNAROUND: 0ms, CPU WAIT: 7584ms, IO WAIT: 359ms
