0ms: PROCESS 8 ADDED TO READY QUEUE
0ms: PROCESS 82 ADDED TO READY QUEUE
0ms: PROCESS 8 DISPATCHED TO CPU
4ms: PROCESS 43 ADDED TO READY QUEUE
7ms: PROCESS 29 ADDED TO READY QUEUE
8ms: PROCESS 67 ADDED TO READY QUEUE
11ms: PROCESS 21 ADDED TO READY QUEUE
11ms: PROCESS 57 ADDED TO READY QUEUE
15ms: PROCESS 93 ADDED TO READY QUEUE
16ms: PROCESS 8 SENT TO IO QUEUE
16ms: PROCESS 82 DISPATCHED TO CPU
18ms: PROCESS 44 ADDED TO READY QUEUE
21ms: PROCESS 0 ADDED TO READY QUEUE
21ms: PROCESS 28 ADDED TO READY QUEUE
32ms: PROCESS 61 ADDED TO READY QUEUE
33ms: PROCESS 87 ADDED TO READY QUEUE
33ms: PROCESS 82 SENT TO IO QUEUE
33ms: PROCESS 43 DISPATCHED TO CPU
34ms: PROCESS 37 ADDED TO READY QUEUE
38ms: PROCESS 8 ADDED TO READY QUEUE
38ms: PROCESS 8 DONE WITH IO
40ms: PROCESS 82 ADDED TO READY QUEUE
40ms: PROCESS 82 DONE WITH IO
42ms: PROCESS 43 SENT TO IO QUEUE
42ms: PROCESS 29 DISPATCHED TO CPU
43ms: PROCESS 22 ADDED TO READY QUEUE
47ms: PROCESS 29 SENT TO IO QUEUE
47ms: PROCESS 67 DISPATCHED TO CPU
50ms: PROCESS 56 ADDED TO READY QUEUE
55ms: PROCESS 6 ADDED TO READY QUEUE
59ms: PROCESS 63 ADDED TO READY QUEUE
59ms: PROCESS 79 ADDED TO READY QUEUE
59ms: PROCESS 89 ADDED TO READY QUEUE
62ms: PROCESS 94 ADDED TO READY QUEUE
62ms: PROCESS 43 ADDED TO READY QUEUE
62ms: PROCESS 43 DONE WITH IO
63ms: PROCESS 67 SENT TO IO QUEUE
63ms: PROCESS 21 DISPATCHED TO CPU
64ms: PROCESS 33 ADDED TO READY QUEUE
69ms: PROCESS 3 ADDED TO READY QUEUE
70ms: PROCESS 29 ADDED TO READY QUEUE
70ms: PROCESS 29 DONE WITH IO
73ms: PROCESS 9 ADDED TO READY QUEUE
73ms: PROCESS 20 ADDED TO READY QUEUE
73ms: PROCESS 21 SENT TO IO QUEUE
73ms: PROCESS 57 DISPATCHED TO CPU
74ms: PROCESS 10 ADDED TO READY QUEUE
74ms: PROCESS 11 ADDED TO READY QUEUE
74ms: PROCESS 86 ADDED TO READY QUEUE
76ms: PROCESS 74 ADDED TO READY QUEUE
77ms: PROCESS 71 ADDED TO READY QUEUE
78ms: PROCESS 67 ADDED TO READY QUEUE
78ms: PROCESS 67 DONE WITH IO
80ms: PROCESS 66 ADDED TO READY QUEUE
83ms: PROCESS 7 ADDED TO READY QUEUE
86ms: PROCESS 57 SENT TO IO QUEUE
86ms: PROCESS 93 DISPATCHED TO CPU
88ms: PROCESS 26 ADDED TO READY QUEUE
90ms: PROCESS 13 ADDED TO READY QUEUE
92ms: PROCESS 60 ADDED TO READY QUEUE
94ms: PROCESS 40 ADDED TO READY QUEUE
95ms: PROCESS 39 ADDED TO READY QUEUE
96ms: PROCESS 21 ADDED TO READY QUEUE
96ms: PROCESS 21 DONE WITH IO
102ms: PROCESS 57 ADDED TO READY QUEUE
102ms: PROCESS 57 DONE WITH IO
103ms: PROCESS 47 ADDED TO READY QUEUE
105ms: PROCESS 93 SENT TO IO QUEUE
105ms: PROCESS 44 DISPATCHED TO CPU
106ms: PROCESS 48 ADDED TO READY QUEUE
107ms: PROCESS 50 ADDED TO READY QUEUE
109ms: PROCESS 41 ADDED TO READY QUEUE
110ms: PROCESS 49 ADDED TO READY QUEUE
113ms: PROCESS 44 SENT TO IO QUEUE
113ms: PROCESS 0 DISPATCHED TO CPU
113ms: PROCESS 93 ADDED TO READY QUEUE
113ms: PROCESS 93 DONE WITH IO
119ms: PROCESS 58 ADDED TO READY QUEUE
120ms: PROCESS 77 ADDED TO READY QUEUE
121ms: PROCESS 0 SENT TO IO QUEUE
121ms: PROCESS 28 DISPATCHED TO CPU
121ms: PROCESS 44 ADDED TO READY QUEUE
121ms: PROCESS 44 DONE WITH IO
124ms: PROCESS 28 SENT TO IO QUEUE
124ms: PROCESS 61 DISPATCHED TO CPU
125ms: PROCESS 35 ADDED TO READY QUEUE
125ms: PROCESS 95 ADDED TO READY QUEUE
126ms: PROCESS 30 ADDED TO READY QUEUE
132ms: PROCESS 38 ADDED TO READY QUEUE
132ms: PROCESS 59 ADDED TO READY QUEUE
133ms: PROCESS 54 ADDED TO READY QUEUE
133ms: PROCESS 61 SENT TO IO QUEUE
133ms: PROCESS 87 DISPATCHED TO CPU
137ms: PROCESS 0 ADDED TO READY QUEUE
137ms: PROCESS 0 DONE WITH IO
139ms: PROCESS 84 ADDED TO READY QUEUE
139ms: PROCESS 87 SENT TO IO QUEUE
139ms: PROCESS 37 DISPATCHED TO CPU
143ms: PROCESS 92 ADDED TO READY QUEUE
145ms: PROCESS 81 ADDED TO READY QUEUE
146ms: PROCESS 4 ADDED TO READY QUEUE
147ms: PROCESS 28 ADDED TO READY QUEUE
147ms: PROCESS 28 DONE WITH IO
149ms: PROCESS 85 ADDED TO READY QUEUE
149ms: PROCESS 97 ADDED TO READY QUEUE
149ms: PROCESS 61 ADDED TO READY QUEUE
149ms: PROCESS 61 DONE WITH IO
151ms: PROCESS 37 SENT TO IO QUEUE
151ms: PROCESS 8 DISPATCHED TO CPU
152ms: PROCESS 72 ADDED TO READY QUEUE
152ms: PROCESS 87 ADDED TO READY QUEUE
152ms: PROCESS 87 DONE WITH IO
153ms: PROCESS 25 ADDED TO READY QUEUE
154ms: PROCESS 64 ADDED TO READY QUEUE
154ms: PROCESS 73 ADDED TO READY QUEUE
154ms: PROCESS 98 ADDED TO READY QUEUE
154ms: PROCESS 37 ADDED TO READY QUEUE
154ms: PROCESS 37 DONE WITH IO
158ms: PROCESS 14 ADDED TO READY QUEUE
160ms: PROCESS 75 ADDED TO READY QUEUE
160ms: PROCESS 8 FINISHED, TURNAROUND: 0ms, CPU WAIT: 114ms, IO WAIT: 22ms
160ms: PROCESS 82 DISPATCHED TO CPU
161ms: PROCESS 78 ADDED TO READY QUEUE
165ms: PROCESS 42 ADDED TO READY QUEUE
166ms: PROCESS 2 ADDED TO READY QUEUE
166ms: PROCESS 90 ADDED TO READY QUEUE
167ms: PROCESS 24 ADDED TO READY QUEUE
167ms: PROCESS 88 ADDED TO READY QUEUE
170ms: PROCESS 31 ADDED TO READY QUEUE
172ms: PROCESS 80 ADDED TO READY QUEUE
175ms: PROCESS 68 ADDED TO READY QUEUE
176ms: PROCESS 82 SENT TO IO QUEUE
176ms: PROCESS 22 DISPATCHED TO CPU
179ms: PROCESS 22 SENT TO IO QUEUE
179ms: PROCESS 56 DISPATCHED TO CPU
179ms: PROCESS 82 ADDED TO READY QUEUE
179ms: PROCESS 82 DONE WITH IO
182ms: PROCESS 32 ADDED TO READY QUEUE
183ms: PROCESS 56 SENT TO IO QUEUE
183ms: PROCESS 6 DISPATCHED TO CPU
186ms: PROCESS 36 ADDED TO READY QUEUE
187ms: PROCESS 6 FINISHED, TURNAROUND: 0ms, CPU WAIT: 129ms, IO WAIT: 0ms
187ms: PROCESS 63 DISPATCHED TO CPU
193ms: PROCESS 69 ADDED TO READY QUEUE
194ms: PROCESS 12 ADDED TO READY QUEUE
195ms: PROCESS 17 ADDED TO READY QUEUE
196ms: PROCESS 65 ADDED TO READY QUEUE
196ms: PROCESS 22 ADDED TO READY QUEUE
196ms: PROCESS 22 DONE WITH IO
197ms: PROCESS 83 ADDED TO READY QUEUE
200ms: PROCESS 18 ADDED TO READY QUEUE
200ms: PROCESS 70 ADDED TO READY QUEUE
204ms: PROCESS 63 SENT TO IO QUEUE
204ms: PROCESS 79 DISPATCHED TO CPU
207ms: PROCESS 1 ADDED TO READY QUEUE
213ms: PROCESS 53 ADDED TO READY QUEUE
213ms: PROCESS 55 ADDED TO READY QUEUE
213ms: PROCESS 79 SENT TO IO QUEUE
213ms: PROCESS 89 DISPATCHED TO CPU
216ms: PROCESS 89 SENT TO IO QUEUE
216ms: PROCESS 94 DISPATCHED TO CPU
217ms: PROCESS 51 ADDED TO READY QUEUE
217ms: PROCESS 96 ADDED TO READY QUEUE
218ms: PROCESS 19 ADDED TO READY QUEUE
218ms: PROCESS 56 ADDED TO READY QUEUE
218ms: PROCESS 56 DONE WITH IO
219ms: PROCESS 16 ADDED TO READY QUEUE
224ms: PROCESS 91 ADDED TO READY QUEUE
225ms: PROCESS 45 ADDED TO READY QUEUE
226ms: PROCESS 52 ADDED TO READY QUEUE
228ms: PROCESS 34 ADDED TO READY QUEUE
232ms: PROCESS 94 SENT TO IO QUEUE
232ms: PROCESS 43 DISPATCHED TO CPU
233ms: PROCESS 62 ADDED TO READY QUEUE
233ms: PROCESS 99 ADDED TO READY QUEUE
235ms: PROCESS 27 ADDED TO READY QUEUE
235ms: PROCESS 63 ADDED TO READY QUEUE
235ms: PROCESS 63 DONE WITH IO
236ms: PROCESS 15 ADDED TO READY QUEUE
237ms: PROCESS 79 ADDED TO READY QUEUE
237ms: PROCESS 79 DONE WITH IO
238ms: PROCESS 5 ADDED TO READY QUEUE
239ms: PROCESS 46 ADDED TO READY QUEUE
241ms: PROCESS 23 ADDED TO READY QUEUE
242ms: PROCESS 76 ADDED TO READY QUEUE
245ms: PROCESS 89 ADDED TO READY QUEUE
245ms: PROCESS 89 DONE WITH IO
253ms: PROCESS 43 SENT TO IO QUEUE
253ms: PROCESS 33 DISPATCHED TO CPU
257ms: PROCESS 33 SENT TO IO QUEUE
257ms: PROCESS 3 DISPATCHED TO CPU
264ms: PROCESS 94 ADDED TO READY QUEUE
264ms: PROCESS 94 DONE WITH IO
265ms: PROCESS 3 SENT TO IO QUEUE
265ms: PROCESS 29 DISPATCHED TO CPU
277ms: PROCESS 29 SENT TO IO QUEUE
277ms: PROCESS 9 DISPATCHED TO CPU
278ms: PROCESS 43 ADDED TO READY QUEUE
278ms: PROCESS 43 DONE WITH IO
287ms: PROCESS 33 ADDED TO READY QUEUE
287ms: PROCESS 33 DONE WITH IO
293ms: PROCESS 9 SENT TO IO QUEUE
293ms: PROCESS 20 DISPATCHED TO CPU
