5ms: PROCESS 0 ADDED TO READY QUEUE
5ms: PROCESS 0 DISPATCHED TO CPU
6ms: PROCESS 4 ADDED TO READY QUEUE
6ms: PROCESS 5 ADDED TO READY QUEUE
7ms: PROCESS 2 ADDED TO READY QUEUE
9ms: PROCESS 0 PREMPTED
9ms: PROCESS 4 DISPATCHED TO CPU
9ms: PROCESS 0 ADDED TO READY QUEUE
10ms: PROCESS 1 ADDED TO READY QUEUE
10ms: PROCESS 3 ADDED TO READY QUEUE
12ms: PROCESS 4 PREMPTED
12ms: PROCESS 5 DISPATCHED TO CPU
12ms: PROCESS 4 ADDED TO READY QUEUE
15ms: PROCESS 5 PREMPTED
15ms: PROCESS 2 DISPATCHED TO CPU
15ms: PROCESS 5 ADDED TO READY QUEUE
18ms: PROCESS 9 ADDED TO READY QUEUE
18ms: PROCESS 2 PREMPTED
18ms: PROCESS 0 DISPATCHED TO CPU
18ms: PROCESS 2 ADDED TO READY QUEUE
19ms: PROCESS 7 ADDED TO READY QUEUE
21ms: PROCESS 6 ADDED TO READY QUEUE
21ms: PROCESS 0 PREMPTED
21ms: PROCESS 1 DISPATCHED TO CPU
21ms: PROCESS 0 ADDED TO READY QUEUE
22ms: PROCESS 8 ADDED TO READY QUEUE
24ms: PROCESS 1 PREMPTED
24ms: PROCESS 3 DISPATCHED TO CPU
24ms: PROCESS 1 ADDED TO READY QUEUE
27ms: PROCESS 3 PREMPTED
27ms: PROCESS 4 DISPATCHED TO CPU
27ms: PROCESS 3 ADDED TO READY QUEUE
30ms: PROCESS 4 PREMPTED
30ms: PROCESS 5 DISPATCHED TO CPU
30ms: PROCESS 4 ADDED TO READY QUEUE
33ms: PROCESS 5 PREMPTED
33ms: PROCESS 9 DISPATCHED TO CPU
33ms: PROCESS 5 ADDED TO READY QUEUE
34ms: PROCESS 9 SENT TO IO QUEUE
34ms: PROCESS 2 DISPATCHED TO CPU
38ms: PROCESS 2 PREMPTED
38ms: PROCESS 7 DISPATCHED TO CPU
38ms: PROCESS 2 ADDED TO READY QUEUE
41ms: PROCESS 7 PREMPTED
41ms: PROCESS 6 DISPATCHED TO CPU
41ms: PROCESS 7 ADDED TO READY QUEUE
41ms: PROCESS 9 ADDED TO READY QUEUE
41ms: PROCESS 9 DONE WITH IO
44ms: PROCESS 6 PREMPTED
44ms: PROCESS 0 DISPATCHED TO CPU
44ms: PROCESS 6 ADDED TO READY QUEUE
47ms: PROCESS 0 PREMPTED
47ms: PROCESS 8 DISPATCHED TO CPU
47ms: PROCESS 0 ADDED TO READY QUEUE
50ms: PROCESS 8 PREMPTED
50ms: PROCESS 1 DISPATCHED TO CPU
50ms: PROCESS 8 ADDED TO READY QUEUE
53ms: PROCESS 1 PREMPTED
53ms: PROCESS 3 DISPATCHED TO CPU
53ms: PROCESS 1 ADDED TO READY QUEUE
55ms: PROCESS 3 SENT TO IO QUEUE
55ms: PROCESS 4 DISPATCHED TO CPU
59ms: PROCESS 4 PREMPTED
59ms: PROCESS 5 DISPATCHED TO CPU
59ms: PROCESS 4 ADDED TO READY QUEUE
62ms: PROCESS 5 PREMPTED
62ms: PROCESS 2 DISPATCHED TO CPU
62ms: PROCESS 5 ADDED TO READY QUEUE
65ms: PROCESS 2 PREMPTED
65ms: PROCESS 7 DISPATCHED TO CPU
65ms: PROCESS 2 ADDED TO READY QUEUE
68ms: PROCESS 7 PREMPTED
68ms: PROCESS 9 DISPATCHED TO CPU
68ms: PROCESS 7 ADDED TO READY QUEUE
70ms: PROCESS 9 SENT TO IO QUEUE
70ms: PROCESS 6 DISPATCHED TO CPU
74ms: PROCESS 6 PREMPTED
74ms: PROCESS 0 DISPATCHED TO CPU
74ms: PROCESS 6 ADDED TO READY QUEUE
74ms: PROCESS 3 ADDED TO READY QUEUE
74ms: PROCESS 3 DONE WITH IO
77ms: PROCESS 0 PREMPTED
77ms: PROCESS 8 DISPATCHED TO CPU
77ms: PROCESS 0 ADDED TO READY QUEUE
80ms: PROCESS 8 PREMPTED
80ms: PROCESS 1 DISPATCHED TO CPU
80ms: PROCESS 8 ADDED TO READY QUEUE
80ms: PROCESS 9 ADDED TO READY QUEUE
80ms: PROCESS 9 DONE WITH IO
83ms: PROCESS 1 PREMPTED
83ms: PROCESS 4 DISPATCHED TO CPU
83ms: PROCESS 1 ADDED TO READY QUEUE
86ms: PROCESS 4 PREMPTED
86ms: PROCESS 5 DISPATCHED TO CPU
86ms: PROCESS 4 ADDED TO READY QUEUE
89ms: PROCESS 5 PREMPTED
89ms: PROCESS 2 DISPATCHED TO CPU
89ms: PROCESS 5 ADDED TO READY QUEUE
92ms: PROCESS 2 PREMPTED
92ms: PROCESS 7 DISPATCHED TO CPU
92ms: PROCESS 2 ADDED TO READY QUEUE
92ms: PROCESS 7 SENT TO IO QUEUE
92ms: PROCESS 6 DISPATCHED TO CPU
96ms: PROCESS 6 PREMPTED
96ms: PROCESS 3 DISPATCHED TO CPU
96ms: PROCESS 6 ADDED TO READY QUEUE
99ms: PROCESS 3 PREMPTED
99ms: PROCESS 0 DISPATCHED TO CPU
99ms: PROCESS 3 ADDED TO READY QUEUE
102ms: PROCESS 0 PREMPTED
102ms: PROCESS 8 DISPATCHED TO CPU
102ms: PROCESS 0 ADDED TO READY QUEUE
104ms: PROCESS 7 ADDED TO READY QUEUE
104ms: PROCESS 7 DONE WITH IO
105ms: PROCESS 8 PREMPTED
105ms: PROCESS 9 DISPATCHED TO CPU
105ms: PROCESS 8 ADDED TO READY QUEUE
108ms: PROCESS 9 PREMPTED
108ms: PROCESS 1 DISPATCHED TO CPU
108ms: PROCESS 9 ADDED TO READY QUEUE
111ms: PROCESS 1 PREMPTED
111ms: PROCESS 4 DISPATCHED TO CPU
111ms: PROCESS 1 ADDED TO READY QUEUE
111ms: PROCESS 4 FINISHED, TURNAROUND: 0ms, CPU WAIT: 93ms, IO WAIT: 0ms
111ms: PROCESS 5 DISPATCHED TO CPU
115ms: PROCESS 5 PREMPTED
115ms: PROCESS 2 DISPATCHED TO CPU
115ms: PROCESS 5 ADDED TO READY QUEUE
118ms: PROCESS 2 PREMPTED
118ms: PROCESS 6 DISPATCHED TO CPU
118ms: PROCESS 2 ADDED TO READY QUEUE
121ms: PROCESS 6 PREMPTED
121ms: PROCESS 3 DISPATCHED TO CPU
121ms: PROCESS 6 ADDED TO READY QUEUE
124ms: PROCESS 3 PREMPTED
124ms: PROCESS 0 DISPATCHED TO CPU
124ms: PROCESS 3 ADDED TO READY QUEUE
126ms: PROCESS 0 SENT TO IO QUEUE
126ms: PROCESS 7 DISPATCHED TO CPU
130ms: PROCESS 7 PREMPTED
130ms: PROCESS 8 DISPATCHED TO CPU
130ms: PROCESS 7 ADDED TO READY QUEUE
130ms: PROCESS 0 ADDED TO READY QUEUE
130ms: PROCESS 0 DONE WITH IO
133ms: PROCESS 8 PREMPTED
133ms: PROCESS 9 DISPATCHED TO CPU
133ms: PROCESS 8 ADDED TO READY QUEUE
136ms: PROCESS 9 PREMPTED
136ms: PROCESS 1 DISPATCHED TO CPU
136ms: PROCESS 9 ADDED TO READY QUEUE
139ms: PROCESS 1 PREMPTED
139ms: PROCESS 5 DISPATCHED TO CPU
139ms: PROCESS 1 ADDED TO READY QUEUE
142ms: PROCESS 5 PREMPTED
142ms: PROCESS 2 DISPATCHED TO CPU
142ms: PROCESS 5 ADDED TO READY QUEUE
145ms: PROCESS 2 PREMPTED
145ms: PROCESS 6 DISPATCHED TO CPU
145ms: PROCESS 2 ADDED TO READY QUEUE
148ms: PROCESS 6 PREMPTED
148ms: PROCESS 3 DISPATCHED TO CPU
148ms: PROCESS 6 ADDED TO READY QUEUE
151ms: PROCESS 3 PREMPTED
151ms: PROCESS 7 DISPATCHED TO CPU
151ms: PROCESS 3 ADDED TO READY QUEUE
154ms: PROCESS 7 PREMPTED
154ms: PROCESS 0 DISPATCHED TO CPU
154ms: PROCESS 7 ADDED TO READY QUEUE
157ms: PROCESS 0 PREMPTED
157ms: PROCESS 8 DISPATCHED TO CPU
157ms: PROCESS 0 ADDED TO READY QUEUE
160ms: PROCESS 8 PREMPTED
160ms: PROCESS 9 DISPATCHED TO CPU
160ms: PROCESS 8 ADDED TO READY QUEUE
163ms: PROCESS 9 PREMPTED
163ms: PROCESS 1 DISPATCHED TO CPU
163ms: PROCESS 9 ADDED TO READY QUEUE
166ms: PROCESS 1 PREMPTED
166ms: PROCESS 5 DISPATCHED TO CPU
166ms: PROCESS 1 ADDED TO READY QUEUE
166ms: PROCESS 5 FINISHED, TURNAROUND: 0ms, CPU WAIT: 142ms, IO WAIT: 0ms
166ms: PROCESS 2 DISPATCHED TO CPU
170ms: PROCESS 2 PREMPTED
170ms: PROCESS 6 DISPATCHED TO CPU
170ms: PROCESS 2 ADDED TO READY QUEUE
173ms: PROCESS 6 PREMPTED
173ms: PROCESS 3 DISPATCHED TO CPU
173ms: PROCESS 6 ADDED TO READY QUEUE
176ms: PROCESS 3 PREMPTED
176ms: PROCESS 7 DISPATCHED TO CPU
176ms: PROCESS 3 ADDED TO READY QUEUE
176ms: PROCESS 7 SENT TO IO QUEUE
176ms: PROCESS 0 DISPATCHED TO CPU
179ms: PROCESS 0 SENT TO IO QUEUE
179ms: PROCESS 8 DISPATCHED TO CPU
180ms: PROCESS 8 SENT TO IO QUEUE
180ms: PROCESS 9 DISPATCHED TO CPU
181ms: PROCESS 9 SENT TO IO QUEUE
181ms: PROCESS 1 DISPATCHED TO CPU
185ms: PROCESS 1 PREMPTED
185ms: PROCESS 2 DISPATCHED TO CPU
185ms: PROCESS 1 ADDED TO READY QUEUE
186ms: PROCESS 2 SENT TO IO QUEUE
186ms: PROCESS 6 DISPATCHED TO CPU
189ms: PROCESS 7 ADDED TO READY QUEUE
189ms: PROCESS 7 DONE WITH IO
190ms: PROCESS 6 PREMPTED
190ms: PROCESS 3 DISPATCHED TO CPU
190ms: PROCESS 6 ADDED TO READY QUEUE
193ms: PROCESS 3 PREMPTED
193ms: PROCESS 1 DISPATCHED TO CPU
193ms: PROCESS 3 ADDED TO READY QUEUE
194ms: PROCESS 1 SENT TO IO QUEUE
194ms: PROCESS 7 DISPATCHED TO CPU
198ms: PROCESS 7 PREMPTED
198ms: PROCESS 6 DISPATCHED TO CPU
198ms: PROCESS 7 ADDED TO READY QUEUE
201ms: PROCESS 6 PREMPTED
201ms: PROCESS 3 DISPATCHED TO CPU
201ms: PROCESS 6 ADDED TO READY QUEUE
204ms: PROCESS 3 PREMPTED
204ms: PROCESS 7 DISPATCHED TO CPU
204ms: PROCESS 3 ADDED TO READY QUEUE
207ms: PROCESS 7 PREMPTED
207ms: PROCESS 6 DISPATCHED TO CPU
207ms: PROCESS 7 ADDED TO READY QUEUE
207ms: PROCESS 6 SENT TO IO QUEUE
207ms: PROCESS 3 DISPATCHED TO CPU
208ms: PROCESS 0 ADDED TO READY QUEUE
208ms: PROCESS 0 DONE WITH IO
211ms: PROCESS 3 PREMPTED
211ms: PROCESS 7 DISPATCHED TO CPU
211ms: PROCESS 3 ADDED TO READY QUEUE
214ms: PROCESS 7 PREMPTED
214ms: PROCESS 0 DISPATCHED TO CPU
214ms: PROCESS 7 ADDED TO READY QUEUE
217ms: PROCESS 0 PREMPTED
217ms: PROCESS 3 DISPATCHED TO CPU
217ms: PROCESS 0 ADDED TO READY QUEUE
219ms: PROCESS 8 ADDED TO READY QUEUE
219ms: PROCESS 8 DONE WITH IO
220ms: PROCESS 3 PREMPTED
220ms: PROCESS 7 DISPATCHED TO CPU
220ms: PROCESS 3 ADDED TO READY QUEUE
220ms: PROCESS 7 SENT TO IO QUEUE
220ms: PROCESS 0 DISPATCHED TO CPU
223ms: PROCESS 0 SENT TO IO QUEUE
223ms: PROCESS 8 DISPATCHED TO CPU
227ms: PROCESS 8 PREMPTED
227ms: PROCESS 3 DISPATCHED TO CPU
227ms: PROCESS 8 ADDED TO READY QUEUE
227ms: PROCESS 3 SENT TO IO QUEUE
227ms: PROCESS 8 DISPATCHED TO CPU
233ms: PROCESS 9 ADDED TO READY QUEUE
233ms: PROCESS 9 DONE WITH IO
237ms: PROCESS 8 PREMPTED
237ms: PROCESS 9 DISPATCHED TO CPU
237ms: PROCESS 8 ADDED TO READY QUEUE
240ms: PROCESS 9 PREMPTED
240ms: PROCESS 8 DISPATCHED TO CPU
240ms: PROCESS 9 ADDED TO READY QUEUE
243ms: PROCESS 8 PREMPTED
243ms: PROCESS 9 DISPATCHED TO CPU
243ms: PROCESS 8 ADDED TO READY QUEUE
244ms: PROCESS 9 SENT TO IO QUEUE
244ms: PROCESS 8 DISPATCHED TO CPU
254ms: PROCESS 8 FINISHED, TURNAROUND: 0ms, CPU WAIT: 151ms, IO WAIT: 39ms
256ms: PROCESS 2 ADDED TO READY QUEUE
256ms: PROCESS 2 DONE WITH IO
257ms: PROCESS 2 DISPATCHED TO CPU
268ms: PROCESS 1 ADDED TO READY QUEUE
268ms: PROCESS 1 DONE WITH IO
272ms: PROCESS 2 PREMPTED
272ms: PROCESS 1 DISPATCHED TO CPU
272ms: PROCESS 2 ADDED TO READY QUEUE
275ms: PROCESS 1 PREMPTED
275ms: PROCESS 2 DISPATCHED TO CPU
275ms: PROCESS 1 ADDED TO READY QUEUE
278ms: PROCESS 2 PREMPTED
278ms: PROCESS 1 DISPATCHED TO CPU
278ms: PROCESS 2 ADDED TO READY QUEUE
281ms: PROCESS 1 PREMPTED
281ms: PROCESS 2 DISPATCHED TO CPU
281ms: PROCESS 1 ADDED TO READY QUEUE
282ms: PROCESS 2 SENT TO IO QUEUE
282ms: PROCESS 1 DISPATCHED TO CPU
283ms: PROCESS 6 ADDED TO READY QUEUE
283ms: PROCESS 6 DONE WITH IO
287ms: PROCESS 1 PREMPTED
287ms: PROCESS 6 DISPATCHED TO CPU
287ms: PROCESS 1 ADDED TO READY QUEUE
290ms: PROCESS 6 PREMPTED
290ms: PROCESS 1 DISPATCHED TO CPU
290ms: PROCESS 6 ADDED TO READY QUEUE
293ms: PROCESS 1 PREMPTED
293ms: PROCESS 6 DISPATCHED TO CPU
293ms: PROCESS 1 ADDED TO READY QUEUE
296ms: PROCESS 6 PREMPTED
296ms: PROCESS 1 DISPATCHED TO CPU
296ms: PROCESS 6 ADDED TO READY QUEUE
299ms: PROCESS 1 PREMPTED
299ms: PROCESS 6 DISPATCHED TO CPU
299ms: PROCESS 1 ADDED TO READY QUEUE
302ms: PROCESS 6 PREMPTED
302ms: PROCESS 1 DISPATCHED TO CPU
302ms: PROCESS 6 ADDED TO READY QUEUE
303ms: PROCESS 7 ADDED TO READY QUEUE
303ms: PROCESS 7 DONE WITH IO
305ms: PROCESS 1 PREMPTED
305ms: PROCESS 6 DISPATCHED TO CPU
305ms: PROCESS 1 ADDED TO READY QUEUE
307ms: PROCESS 0 ADDED TO READY QUEUE
307ms: PROCESS 0 DONE WITH IO
308ms: PROCESS 6 PREMPTED
308ms: PROCESS 7 DISPATCHED TO CPU
308ms: PROCESS 6 ADDED TO READY QUEUE
311ms: PROCESS 7 PREMPTED
311ms: PROCESS 1 DISPATCHED TO CPU
311ms: PROCESS 7 ADDED TO READY QUEUE
314ms: PROCESS 1 PREMPTED
314ms: PROCESS 0 DISPATCHED TO CPU
314ms: PROCESS 1 ADDED TO READY QUEUE
317ms: PROCESS 0 PREMPTED
317ms: PROCESS 6 DISPATCHED TO CPU
317ms: PROCESS 0 ADDED TO READY QUEUE
320ms: PROCESS 6 PREMPTED
320ms: PROCESS 7 DISPATCHED TO CPU
320ms: PROCESS 6 ADDED TO READY QUEUE
323ms: PROCESS 7 PREMPTED
323ms: PROCESS 1 DISPATCHED TO CPU
323ms: PROCESS 7 ADDED TO READY QUEUE
323ms: PROCESS 1 SENT TO IO QUEUE
323ms: PROCESS 0 DISPATCHED TO CPU
326ms: PROCESS 3 ADDED TO READY QUEUE
326ms: PROCESS 3 DONE WITH IO
327ms: PROCESS 0 PREMPTED
327ms: PROCESS 6 DISPATCHED TO CPU
327ms: PROCESS 0 ADDED TO READY QUEUE
330ms: PROCESS 6 PREMPTED
330ms: PROCESS 7 DISPATCHED TO CPU
330ms: PROCESS 6 ADDED TO READY QUEUE
333ms: PROCESS 7 PREMPTED
333ms: PROCESS 3 DISPATCHED TO CPU
333ms: PROCESS 7 ADDED TO READY QUEUE
336ms: PROCESS 3 PREMPTED
336ms: PROCESS 0 DISPATCHED TO CPU
336ms: PROCESS 3 ADDED TO READY QUEUE
339ms: PROCESS 0 PREMPTED
339ms: PROCESS 6 DISPATCHED TO CPU
339ms: PROCESS 0 ADDED TO READY QUEUE
340ms: PROCESS 6 SENT TO IO QUEUE
340ms: PROCESS 7 DISPATCHED TO CPU
344ms: PROCESS 7 PREMPTED
344ms: PROCESS 3 DISPATCHED TO CPU
344ms: PROCESS 7 ADDED TO READY QUEUE
345ms: PROCESS 9 ADDED TO READY QUEUE
345ms: PROCESS 9 DONE WITH IO
347ms: PROCESS 3 PREMPTED
347ms: PROCESS 0 DISPATCHED TO CPU
347ms: PROCESS 3 ADDED TO READY QUEUE
348ms: PROCESS 0 SENT TO IO QUEUE
348ms: PROCESS 7 DISPATCHED TO CPU
352ms: PROCESS 7 PREMPTED
352ms: PROCESS 9 DISPATCHED TO CPU
352ms: PROCESS 7 ADDED TO READY QUEUE
355ms: PROCESS 9 PREMPTED
355ms: PROCESS 3 DISPATCHED TO CPU
355ms: PROCESS 9 ADDED TO READY QUEUE
358ms: PROCESS 3 PREMPTED
358ms: PROCESS 7 DISPATCHED TO CPU
358ms: PROCESS 3 ADDED TO READY QUEUE
358ms: PROCESS 2 ADDED TO READY QUEUE
358ms: PROCESS 2 DONE WITH IO
360ms: PROCESS 1 ADDED TO READY QUEUE
360ms: PROCESS 1 DONE WITH IO
361ms: PROCESS 7 PREMPTED
361ms: PROCESS 9 DISPATCHED TO CPU
361ms: PROCESS 7 ADDED TO READY QUEUE
364ms: PROCESS 9 PREMPTED
364ms: PROCESS 3 DISPATCHED TO CPU
364ms: PROCESS 9 ADDED TO READY QUEUE
366ms: PROCESS 3 SENT TO IO QUEUE
366ms: PROCESS 2 DISPATCHED TO CPU
370ms: PROCESS 2 PREMPTED
370ms: PROCESS 1 DISPATCHED TO CPU
370ms: PROCESS 2 ADDED TO READY QUEUE
370ms: PROCESS 6 ADDED TO READY QUEUE
370ms: PROCESS 6 DONE WITH IO
373ms: PROCESS 1 PREMPTED
373ms: PROCESS 7 DISPATCHED TO CPU
373ms: PROCESS 1 ADDED TO READY QUEUE
376ms: PROCESS 7 PREMPTED
376ms: PROCESS 9 DISPATCHED TO CPU
376ms: PROCESS 7 ADDED TO READY QUEUE
379ms: PROCESS 9 PREMPTED
379ms: PROCESS 2 DISPATCHED TO CPU
379ms: PROCESS 9 ADDED TO READY QUEUE
382ms: PROCESS 2 PREMPTED
382ms: PROCESS 6 DISPATCHED TO CPU
382ms: PROCESS 2 ADDED TO READY QUEUE
385ms: PROCESS 6 PREMPTED
385ms: PROCESS 1 DISPATCHED TO CPU
385ms: PROCESS 6 ADDED TO READY QUEUE
388ms: PROCESS 1 PREMPTED
388ms: PROCESS 7 DISPATCHED TO CPU
388ms: PROCESS 1 ADDED TO READY QUEUE
391ms: PROCESS 7 PREMPTED
391ms: PROCESS 9 DISPATCHED TO CPU
391ms: PROCESS 7 ADDED TO READY QUEUE
394ms: PROCESS 9 PREMPTED
394ms: PROCESS 2 DISPATCHED TO CPU
394ms: PROCESS 9 ADDED TO READY QUEUE
394ms: PROCESS 0 ADDED TO READY QUEUE
394ms: PROCESS 0 DONE WITH IO
397ms: PROCESS 2 PREMPTED
397ms: PROCESS 6 DISPATCHED TO CPU
397ms: PROCESS 2 ADDED TO READY QUEUE
400ms: PROCESS 6 PREMPTED
400ms: PROCESS 1 DISPATCHED TO CPU
400ms: PROCESS 6 ADDED TO READY QUEUE
403ms: PROCESS 1 PREMPTED
403ms: PROCESS 7 DISPATCHED TO CPU
403ms: PROCESS 1 ADDED TO READY QUEUE
403ms: PROCESS 7 SENT TO IO QUEUE
403ms: PROCESS 9 DISPATCHED TO CPU
404ms: PROCESS 9 SENT TO IO QUEUE
404ms: PROCESS 0 DISPATCHED TO CPU
407ms: PROCESS 3 ADDED TO READY QUEUE
407ms: PROCESS 3 DONE WITH IO
408ms: PROCESS 0 PREMPTED
408ms: PROCESS 2 DISPATCHED TO CPU
408ms: PROCESS 0 ADDED TO READY QUEUE
411ms: PROCESS 2 PREMPTED
411ms: PROCESS 6 DISPATCHED TO CPU
411ms: PROCESS 2 ADDED TO READY QUEUE
414ms: PROCESS 6 PREMPTED
414ms: PROCESS 1 DISPATCHED TO CPU
414ms: PROCESS 6 ADDED TO READY QUEUE
417ms: PROCESS 1 PREMPTED
417ms: PROCESS 3 DISPATCHED TO CPU
417ms: PROCESS 1 ADDED TO READY QUEUE
420ms: PROCESS 3 PREMPTED
420ms: PROCESS 0 DISPATCHED TO CPU
420ms: PROCESS 3 ADDED TO READY QUEUE
421ms: PROCESS 7 ADDED TO READY QUEUE
421ms: PROCESS 7 DONE WITH IO
423ms: PROCESS 0 PREMPTED
423ms: PROCESS 2 DISPATCHED TO CPU
423ms: PROCESS 0 ADDED TO READY QUEUE
426ms: PROCESS 2 PREMPTED
426ms: PROCESS 6 DISPATCHED TO CPU
426ms: PROCESS 2 ADDED TO READY QUEUE
429ms: PROCESS 6 PREMPTED
429ms: PROCESS 1 DISPATCHED TO CPU
429ms: PROCESS 6 ADDED TO READY QUEUE
432ms: PROCESS 1 PREMPTED
432ms: PROCESS 3 DISPATCHED TO CPU
432ms: PROCESS 1 ADDED TO READY QUEUE
432ms: PROCESS 9 ADDED TO READY QUEUE
432ms: PROCESS 9 DONE WITH IO
433ms: PROCESS 3 SENT TO IO QUEUE
433ms: PROCESS 7 DISPATCHED TO CPU
437ms: PROCESS 7 PREMPTED
437ms: PROCESS 0 DISPATCHED TO CPU
437ms: PROCESS 7 ADDED TO READY QUEUE
440ms: PROCESS 0 PREMPTED
440ms: PROCESS 2 DISPATCHED TO CPU
440ms: PROCESS 0 ADDED TO READY QUEUE
442ms: PROCESS 2 FINISHED, TURNAROUND: 0ms, CPU WAIT: 229ms, IO WAIT: 146ms
442ms: PROCESS 6 DISPATCHED TO CPU
446ms: PROCESS 6 PREMPTED
446ms: PROCESS 1 DISPATCHED TO CPU
446ms: PROCESS 6 ADDED TO READY QUEUE
449ms: PROCESS 1 PREMPTED
449ms: PROCESS 9 DISPATCHED TO CPU
449ms: PROCESS 1 ADDED TO READY QUEUE
451ms: PROCESS 9 SENT TO IO QUEUE
451ms: PROCESS 7 DISPATCHED TO CPU
452ms: PROCESS 3 ADDED TO READY QUEUE
452ms: PROCESS 3 DONE WITH IO
455ms: PROCESS 7 PREMPTED
455ms: PROCESS 0 DISPATCHED TO CPU
455ms: PROCESS 7 ADDED TO READY QUEUE
458ms: PROCESS 0 PREMPTED
458ms: PROCESS 6 DISPATCHED TO CPU
458ms: PROCESS 0 ADDED TO READY QUEUE
461ms: PROCESS 6 PREMPTED
461ms: PROCESS 1 DISPATCHED TO CPU
461ms: PROCESS 6 ADDED TO READY QUEUE
462ms: PROCESS 9 ADDED TO READY QUEUE
462ms: PROCESS 9 DONE WITH IO
464ms: PROCESS 1 PREMPTED
464ms: PROCESS 3 DISPATCHED TO CPU
464ms: PROCESS 1 ADDED TO READY QUEUE
467ms: PROCESS 3 PREMPTED
467ms: PROCESS 7 DISPATCHED TO CPU
467ms: PROCESS 3 ADDED TO READY QUEUE
470ms: PROCESS 7 PREMPTED
470ms: PROCESS 0 DISPATCHED TO CPU
470ms: PROCESS 7 ADDED TO READY QUEUE
473ms: PROCESS 0 PREMPTED
473ms: PROCESS 6 DISPATCHED TO CPU
473ms: PROCESS 0 ADDED TO READY QUEUE
476ms: PROCESS 6 PREMPTED
476ms: PROCESS 9 DISPATCHED TO CPU
476ms: PROCESS 6 ADDED TO READY QUEUE
479ms: PROCESS 9 PREMPTED
479ms: PROCESS 1 DISPATCHED TO CPU
479ms: PROCESS 9 ADDED TO READY QUEUE
481ms: PROCESS 1 SENT TO IO QUEUE
481ms: PROCESS 3 DISPATCHED TO CPU
485ms: PROCESS 3 PREMPTED
485ms: PROCESS 7 DISPATCHED TO CPU
485ms: PROCESS 3 ADDED TO READY QUEUE
488ms: PROCESS 7 PREMPTED
488ms: PROCESS 0 DISPATCHED TO CPU
488ms: PROCESS 7 ADDED TO READY QUEUE
491ms: PROCESS 0 PREMPTED
491ms: PROCESS 6 DISPATCHED TO CPU
491ms: PROCESS 0 ADDED TO READY QUEUE
492ms: PROCESS 1 ADDED TO READY QUEUE
492ms: PROCESS 1 DONE WITH IO
494ms: PROCESS 6 PREMPTED
494ms: PROCESS 9 DISPATCHED TO CPU
494ms: PROCESS 6 ADDED TO READY QUEUE
497ms: PROCESS 9 PREMPTED
497ms: PROCESS 3 DISPATCHED TO CPU
497ms: PROCESS 9 ADDED TO READY QUEUE
500ms: PROCESS 3 PREMPTED
500ms: PROCESS 7 DISPATCHED TO CPU
500ms: PROCESS 3 ADDED TO READY QUEUE
503ms: PROCESS 7 PREMPTED
503ms: PROCESS 0 DISPATCHED TO CPU
503ms: PROCESS 7 ADDED TO READY QUEUE
504ms: PROCESS 0 SENT TO IO QUEUE
504ms: PROCESS 1 DISPATCHED TO CPU
508ms: PROCESS 1 PREMPTED
508ms: PROCESS 6 DISPATCHED TO CPU
508ms: PROCESS 1 ADDED TO READY QUEUE
508ms: PROCESS 6 SENT TO IO QUEUE
508ms: PROCESS 9 DISPATCHED TO CPU
512ms: PROCESS 9 PREMPTED
512ms: PROCESS 3 DISPATCHED TO CPU
512ms: PROCESS 9 ADDED TO READY QUEUE
515ms: PROCESS 3 PREMPTED
515ms: PROCESS 7 DISPATCHED TO CPU
515ms: PROCESS 3 ADDED TO READY QUEUE
518ms: PROCESS 7 PREMPTED
518ms: PROCESS 1 DISPATCHED TO CPU
518ms: PROCESS 7 ADDED TO READY QUEUE
518ms: PROCESS 0 ADDED TO READY QUEUE
518ms: PROCESS 0 DONE WITH IO
521ms: PROCESS 1 PREMPTED
521ms: PROCESS 9 DISPATCHED TO CPU
521ms: PROCESS 1 ADDED TO READY QUEUE
524ms: PROCESS 9 PREMPTED
524ms: PROCESS 3 DISPATCHED TO CPU
524ms: PROCESS 9 ADDED TO READY QUEUE
527ms: PROCESS 3 PREMPTED
527ms: PROCESS 7 DISPATCHED TO CPU
527ms: PROCESS 3 ADDED TO READY QUEUE
530ms: PROCESS 7 PREMPTED
530ms: PROCESS 0 DISPATCHED TO CPU
530ms: PROCESS 7 ADDED TO READY QUEUE
531ms: PROCESS 6 ADDED TO READY QUEUE
531ms: PROCESS 6 DONE WITH IO
533ms: PROCESS 0 PREMPTED
533ms: PROCESS 1 DISPATCHED TO CPU
533ms: PROCESS 0 ADDED TO READY QUEUE
536ms: PROCESS 1 PREMPTED
536ms: PROCESS 9 DISPATCHED TO CPU
536ms: PROCESS 1 ADDED TO READY QUEUE
539ms: PROCESS 9 PREMPTED
539ms: PROCESS 3 DISPATCHED TO CPU
539ms: PROCESS 9 ADDED TO READY QUEUE
542ms: PROCESS 3 PREMPTED
542ms: PROCESS 7 DISPATCHED TO CPU
542ms: PROCESS 3 ADDED TO READY QUEUE
545ms: PROCESS 7 PREMPTED
545ms: PROCESS 6 DISPATCHED TO CPU
545ms: PROCESS 7 ADDED TO READY QUEUE
548ms: PROCESS 6 PREMPTED
548ms: PROCESS 0 DISPATCHED TO CPU
548ms: PROCESS 6 ADDED TO READY QUEUE
551ms: PROCESS 0 PREMPTED
551ms: PROCESS 1 DISPATCHED TO CPU
551ms: PROCESS 0 ADDED TO READY QUEUE
554ms: PROCESS 1 PREMPTED
554ms: PROCESS 9 DISPATCHED TO CPU
554ms: PROCESS 1 ADDED TO READY QUEUE
557ms: PROCESS 9 PREMPTED
557ms: PROCESS 3 DISPATCHED TO CPU
557ms: PROCESS 9 ADDED TO READY QUEUE
558ms: PROCESS 3 SENT TO IO QUEUE
558ms: PROCESS 7 DISPATCHED TO CPU
559ms: PROCESS 7 SENT TO IO QUEUE
559ms: PROCESS 6 DISPATCHED TO CPU
560ms: PROCESS 6 SENT TO IO QUEUE
560ms: PROCESS 0 DISPATCHED TO CPU
564ms: PROCESS 0 PREMPTED
564ms: PROCESS 1 DISPATCHED TO CPU
564ms: PROCESS 0 ADDED TO READY QUEUE
567ms: PROCESS 1 PREMPTED
567ms: PROCESS 9 DISPATCHED TO CPU
567ms: PROCESS 1 ADDED TO READY QUEUE
570ms: PROCESS 9 PREMPTED
570ms: PROCESS 0 DISPATCHED TO CPU
570ms: PROCESS 9 ADDED TO READY QUEUE
571ms: PROCESS 3 ADDED TO READY QUEUE
571ms: PROCESS 3 DONE WITH IO
573ms: PROCESS 0 PREMPTED
573ms: PROCESS 1 DISPATCHED TO CPU
573ms: PROCESS 0 ADDED TO READY QUEUE
576ms: PROCESS 1 PREMPTED
576ms: PROCESS 9 DISPATCHED TO CPU
576ms: PROCESS 1 ADDED TO READY QUEUE
577ms: PROCESS 9 FINISHED, TURNAROUND: 0ms, CPU WAIT: 296ms, IO WAIT: 209ms
577ms: PROCESS 3 DISPATCHED TO CPU
581ms: PROCESS 3 PREMPTED
581ms: PROCESS 0 DISPATCHED TO CPU
581ms: PROCESS 3 ADDED TO READY QUEUE
584ms: PROCESS 0 PREMPTED
584ms: PROCESS 1 DISPATCHED TO CPU
584ms: PROCESS 0 ADDED TO READY QUEUE
584ms: PROCESS 1 SENT TO IO QUEUE
584ms: PROCESS 3 DISPATCHED TO CPU
587ms: PROCESS 7 ADDED TO READY QUEUE
587ms: PROCESS 7 DONE WITH IO
588ms: PROCESS 3 PREMPTED
588ms: PROCESS 0 DISPATCHED TO CPU
588ms: PROCESS 3 ADDED TO READY QUEUE
590ms: PROCESS 0 SENT TO IO QUEUE
590ms: PROCESS 7 DISPATCHED TO CPU
594ms: PROCESS 7 PREMPTED
594ms: PROCESS 3 DISPATCHED TO CPU
594ms: PROCESS 7 ADDED TO READY QUEUE
595ms: PROCESS 6 ADDED TO READY QUEUE
595ms: PROCESS 6 DONE WITH IO
597ms: PROCESS 3 PREMPTED
597ms: PROCESS 7 DISPATCHED TO CPU
597ms: PROCESS 3 ADDED TO READY QUEUE
600ms: PROCESS 7 PREMPTED
600ms: PROCESS 6 DISPATCHED TO CPU
600ms: PROCESS 7 ADDED TO READY QUEUE
603ms: PROCESS 6 PREMPTED
603ms: PROCESS 3 DISPATCHED TO CPU
603ms: PROCESS 6 ADDED TO READY QUEUE
606ms: PROCESS 3 PREMPTED
606ms: PROCESS 7 DISPATCHED TO CPU
606ms: PROCESS 3 ADDED TO READY QUEUE
609ms: PROCESS 7 PREMPTED
609ms: PROCESS 6 DISPATCHED TO CPU
609ms: PROCESS 7 ADDED TO READY QUEUE
612ms: PROCESS 6 PREMPTED
612ms: PROCESS 3 DISPATCHED TO CPU
612ms: PROCESS 6 ADDED TO READY QUEUE
615ms: PROCESS 3 PREMPTED
615ms: PROCESS 7 DISPATCHED TO CPU
615ms: PROCESS 3 ADDED TO READY QUEUE
617ms: PROCESS 1 ADDED TO READY QUEUE
617ms: PROCESS 1 DONE WITH IO
618ms: PROCESS 7 PREMPTED
618ms: PROCESS 6 DISPATCHED TO CPU
618ms: PROCESS 7 ADDED TO READY QUEUE
620ms: PROCESS 0 ADDED TO READY QUEUE
620ms: PROCESS 0 DONE WITH IO
621ms: PROCESS 6 PREMPTED
621ms: PROCESS 3 DISPATCHED TO CPU
621ms: PROCESS 6 ADDED TO READY QUEUE
624ms: PROCESS 3 PREMPTED
624ms: PROCESS 1 DISPATCHED TO CPU
624ms: PROCESS 3 ADDED TO READY QUEUE
627ms: PROCESS 1 PREMPTED
627ms: PROCESS 7 DISPATCHED TO CPU
627ms: PROCESS 1 ADDED TO READY QUEUE
630ms: PROCESS 7 PREMPTED
630ms: PROCESS 0 DISPATCHED TO CPU
630ms: PROCESS 7 ADDED TO READY QUEUE
633ms: PROCESS 0 PREMPTED
633ms: PROCESS 6 DISPATCHED TO CPU
633ms: PROCESS 0 ADDED TO READY QUEUE
636ms: PROCESS 6 PREMPTED
636ms: PROCESS 3 DISPATCHED TO CPU
636ms: PROCESS 6 ADDED TO READY QUEUE
639ms: PROCESS 3 PREMPTED
639ms: PROCESS 1 DISPATCHED TO CPU
639ms: PROCESS 3 ADDED TO READY QUEUE
642ms: PROCESS 1 PREMPTED
642ms: PROCESS 7 DISPATCHED TO CPU
642ms: PROCESS 1 ADDED TO READY QUEUE
642ms: PROCESS 7 SENT TO IO QUEUE
642ms: PROCESS 0 DISPATCHED TO CPU
646ms: PROCESS 0 PREMPTED
646ms: PROCESS 6 DISPATCHED TO CPU
646ms: PROCESS 0 ADDED TO READY QUEUE
649ms: PROCESS 6 PREMPTED
649ms: PROCESS 3 DISPATCHED TO CPU
649ms: PROCESS 6 ADDED TO READY QUEUE
649ms: PROCESS 3 SENT TO IO QUEUE
649ms: PROCESS 1 DISPATCHED TO CPU
652ms: PROCESS 1 FINISHED, TURNAROUND: 0ms, CPU WAIT: 391ms, IO WAIT: 155ms
652ms: PROCESS 0 DISPATCHED TO CPU
656ms: PROCESS 0 PREMPTED
656ms: PROCESS 6 DISPATCHED TO CPU
656ms: PROCESS 0 ADDED TO READY QUEUE
659ms: PROCESS 6 PREMPTED
659ms: PROCESS 0 DISPATCHED TO CPU
659ms: PROCESS 6 ADDED TO READY QUEUE
661ms: PROCESS 7 ADDED TO READY QUEUE
661ms: PROCESS 7 DONE WITH IO
662ms: PROCESS 0 PREMPTED
662ms: PROCESS 6 DISPATCHED TO CPU
662ms: PROCESS 0 ADDED TO READY QUEUE
665ms: PROCESS 6 PREMPTED
665ms: PROCESS 7 DISPATCHED TO CPU
665ms: PROCESS 6 ADDED TO READY QUEUE
668ms: PROCESS 7 PREMPTED
668ms: PROCESS 0 DISPATCHED TO CPU
668ms: PROCESS 7 ADDED TO READY QUEUE
671ms: PROCESS 0 PREMPTED
671ms: PROCESS 6 DISPATCHED TO CPU
671ms: PROCESS 0 ADDED TO READY QUEUE
671ms: PROCESS 6 SENT TO IO QUEUE
671ms: PROCESS 7 DISPATCHED TO CPU
675ms: PROCESS 7 PREMPTED
675ms: PROCESS 0 DISPATCHED TO CPU
675ms: PROCESS 7 ADDED TO READY QUEUE
676ms: PROCESS 3 ADDED TO READY QUEUE
676ms: PROCESS 3 DONE WITH IO
678ms: PROCESS 0 PREMPTED
678ms: PROCESS 7 DISPATCHED TO CPU
678ms: PROCESS 0 ADDED TO READY QUEUE
681ms: PROCESS 7 PREMPTED
681ms: PROCESS 3 DISPATCHED TO CPU
681ms: PROCESS 7 ADDED TO READY QUEUE
684ms: PROCESS 3 PREMPTED
684ms: PROCESS 0 DISPATCHED TO CPU
684ms: PROCESS 3 ADDED TO READY QUEUE
687ms: PROCESS 0 PREMPTED
687ms: PROCESS 7 DISPATCHED TO CPU
687ms: PROCESS 0 ADDED TO READY QUEUE
690ms: PROCESS 7 PREMPTED
690ms: PROCESS 3 DISPATCHED TO CPU
690ms: PROCESS 7 ADDED TO READY QUEUE
691ms: PROCESS 6 ADDED TO READY QUEUE
691ms: PROCESS 6 DONE WITH IO
693ms: PROCESS 3 PREMPTED
693ms: PROCESS 0 DISPATCHED TO CPU
693ms: PROCESS 3 ADDED TO READY QUEUE
694ms: PROCESS 0 SENT TO IO QUEUE
694ms: PROCESS 7 DISPATCHED TO CPU
698ms: PROCESS 7 PREMPTED
698ms: PROCESS 6 DISPATCHED TO CPU
698ms: PROCESS 7 ADDED TO READY QUEUE
699ms: PROCESS 0 ADDED TO READY QUEUE
699ms: PROCESS 0 DONE WITH IO
701ms: PROCESS 6 PREMPTED
701ms: PROCESS 3 DISPATCHED TO CPU
701ms: PROCESS 6 ADDED TO READY QUEUE
704ms: PROCESS 3 PREMPTED
704ms: PROCESS 7 DISPATCHED TO CPU
704ms: PROCESS 3 ADDED TO READY QUEUE
707ms: PROCESS 7 PREMPTED
707ms: PROCESS 0 DISPATCHED TO CPU
707ms: PROCESS 7 ADDED TO READY QUEUE
710ms: PROCESS 0 PREMPTED
710ms: PROCESS 6 DISPATCHED TO CPU
710ms: PROCESS 0 ADDED TO READY QUEUE
713ms: PROCESS 6 PREMPTED
713ms: PROCESS 3 DISPATCHED TO CPU
713ms: PROCESS 6 ADDED TO READY QUEUE
716ms: PROCESS 3 PREMPTED
716ms: PROCESS 7 DISPATCHED TO CPU
716ms: PROCESS 3 ADDED TO READY QUEUE
719ms: PROCESS 7 PREMPTED
719ms: PROCESS 0 DISPATCHED TO CPU
719ms: PROCESS 7 ADDED TO READY QUEUE
722ms: PROCESS 0 PREMPTED
722ms: PROCESS 6 DISPATCHED TO CPU
722ms: PROCESS 0 ADDED TO READY QUEUE
725ms: PROCESS 6 PREMPTED
725ms: PROCESS 3 DISPATCHED TO CPU
725ms: PROCESS 6 ADDED TO READY QUEUE
725ms: PROCESS 3 SENT TO IO QUEUE
725ms: PROCESS 7 DISPATCHED TO CPU
728ms: PROCESS 7 SENT TO IO QUEUE
728ms: PROCESS 0 DISPATCHED TO CPU
731ms: PROCESS 0 FINISHED, TURNAROUND: 0ms, CPU WAIT: 403ms, IO WAIT: 212ms
731ms: PROCESS 6 DISPATCHED TO CPU
739ms: PROCESS 6 SENT TO IO QUEUE
744ms: PROCESS 3 ADDED TO READY QUEUE
744ms: PROCESS 3 DONE WITH IO
745ms: PROCESS 3 DISPATCHED TO CPU
747ms: PROCESS 3 SENT TO IO QUEUE
767ms: PROCESS 7 ADDED TO READY QUEUE
767ms: PROCESS 7 DONE WITH IO
768ms: PROCESS 7 DISPATCHED TO CPU
772ms: PROCESS 6 ADDED TO READY QUEUE
772ms: PROCESS 6 DONE WITH IO
776ms: PROCESS 7 PREMPTED
776ms: PROCESS 6 DISPATCHED TO CPU
776ms: PROCESS 7 ADDED TO READY QUEUE
778ms: PROCESS 3 ADDED TO READY QUEUE
778ms: PROCESS 3 DONE WITH IO
779ms: PROCESS 6 PREMPTED
779ms: PROCESS 7 DISPATCHED TO CPU
779ms: PROCESS 6 ADDED TO READY QUEUE
782ms: PROCESS 7 PREMPTED
782ms: PROCESS 3 DISPATCHED TO CPU
782ms: PROCESS 7 ADDED TO READY QUEUE
785ms: PROCESS 3 PREMPTED
785ms: PROCESS 6 DISPATCHED TO CPU
785ms: PROCESS 3 ADDED TO READY QUEUE
788ms: PROCESS 6 PREMPTED
788ms: PROCESS 7 DISPATCHED TO CPU
788ms: PROCESS 6 ADDED TO READY QUEUE
791ms: PROCESS 7 PREMPTED
791ms: PROCESS 3 DISPATCHED TO CPU
791ms: PROCESS 7 ADDED TO READY QUEUE
794ms: PROCESS 3 PREMPTED
794ms: PROCESS 6 DISPATCHED TO CPU
794ms: PROCESS 3 ADDED TO READY QUEUE
797ms: PROCESS 6 PREMPTED
797ms: PROCESS 7 DISPATCHED TO CPU
797ms: PROCESS 6 ADDED TO READY QUEUE
800ms: PROCESS 7 PREMPTED
800ms: PROCESS 3 DISPATCHED TO CPU
800ms: PROCESS 7 ADDED TO READY QUEUE
803ms: PROCESS 3 PREMPTED
803ms: PROCESS 6 DISPATCHED TO CPU
803ms: PROCESS 3 ADDED TO READY QUEUE
804ms: PROCESS 6 SENT TO IO QUEUE
804ms: PROCESS 7 DISPATCHED TO CPU
806ms: PROCESS 7 SENT TO IO QUEUE
806ms: PROCESS 3 DISPATCHED TO CPU
807ms: PROCESS 6 ADDED TO READY QUEUE
807ms: PROCESS 6 DONE WITH IO
809ms: PROCESS 3 SENT TO IO QUEUE
809ms: PROCESS 6 DISPATCHED TO CPU
812ms: PROCESS 7 ADDED TO READY QUEUE
812ms: PROCESS 7 DONE WITH IO
815ms: PROCESS 3 ADDED TO READY QUEUE
815ms: PROCESS 3 DONE WITH IO
816ms: PROCESS 6 PREMPTED
816ms: PROCESS 7 DISPATCHED TO CPU
816ms: PROCESS 6 ADDED TO READY QUEUE
819ms: PROCESS 7 PREMPTED
819ms: PROCESS 3 DISPATCHED TO CPU
819ms: PROCESS 7 ADDED TO READY QUEUE
820ms: PROCESS 3 SENT TO IO QUEUE
820ms: PROCESS 6 DISPATCHED TO CPU
824ms: PROCESS 6 PREMPTED
824ms: PROCESS 7 DISPATCHED TO CPU
824ms: PROCESS 6 ADDED TO READY QUEUE
827ms: PROCESS 7 PREMPTED
827ms: PROCESS 6 DISPATCHED TO CPU
827ms: PROCESS 7 ADDED TO READY QUEUE
830ms: PROCESS 6 PREMPTED
830ms: PROCESS 7 DISPATCHED TO CPU
830ms: PROCESS 6 ADDED TO READY QUEUE
833ms: PROCESS 7 PREMPTED
833ms: PROCESS 6 DISPATCHED TO CPU
833ms: PROCESS 7 ADDED TO READY QUEUE
834ms: PROCESS 3 ADDED TO READY QUEUE
834ms: PROCESS 3 DONE WITH IO
836ms: PROCESS 6 PREMPTED
836ms: PROCESS 7 DISPATCHED TO CPU
836ms: PROCESS 6 ADDED TO READY QUEUE
839ms: PROCESS 7 PREMPTED
839ms: PROCESS 3 DISPATCHED TO CPU
839ms: PROCESS 7 ADDED TO READY QUEUE
842ms: PROCESS 3 PREMPTED
842ms: PROCESS 6 DISPATCHED TO CPU
842ms: PROCESS 3 ADDED TO READY QUEUE
845ms: PROCESS 6 PREMPTED
845ms: PROCESS 7 DISPATCHED TO CPU
845ms: PROCESS 6 ADDED TO READY QUEUE
848ms: PROCESS 7 PREMPTED
848ms: PROCESS 3 DISPATCHED TO CPU
848ms: PROCESS 7 ADDED TO READY QUEUE
851ms: PROCESS 3 PREMPTED
851ms: PROCESS 6 DISPATCHED TO CPU
851ms: PROCESS 3 ADDED TO READY QUEUE
852ms: PROCESS 6 SENT TO IO QUEUE
852ms: PROCESS 7 DISPATCHED TO CPU
853ms: PROCESS 7 FINISHED, TURNAROUND: 0ms, CPU WAIT: 464ms, IO WAIT: 218ms
853ms: PROCESS 3 DISPATCHED TO CPU
856ms: PROCESS 3 FINISHED, TURNAROUND: 0ms, CPU WAIT: 435ms, IO WAIT: 288ms
868ms: PROCESS 6 ADDED TO READY QUEUE
868ms: PROCESS 6 DONE WITH IO
869ms: PROCESS 6 DISPATCHED TO CPU
887ms: PROCESS 6 SENT TO IO QUEUE
897ms: PROCESS 6 ADDED TO READY QUEUE
897ms: PROCESS 6 DONE WITH IO
898ms: PROCESS 6 DISPATCHED TO CPU
910ms: PROCESS 6 FINISHED, TURNAROUND: 0ms, CPU WAIT: 470ms, IO WAIT: 246ms
