0ms: PROCESS 22 ADDED TO READY QUEUE
0ms: PROCESS 23 ADDED TO READY QUEUE
0ms: PROCESS 45 ADDED TO READY QUEUE
0ms: PROCESS 107 ADDED TO READY QUEUE
0ms: PROCESS 109 ADDED TO READY QUEUE
0ms: PROCESS 113 ADDED TO READY QUEUE
0ms: PROCESS 119 ADDED TO READY QUEUE
0ms: PROCESS 138 ADDED TO READY QUEUE
0ms: PROCESS 143 ADDED TO READY QUEUE
0ms: PROCESS 168 ADDED TO READY QUEUE
0ms: PROCESS 219 ADDED TO READY QUEUE
0ms: PROCESS 225 ADDED TO READY QUEUE
0ms: PROCESS 241 ADDED TO READY QUEUE
0ms: PROCESS 322 ADDED TO READY QUEUE
0ms: PROCESS 343 ADDED TO READY QUEUE
0ms: PROCESS 350 ADDED TO READY QUEUE
0ms: PROCESS 362 ADDED TO READY QUEUE
0ms: PROCESS 369 ADDED TO READY QUEUE
0ms: PROCESS 377 ADDED TO READY QUEUE
0ms: PROCESS 452 ADDED TO READY QUEUE
0ms: PROCESS 592 ADDED TO READY QUEUE
0ms: PROCESS 618 ADDED TO READY QUEUE
0ms: PROCESS 657 ADDED TO READY QUEUE
0ms: PROCESS 663 ADDED TO READY QUEUE
0ms: PROCESS 669 ADDED TO READY QUEUE
0ms: PROCESS 685 ADDED TO READY QUEUE
0ms: PROCESS 698 ADDED TO READY QUEUE
0ms: PROCESS 715 ADDED TO READY QUEUE
0ms: PROCESS 728 ADDED TO READY QUEUE
0ms: PROCESS 733 ADDED TO READY QUEUE
0ms: PROCESS 740 ADDED TO READY QUEUE
0ms: PROCESS 754 ADDED TO READY QUEUE
0ms: PROCESS 771 ADDED TO READY QUEUE
0ms: PROCESS 785 ADDED TO READY QUEUE
0ms: PROCESS 820 ADDED TO READY QUEUE
0ms: PROCESS 822 ADDED TO READY QUEUE
0ms: PROCESS 827 ADDED TO READY QUEUE
0ms: PROCESS 840 ADDED TO READY QUEUE
0ms: PROCESS 853 ADDED TO READY QUEUE
0ms: PROCESS 926 ADDED TO READY QUEUE
0ms: PROCESS 960 ADDED TO READY QUEUE
0ms: PROCESS 22 DISPATCHED TO CPU
1ms: PROCESS 9 ADDED TO READY QUEUE
1ms: PROCESS 36 ADDED TO READY QUEUE
1ms: PROCESS 39 ADDED TO READY QUEUE
1ms: PROCESS 136 ADDED TO READY QUEUE
1ms: PROCESS 139 ADDED TO READY QUEUE
1ms: PROCESS 146 ADDED TO READY QUEUE
1ms: PROCESS 169 ADDED TO READY QUEUE
1ms: PROCESS 174 ADDED TO READY QUEUE
1ms: PROCESS 239 ADDED TO READY QUEUE
1ms: PROCESS 254 ADDED TO READY QUEUE
1ms: PROCESS 274 ADDED TO READY QUEUE
1ms: PROCESS 298 ADDED TO READY QUEUE
1ms: PROCESS 305 ADDED TO READY QUEUE
1ms: PROCESS 316 ADDED TO READY QUEUE
1ms: PROCESS 331 ADDED TO READY QUEUE
1ms: PROCESS 384 ADDED TO READY QUEUE
1ms: PROCESS 469 ADDED TO READY QUEUE
1ms: PROCESS 548 ADDED TO READY QUEUE
1ms: PROCESS 576 ADDED TO READY QUEUE
1ms: PROCESS 622 ADDED TO READY QUEUE
1ms: PROCESS 623 ADDED TO READY QUEUE
1ms: PROCESS 635 ADDED TO READY QUEUE
1ms: PROCESS 667 ADDED TO READY QUEUE
1ms: PROCESS 697 ADDED TO READY QUEUE
1ms: PROCESS 703 ADDED TO READY QUEUE
1ms: PROCESS 716 ADDED TO READY QUEUE
1ms: PROCESS 719 ADDED TO READY QUEUE
1ms: PROCESS 737 ADDED TO READY QUEUE
1ms: PROCESS 756 ADDED TO READY QUEUE
1ms: PROCESS 758 ADDED TO READY QUEUE
1ms: PROCESS 766 ADDED TO READY QUEUE
1ms: PROCESS 780 ADDED TO READY QUEUE
1ms: PROCESS 786 ADDED TO READY QUEUE
1ms: PROCESS 813 ADDED TO READY QUEUE
1ms: PROCESS 816 ADDED TO READY QUEUE
1ms: PROCESS 881 ADDED TO READY QUEUE
1ms: PROCESS 902 ADDED TO READY QUEUE
1ms: PROCESS 905 ADDED TO READY QUEUE
1ms: PROCESS 908 ADDED TO READY QUEUE
1ms: PROCESS 915 ADDED TO READY QUEUE
1ms: PROCESS 919 ADDED TO READY QUEUE
1ms: PROCESS 959 ADDED TO READY QUEUE
2ms: PROCESS 55 ADDED TO READY QUEUE
2ms: PROCESS 110 ADDED TO READY QUEUE
2ms: PROCESS 137 ADDED TO READY QUEUE
2ms: PROCESS 140 ADDED TO READY QUEUE
2ms: PROCESS 171 ADDED TO READY QUEUE
2ms: PROCESS 194 ADDED TO READY QUEUE
2ms: PROCESS 215 ADDED TO READY QUEUE
2ms: PROCESS 289 ADDED TO READY QUEUE
2ms: PROCESS 328 ADDED TO READY QUEUE
2ms: PROCESS 338 ADDED TO READY QUEUE
2ms: PROCESS 359 ADDED TO READY QUEUE
2ms: PROCESS 360 ADDED TO READY QUEUE
2ms: PROCESS 415 ADDED TO READY QUEUE
2ms: PROCESS 436 ADDED TO READY QUEUE
2ms: PROCESS 437 ADDED TO READY QUEUE
2ms: PROCESS 440 ADDED TO READY QUEUE
2ms: PROCESS 455 ADDED TO READY QUEUE
2ms: PROCESS 468 ADDED TO READY QUEUE
2ms: PROCESS 499 ADDED TO READY QUEUE
2ms: PROCESS 505 ADDED TO READY QUEUE
2ms: PROCESS 507 ADDED TO READY QUEUE
2ms: PROCESS 530 ADDED TO READY QUEUE
2ms: PROCESS 531 ADDED TO READY QUEUE
2ms: PROCESS 562 ADDED TO READY QUEUE
2ms: PROCESS 591 ADDED TO READY QUEUE
2ms: PROCESS 601 ADDED TO READY QUEUE
2ms: PROCESS 653 ADDED TO READY QUEUE
2ms: PROCESS 673 ADDED TO READY QUEUE
2ms: PROCESS 707 ADDED TO READY QUEUE
2ms: PROCESS 712 ADDED TO READY QUEUE
2ms: PROCESS 739 ADDED TO READY QUEUE
2ms: PROCESS 790 ADDED TO READY QUEUE
2ms: PROCESS 829 ADDED TO READY QUEUE
2ms: PROCESS 832 ADDED TO READY QUEUE
2ms: PROCESS 838 ADDED TO READY QUEUE
2ms: PROCESS 849 ADDED TO READY QUEUE
2ms: PROCESS 861 ADDED TO READY QUEUE
2ms: PROCESS 892 ADDED TO READY QUEUE
2ms: PROCESS 895 ADDED TO READY QUEUE
2ms: PROCESS 998 ADDED TO READY QUEUE
3ms: PROCESS 4 ADDED TO READY QUEUE
3ms: PROCESS 21 ADDED TO READY QUEUE
3ms: PROCESS 38 ADDED TO READY QUEUE
3ms: PROCESS 46 ADDED TO READY QUEUE
3ms: PROCESS 57 ADDED TO READY QUEUE
3ms: PROCESS 62 ADDED TO READY QUEUE
3ms: PROCESS 63 ADDED TO READY QUEUE
3ms: PROCESS 75 ADDED TO READY QUEUE
3ms: PROCESS 121 ADDED TO READY QUEUE
3ms: PROCESS 128 ADDED TO READY QUEUE
3ms: PROCESS 157 ADDED TO READY QUEUE
3ms: PROCESS 218 ADDED TO READY QUEUE
3ms: PROCESS 228 ADDED TO READY QUEUE
3ms: PROCESS 304 ADDED TO READY QUEUE
3ms: PROCESS 333 ADDED TO READY QUEUE
3ms: PROCESS 357 ADDED TO READY QUEUE
3ms: PROCESS 408 ADDED TO READY QUEUE
3ms: PROCESS 410 ADDED TO READY QUEUE
3ms: PROCESS 495 ADDED TO READY QUEUE
3ms: PROCESS 517 ADDED TO READY QUEUE
3ms: PROCESS 529 ADDED TO READY QUEUE
3ms: PROCESS 533 ADDED TO READY QUEUE
3ms: PROCESS 545 ADDED TO READY QUEUE
3ms: PROCESS 581 ADDED TO READY QUEUE
3ms: PROCESS 606 ADDED TO READY QUEUE
3ms: PROCESS 630 ADDED TO READY QUEUE
3ms: PROCESS 652 ADDED TO READY QUEUE
3ms: PROCESS 654 ADDED TO READY QUEUE
3ms: PROCESS 680 ADDED TO READY QUEUE
3ms: PROCESS 750 ADDED TO READY QUEUE
3ms: PROCESS 788 ADDED TO READY QUEUE
3ms: PROCESS 844 ADDED TO READY QUEUE
3ms: PROCESS 951 ADDED TO READY QUEUE
3ms: PROCESS 961 ADDED TO READY QUEUE
3ms: PROCESS 965 ADDED TO READY QUEUE
4ms: PROCESS 5 ADDED TO READY QUEUE
4ms: PROCESS 6 ADDED TO READY QUEUE
4ms: PROCESS 7 ADDED TO READY QUEUE
4ms: PROCESS 14 ADDED TO READY QUEUE
4ms: PROCESS 98 ADDED TO READY QUEUE
4ms: PROCESS 100 ADDED TO READY QUEUE
4ms: PROCESS 123 ADDED TO READY QUEUE
4ms: PROCESS 148 ADDED TO READY QUEUE
4ms: PROCESS 229 ADDED TO READY QUEUE
4ms: PROCESS 245 ADDED TO READY QUEUE
4ms: PROCESS 312 ADDED TO READY QUEUE
4ms: PROCESS 348 ADDED TO READY QUEUE
4ms: PROCESS 381 ADDED TO READY QUEUE
4ms: PROCESS 411 ADDED TO READY QUEUE
4ms: PROCESS 439 ADDED TO READY QUEUE
4ms: PROCESS 458 ADDED TO READY QUEUE
4ms: PROCESS 473 ADDED TO READY QUEUE
4ms: PROCESS 478 ADDED TO READY QUEUE
4ms: PROCESS 492 ADDED TO READY QUEUE
4ms: PROCESS 500 ADDED TO READY QUEUE
4ms: PROCESS 528 ADDED TO READY QUEUE
4ms: PROCESS 549 ADDED TO READY QUEUE
4ms: PROCESS 603 ADDED TO READY QUEUE
4ms: PROCESS 672 ADDED TO READY QUEUE
4ms: PROCESS 676 ADDED TO READY QUEUE
4ms: PROCESS 683 ADDED TO READY QUEUE
4ms: PROCESS 691 ADDED TO READY QUEUE
4ms: PROCESS 747 ADDED TO READY QUEUE
4ms: PROCESS 757 ADDED TO READY QUEUE
4ms: PROCESS 850 ADDED TO READY QUEUE
4ms: PROCESS 856 ADDED TO READY QUEUE
4ms: PROCESS 888 ADDED TO READY QUEUE
4ms: PROCESS 898 ADDED TO READY QUEUE
4ms: PROCESS 917 ADDED TO READY QUEUE
4ms: PROCESS 923 ADDED TO READY QUEUE
4ms: PROCESS 933 ADDED TO READY QUEUE
4ms: PROCESS 940 ADDED TO READY QUEUE
4ms: PROCESS 943 ADDED TO READY QUEUE
4ms: PROCESS 992 ADDED TO READY QUEUE
5ms: PROCESS 10 ADDED TO READY QUEUE
5ms: PROCESS 13 ADDED TO READY QUEUE
5ms: PROCESS 59 ADDED TO READY QUEUE
5ms: PROCESS 67 ADDED TO READY QUEUE
5ms: PROCESS 105 ADDED TO READY QUEUE
5ms: PROCESS 163 ADDED TO READY QUEUE
5ms: PROCESS 227 ADDED TO READY QUEUE
5ms: PROCESS 234 ADDED TO READY QUEUE
5ms: PROCESS 247 ADDED TO READY QUEUE
5ms: PROCESS 253 ADDED TO READY QUEUE
5ms: PROCESS 313 ADDED TO READY QUEUE
5ms: PROCESS 336 ADDED TO READY QUEUE
5ms: PROCESS 351 ADDED TO READY QUEUE
5ms: PROCESS 442 ADDED TO READY QUEUE
5ms: PROCESS 456 ADDED TO READY QUEUE
5ms: PROCESS 474 ADDED TO READY QUEUE
5ms: PROCESS 513 ADDED TO READY QUEUE
5ms: PROCESS 514 ADDED TO READY QUEUE
5ms: PROCESS 516 ADDED TO READY QUEUE
5ms: PROCESS 559 ADDED TO READY QUEUE
5ms: PROCESS 564 ADDED TO READY QUEUE
5ms: PROCESS 574 ADDED TO READY QUEUE
5ms: PROCESS 646 ADDED TO READY QUEUE
5ms: PROCESS 781 ADDED TO READY QUEUE
5ms: PROCESS 796 ADDED TO READY QUEUE
5ms: PROCESS 803 ADDED TO READY QUEUE
5ms: PROCESS 839 ADDED TO READY QUEUE
5ms: PROCESS 903 ADDED TO READY QUEUE
5ms: PROCESS 952 ADDED TO READY QUEUE
5ms: PROCESS 987 ADDED TO READY QUEUE
6ms: PROCESS 11 ADDED TO READY QUEUE
6ms: PROCESS 12 ADDED TO READY QUEUE
6ms: PROCESS 50 ADDED TO READY QUEUE
6ms: PROCESS 52 ADDED TO READY QUEUE
6ms: PROCESS 64 ADDED TO READY QUEUE
6ms: PROCESS 88 ADDED TO READY QUEUE
6ms: PROCESS 115 ADDED TO READY QUEUE
6ms: PROCESS 199 ADDED TO READY QUEUE
6ms: PROCESS 200 ADDED TO READY QUEUE
6ms: PROCESS 205 ADDED TO READY QUEUE
6ms: PROCESS 251 ADDED TO READY QUEUE
6ms: PROCESS 275 ADDED TO READY QUEUE
6ms: PROCESS 282 ADDED TO READY QUEUE
6ms: PROCESS 286 ADDED TO READY QUEUE
6ms: PROCESS 385 ADDED TO READY QUEUE
6ms: PROCESS 429 ADDED TO READY QUEUE
6ms: PROCESS 508 ADDED TO READY QUEUE
6ms: PROCESS 535 ADDED TO READY QUEUE
6ms: PROCESS 538 ADDED TO READY QUEUE
6ms: PROCESS 567 ADDED TO READY QUEUE
6ms: PROCESS 679 ADDED TO READY QUEUE
6ms: PROCESS 700 ADDED TO READY QUEUE
6ms: PROCESS 738 ADDED TO READY QUEUE
6ms: PROCESS 759 ADDED TO READY QUEUE
6ms: PROCESS 797 ADDED TO READY QUEUE
6ms: PROCESS 854 ADDED TO READY QUEUE
6ms: PROCESS 858 ADDED TO READY QUEUE
6ms: PROCESS 866 ADDED TO READY QUEUE
6ms: PROCESS 886 ADDED TO READY QUEUE
6ms: PROCESS 894 ADDED TO READY QUEUE
6ms: PROCESS 953 ADDED TO READY QUEUE
6ms: PROCESS 978 ADDED TO READY QUEUE
7ms: PROCESS 42 ADDED TO READY QUEUE
7ms: PROCESS 60 ADDED TO READY QUEUE
7ms: PROCESS 125 ADDED TO READY QUEUE
7ms: PROCESS 131 ADDED TO READY QUEUE
7ms: PROCESS 132 ADDED TO READY QUEUE
7ms: PROCESS 141 ADDED TO READY QUEUE
7ms: PROCESS 167 ADDED TO READY QUEUE
7ms: PROCESS 244 ADDED TO READY QUEUE
7ms: PROCESS 271 ADDED TO READY QUEUE
7ms: PROCESS 319 ADDED TO READY QUEUE
7ms: PROCESS 323 ADDED TO READY QUEUE
7ms: PROCESS 358 ADDED TO READY QUEUE
7ms: PROCESS 373 ADDED TO READY QUEUE
7ms: PROCESS 391 ADDED TO READY QUEUE
7ms: PROCESS 393 ADDED TO READY QUEUE
7ms: PROCESS 397 ADDED TO READY QUEUE
7ms: PROCESS 462 ADDED TO READY QUEUE
7ms: PROCESS 521 ADDED TO READY QUEUE
7ms: PROCESS 542 ADDED TO READY QUEUE
7ms: PROCESS 617 ADDED TO READY QUEUE
7ms: PROCESS 664 ADDED TO READY QUEUE
7ms: PROCESS 677 ADDED TO READY QUEUE
7ms: PROCESS 692 ADDED TO READY QUEUE
7ms: PROCESS 787 ADDED TO READY QUEUE
7ms: PROCESS 818 ADDED TO READY QUEUE
7ms: PROCESS 916 ADDED TO READY QUEUE
7ms: PROCESS 931 ADDED TO READY QUEUE
7ms: PROCESS 937 ADDED TO READY QUEUE
7ms: PROCESS 939 ADDED TO READY QUEUE
7ms: PROCESS 980 ADDED TO READY QUEUE
8ms: PROCESS 53 ADDED TO READY QUEUE
8ms: PROCESS 103 ADDED TO READY QUEUE
8ms: PROCESS 122 ADDED TO READY QUEUE
8ms: PROCESS 126 ADDED TO READY QUEUE
8ms: PROCESS 164 ADDED TO READY QUEUE
8ms: PROCESS 175 ADDED TO READY QUEUE
8ms: PROCESS 181 ADDED TO READY QUEUE
8ms: PROCESS 196 ADDED TO READY QUEUE
8ms: PROCESS 207 ADDED TO READY QUEUE
8ms: PROCESS 268 ADDED TO READY QUEUE
8ms: PROCESS 273 ADDED TO READY QUEUE
8ms: PROCESS 284 ADDED TO READY QUEUE
8ms: PROCESS 416 ADDED TO READY QUEUE
8ms: PROCESS 421 ADDED TO READY QUEUE
8ms: PROCESS 453 ADDED TO READY QUEUE
8ms: PROCESS 487 ADDED TO READY QUEUE
8ms: PROCESS 512 ADDED TO READY QUEUE
8ms: PROCESS 568 ADDED TO READY QUEUE
8ms: PROCESS 621 ADDED TO READY QUEUE
8ms: PROCESS 632 ADDED TO READY QUEUE
8ms: PROCESS 734 ADDED TO READY QUEUE
8ms: PROCESS 735 ADDED TO READY QUEUE
8ms: PROCESS 744 ADDED TO READY QUEUE
8ms: PROCESS 798 ADDED TO READY QUEUE
8ms: PROCESS 904 ADDED TO READY QUEUE
8ms: PROCESS 972 ADDED TO READY QUEUE
8ms: PROCESS 991 ADDED TO READY QUEUE
8ms: PROCESS 997 ADDED TO READY QUEUE
9ms: PROCESS 28 ADDED TO READY QUEUE
9ms: PROCESS 41 ADDED TO READY QUEUE
9ms: PROCESS 76 ADDED TO READY QUEUE
9ms: PROCESS 77 ADDED TO READY QUEUE
9ms: PROCESS 90 ADDED TO READY QUEUE
9ms: PROCESS 92 ADDED TO READY QUEUE
9ms: PROCESS 93 ADDED TO READY QUEUE
9ms: PROCESS 178 ADDED TO READY QUEUE
9ms: PROCESS 180 ADDED TO READY QUEUE
9ms: PROCESS 185 ADDED TO READY QUEUE
9ms: PROCESS 246 ADDED TO READY QUEUE
9ms: PROCESS 255 ADDED TO READY QUEUE
9ms: PROCESS 257 ADDED TO READY QUEUE
9ms: PROCESS 269 ADDED TO READY QUEUE
9ms: PROCESS 290 ADDED TO READY QUEUE
9ms: PROCESS 311 ADDED TO READY QUEUE
9ms: PROCESS 370 ADDED TO READY QUEUE
9ms: PROCESS 400 ADDED TO READY QUEUE
9ms: PROCESS 401 ADDED TO READY QUEUE
9ms: PROCESS 403 ADDED TO READY QUEUE
9ms: PROCESS 444 ADDED TO READY QUEUE
9ms: PROCESS 464 ADDED TO READY QUEUE
9ms: PROCESS 481 ADDED TO READY QUEUE
9ms: PROCESS 483 ADDED TO READY QUEUE
9ms: PROCESS 524 ADDED TO READY QUEUE
9ms: PROCESS 550 ADDED TO READY QUEUE
9ms: PROCESS 552 ADDED TO READY QUEUE
9ms: PROCESS 573 ADDED TO READY QUEUE
9ms: PROCESS 586 ADDED TO READY QUEUE
9ms: PROCESS 588 ADDED TO READY QUEUE
9ms: PROCESS 604 ADDED TO READY QUEUE
9ms: PROCESS 607 ADDED TO READY QUEUE
9ms: PROCESS 633 ADDED TO READY QUEUE
9ms: PROCESS 682 ADDED TO READY QUEUE
9ms: PROCESS 768 ADDED TO READY QUEUE
9ms: PROCESS 795 ADDED TO READY QUEUE
9ms: PROCESS 802 ADDED TO READY QUEUE
9ms: PROCESS 855 ADDED TO READY QUEUE
9ms: PROCESS 865 ADDED TO READY QUEUE
9ms: PROCESS 887 ADDED TO READY QUEUE
9ms: PROCESS 948 ADDED TO READY QUEUE
9ms: PROCESS 950 ADDED TO READY QUEUE
9ms: PROCESS 973 ADDED TO READY QUEUE
10ms: PROCESS 2 ADDED TO READY QUEUE
10ms: PROCESS 83 ADDED TO READY QUEUE
10ms: PROCESS 102 ADDED TO READY QUEUE
10ms: PROCESS 112 ADDED TO READY QUEUE
10ms: PROCESS 153 ADDED TO READY QUEUE
10ms: PROCESS 188 ADDED TO READY QUEUE
10ms: PROCESS 195 ADDED TO READY QUEUE
10ms: PROCESS 202 ADDED TO READY QUEUE
10ms: PROCESS 210 ADDED TO READY QUEUE
10ms: PROCESS 222 ADDED TO READY QUEUE
10ms: PROCESS 264 ADDED TO READY QUEUE
10ms: PROCESS 280 ADDED TO READY QUEUE
10ms: PROCESS 292 ADDED TO READY QUEUE
10ms: PROCESS 314 ADDED TO READY QUEUE
10ms: PROCESS 380 ADDED TO READY QUEUE
10ms: PROCESS 409 ADDED TO READY QUEUE
10ms: PROCESS 412 ADDED TO READY QUEUE
10ms: PROCESS 418 ADDED TO READY QUEUE
10ms: PROCESS 426 ADDED TO READY QUEUE
10ms: PROCESS 467 ADDED TO READY QUEUE
10ms: PROCESS 480 ADDED TO READY QUEUE
10ms: PROCESS 482 ADDED TO READY QUEUE
10ms: PROCESS 484 ADDED TO READY QUEUE
10ms: PROCESS 511 ADDED TO READY QUEUE
10ms: PROCESS 519 ADDED TO READY QUEUE
10ms: PROCESS 543 ADDED TO READY QUEUE
10ms: PROCESS 554 ADDED TO READY QUEUE
10ms: PROCESS 579 ADDED TO READY QUEUE
10ms: PROCESS 637 ADDED TO READY QUEUE
10ms: PROCESS 662 ADDED TO READY QUEUE
10ms: PROCESS 675 ADDED TO READY QUEUE
10ms: PROCESS 695 ADDED TO READY QUEUE
10ms: PROCESS 699 ADDED TO READY QUEUE
10ms: PROCESS 722 ADDED TO READY QUEUE
10ms: PROCESS 736 ADDED TO READY QUEUE
10ms: PROCESS 762 ADDED TO READY QUEUE
10ms: PROCESS 842 ADDED TO READY QUEUE
10ms: PROCESS 871 ADDED TO READY QUEUE
10ms: PROCESS 885 ADDED TO READY QUEUE
10ms: PROCESS 914 ADDED TO READY QUEUE
10ms: PROCESS 968 ADDED TO READY QUEUE
10ms: PROCESS 985 ADDED TO READY QUEUE
10ms: PROCESS 989 ADDED TO READY QUEUE
11ms: PROCESS 31 ADDED TO READY QUEUE
11ms: PROCESS 54 ADDED TO READY QUEUE
11ms: PROCESS 79 ADDED TO READY QUEUE
11ms: PROCESS 124 ADDED TO READY QUEUE
11ms: PROCESS 129 ADDED TO READY QUEUE
11ms: PROCESS 159 ADDED TO READY QUEUE
11ms: PROCESS 176 ADDED TO READY QUEUE
11ms: PROCESS 187 ADDED TO READY QUEUE
11ms: PROCESS 213 ADDED TO READY QUEUE
11ms: PROCESS 217 ADDED TO READY QUEUE
11ms: PROCESS 238 ADDED TO READY QUEUE
11ms: PROCESS 277 ADDED TO READY QUEUE
11ms: PROCESS 320 ADDED TO READY QUEUE
11ms: PROCESS 339 ADDED TO READY QUEUE
11ms: PROCESS 341 ADDED TO READY QUEUE
11ms: PROCESS 471 ADDED TO READY QUEUE
11ms: PROCESS 536 ADDED TO READY QUEUE
11ms: PROCESS 544 ADDED TO READY QUEUE
11ms: PROCESS 578 ADDED TO READY QUEUE
11ms: PROCESS 584 ADDED TO READY QUEUE
11ms: PROCESS 587 ADDED TO READY QUEUE
11ms: PROCESS 627 ADDED TO READY QUEUE
11ms: PROCESS 642 ADDED TO READY QUEUE
11ms: PROCESS 701 ADDED TO READY QUEUE
11ms: PROCESS 732 ADDED TO READY QUEUE
11ms: PROCESS 745 ADDED TO READY QUEUE
11ms: PROCESS 765 ADDED TO READY QUEUE
11ms: PROCESS 792 ADDED TO READY QUEUE
11ms: PROCESS 836 ADDED TO READY QUEUE
11ms: PROCESS 841 ADDED TO READY QUEUE
11ms: PROCESS 867 ADDED TO READY QUEUE
11ms: PROCESS 909 ADDED TO READY QUEUE
11ms: PROCESS 954 ADDED TO READY QUEUE
11ms: PROCESS 971 ADDED TO READY QUEUE
12ms: PROCESS 51 ADDED TO READY QUEUE
12ms: PROCESS 56 ADDED TO READY QUEUE
12ms: PROCESS 68 ADDED TO READY QUEUE
12ms: PROCESS 73 ADDED TO READY QUEUE
12ms: PROCESS 87 ADDED TO READY QUEUE
12ms: PROCESS 117 ADDED TO READY QUEUE
12ms: PROCESS 162 ADDED TO READY QUEUE
12ms: PROCESS 165 ADDED TO READY QUEUE
12ms: PROCESS 232 ADDED TO READY QUEUE
12ms: PROCESS 276 ADDED TO READY QUEUE
12ms: PROCESS 279 ADDED TO READY QUEUE
12ms: PROCESS 302 ADDED TO READY QUEUE
12ms: PROCESS 398 ADDED TO READY QUEUE
12ms: PROCESS 451 ADDED TO READY QUEUE
12ms: PROCESS 454 ADDED TO READY QUEUE
12ms: PROCESS 485 ADDED TO READY QUEUE
12ms: PROCESS 503 ADDED TO READY QUEUE
12ms: PROCESS 563 ADDED TO READY QUEUE
12ms: PROCESS 571 ADDED TO READY QUEUE
12ms: PROCESS 593 ADDED TO READY QUEUE
12ms: PROCESS 629 ADDED TO READY QUEUE
12ms: PROCESS 643 ADDED TO READY QUEUE
12ms: PROCESS 655 ADDED TO READY QUEUE
12ms: PROCESS 656 ADDED TO READY QUEUE
12ms: PROCESS 659 ADDED TO READY QUEUE
12ms: PROCESS 670 ADDED TO READY QUEUE
12ms: PROCESS 686 ADDED TO READY QUEUE
12ms: PROCESS 730 ADDED TO READY QUEUE
12ms: PROCESS 749 ADDED TO READY QUEUE
12ms: PROCESS 760 ADDED TO READY QUEUE
12ms: PROCESS 791 ADDED TO READY QUEUE
12ms: PROCESS 809 ADDED TO READY QUEUE
12ms: PROCESS 864 ADDED TO READY QUEUE
12ms: PROCESS 872 ADDED TO READY QUEUE
12ms: PROCESS 874 ADDED TO READY QUEUE
12ms: PROCESS 910 ADDED TO READY QUEUE
12ms: PROCESS 944 ADDED TO READY QUEUE
12ms: PROCESS 947 ADDED TO READY QUEUE
12ms: PROCESS 956 ADDED TO READY QUEUE
13ms: PROCESS 26 ADDED TO READY QUEUE
13ms: PROCESS 43 ADDED TO READY QUEUE
13ms: PROCESS 86 ADDED TO READY QUEUE
13ms: PROCESS 192 ADDED TO READY QUEUE
13ms: PROCESS 198 ADDED TO READY QUEUE
13ms: PROCESS 214 ADDED TO READY QUEUE
13ms: PROCESS 321 ADDED TO READY QUEUE
13ms: PROCESS 389 ADDED TO READY QUEUE
13ms: PROCESS 424 ADDED TO READY QUEUE
13ms: PROCESS 434 ADDED TO READY QUEUE
13ms: PROCESS 457 ADDED TO READY QUEUE
13ms: PROCESS 475 ADDED TO READY QUEUE
13ms: PROCESS 523 ADDED TO READY QUEUE
13ms: PROCESS 611 ADDED TO READY QUEUE
13ms: PROCESS 666 ADDED TO READY QUEUE
13ms: PROCESS 668 ADDED TO READY QUEUE
13ms: PROCESS 694 ADDED TO READY QUEUE
13ms: PROCESS 770 ADDED TO READY QUEUE
13ms: PROCESS 807 ADDED TO READY QUEUE
13ms: PROCESS 811 ADDED TO READY QUEUE
13ms: PROCESS 859 ADDED TO READY QUEUE
13ms: PROCESS 862 ADDED TO READY QUEUE
13ms: PROCESS 891 ADDED TO READY QUEUE
13ms: PROCESS 897 ADDED TO READY QUEUE
13ms: PROCESS 927 ADDED TO READY QUEUE
13ms: PROCESS 966 ADDED TO READY QUEUE
14ms: PROCESS 0 ADDED TO READY QUEUE
14ms: PROCESS 1 ADDED TO READY QUEUE
14ms: PROCESS 8 ADDED TO READY QUEUE
14ms: PROCESS 15 ADDED TO READY QUEUE
14ms: PROCESS 40 ADDED TO READY QUEUE
14ms: PROCESS 101 ADDED TO READY QUEUE
14ms: PROCESS 150 ADDED TO READY QUEUE
14ms: PROCESS 166 ADDED TO READY QUEUE
14ms: PROCESS 265 ADDED TO READY QUEUE
14ms: PROCESS 299 ADDED TO READY QUEUE
14ms: PROCESS 300 ADDED TO READY QUEUE
14ms: PROCESS 301 ADDED TO READY QUEUE
14ms: PROCESS 317 ADDED TO READY QUEUE
14ms: PROCESS 329 ADDED TO READY QUEUE
14ms: PROCESS 371 ADDED TO READY QUEUE
14ms: PROCESS 383 ADDED TO READY QUEUE
14ms: PROCESS 435 ADDED TO READY QUEUE
14ms: PROCESS 443 ADDED TO READY QUEUE
14ms: PROCESS 446 ADDED TO READY QUEUE
14ms: PROCESS 450 ADDED TO READY QUEUE
14ms: PROCESS 477 ADDED TO READY QUEUE
14ms: PROCESS 501 ADDED TO READY QUEUE
14ms: PROCESS 537 ADDED TO READY QUEUE
14ms: PROCESS 546 ADDED TO READY QUEUE
14ms: PROCESS 590 ADDED TO READY QUEUE
14ms: PROCESS 600 ADDED TO READY QUEUE
14ms: PROCESS 651 ADDED TO READY QUEUE
14ms: PROCESS 702 ADDED TO READY QUEUE
14ms: PROCESS 753 ADDED TO READY QUEUE
14ms: PROCESS 761 ADDED TO READY QUEUE
14ms: PROCESS 767 ADDED TO READY QUEUE
14ms: PROCESS 769 ADDED TO READY QUEUE
14ms: PROCESS 825 ADDED TO READY QUEUE
14ms: PROCESS 876 ADDED TO READY QUEUE
14ms: PROCESS 938 ADDED TO READY QUEUE
14ms: PROCESS 958 ADDED TO READY QUEUE
14ms: PROCESS 993 ADDED TO READY QUEUE
15ms: PROCESS 49 ADDED TO READY QUEUE
15ms: PROCESS 61 ADDED TO READY QUEUE
15ms: PROCESS 71 ADDED TO READY QUEUE
15ms: PROCESS 81 ADDED TO READY QUEUE
15ms: PROCESS 108 ADDED TO READY QUEUE
15ms: PROCESS 145 ADDED TO READY QUEUE
15ms: PROCESS 193 ADDED TO READY QUEUE
15ms: PROCESS 223 ADDED TO READY QUEUE
15ms: PROCESS 307 ADDED TO READY QUEUE
15ms: PROCESS 315 ADDED TO READY QUEUE
15ms: PROCESS 324 ADDED TO READY QUEUE
15ms: PROCESS 326 ADDED TO READY QUEUE
15ms: PROCESS 365 ADDED TO READY QUEUE
15ms: PROCESS 379 ADDED TO READY QUEUE
15ms: PROCESS 390 ADDED TO READY QUEUE
15ms: PROCESS 395 ADDED TO READY QUEUE
15ms: PROCESS 406 ADDED TO READY QUEUE
15ms: PROCESS 413 ADDED TO READY QUEUE
15ms: PROCESS 463 ADDED TO READY QUEUE
15ms: PROCESS 465 ADDED TO READY QUEUE
15ms: PROCESS 489 ADDED TO READY QUEUE
15ms: PROCESS 619 ADDED TO READY QUEUE
15ms: PROCESS 626 ADDED TO READY QUEUE
15ms: PROCESS 641 ADDED TO READY QUEUE
15ms: PROCESS 709 ADDED TO READY QUEUE
15ms: PROCESS 721 ADDED TO READY QUEUE
15ms: PROCESS 755 ADDED TO READY QUEUE
15ms: PROCESS 776 ADDED TO READY QUEUE
15ms: PROCESS 777 ADDED TO READY QUEUE
15ms: PROCESS 810 ADDED TO READY QUEUE
15ms: PROCESS 837 ADDED TO READY QUEUE
15ms: PROCESS 893 ADDED TO READY QUEUE
15ms: PROCESS 900 ADDED TO READY QUEUE
15ms: PROCESS 949 ADDED TO READY QUEUE
15ms: PROCESS 974 ADDED TO READY QUEUE
15ms: PROCESS 981 ADDED TO READY QUEUE
16ms: PROCESS 37 ADDED TO READY QUEUE
16ms: PROCESS 70 ADDED TO READY QUEUE
16ms: PROCESS 84 ADDED TO READY QUEUE
16ms: PROCESS 85 ADDED TO READY QUEUE
16ms: PROCESS 118 ADDED TO READY QUEUE
16ms: PROCESS 135 ADDED TO READY QUEUE
16ms: PROCESS 151 ADDED TO READY QUEUE
16ms: PROCESS 211 ADDED TO READY QUEUE
16ms: PROCESS 216 ADDED TO READY QUEUE
16ms: PROCESS 220 ADDED TO READY QUEUE
16ms: PROCESS 235 ADDED TO READY QUEUE
16ms: PROCESS 306 ADDED TO READY QUEUE
16ms: PROCESS 318 ADDED TO READY QUEUE
16ms: PROCESS 407 ADDED TO READY QUEUE
16ms: PROCESS 422 ADDED TO READY QUEUE
16ms: PROCESS 430 ADDED TO READY QUEUE
16ms: PROCESS 460 ADDED TO READY QUEUE
16ms: PROCESS 526 ADDED TO READY QUEUE
16ms: PROCESS 577 ADDED TO READY QUEUE
16ms: PROCESS 613 ADDED TO READY QUEUE
16ms: PROCESS 616 ADDED TO READY QUEUE
16ms: PROCESS 649 ADDED TO READY QUEUE
16ms: PROCESS 671 ADDED TO READY QUEUE
16ms: PROCESS 684 ADDED TO READY QUEUE
16ms: PROCESS 693 ADDED TO READY QUEUE
16ms: PROCESS 713 ADDED TO READY QUEUE
16ms: PROCESS 717 ADDED TO READY QUEUE
16ms: PROCESS 731 ADDED TO READY QUEUE
16ms: PROCESS 779 ADDED TO READY QUEUE
16ms: PROCESS 782 ADDED TO READY QUEUE
16ms: PROCESS 808 ADDED TO READY QUEUE
16ms: PROCESS 812 ADDED TO READY QUEUE
16ms: PROCESS 823 ADDED TO READY QUEUE
16ms: PROCESS 834 ADDED TO READY QUEUE
16ms: PROCESS 845 ADDED TO READY QUEUE
16ms: PROCESS 860 ADDED TO READY QUEUE
16ms: PROCESS 863 ADDED TO READY QUEUE
16ms: PROCESS 884 ADDED TO READY QUEUE
16ms: PROCESS 913 ADDED TO READY QUEUE
16ms: PROCESS 930 ADDED TO READY QUEUE
16ms: PROCESS 945 ADDED TO READY QUEUE
16ms: PROCESS 967 ADDED TO READY QUEUE
17ms: PROCESS 25 ADDED TO READY QUEUE
17ms: PROCESS 34 ADDED TO READY QUEUE
17ms: PROCESS 44 ADDED TO READY QUEUE
17ms: PROCESS 78 ADDED TO READY QUEUE
17ms: PROCESS 173 ADDED TO READY QUEUE
17ms: PROCESS 249 ADDED TO READY QUEUE
17ms: PROCESS 252 ADDED TO READY QUEUE
17ms: PROCESS 267 ADDED TO READY QUEUE
17ms: PROCESS 285 ADDED TO READY QUEUE
17ms: PROCESS 309 ADDED TO READY QUEUE
17ms: PROCESS 332 ADDED TO READY QUEUE
17ms: PROCESS 375 ADDED TO READY QUEUE
17ms: PROCESS 427 ADDED TO READY QUEUE
17ms: PROCESS 479 ADDED TO READY QUEUE
17ms: PROCESS 494 ADDED TO READY QUEUE
17ms: PROCESS 498 ADDED TO READY QUEUE
17ms: PROCESS 534 ADDED TO READY QUEUE
17ms: PROCESS 547 ADDED TO READY QUEUE
17ms: PROCESS 602 ADDED TO READY QUEUE
17ms: PROCESS 612 ADDED TO READY QUEUE
17ms: PROCESS 650 ADDED TO READY QUEUE
17ms: PROCESS 658 ADDED TO READY QUEUE
17ms: PROCESS 674 ADDED TO READY QUEUE
17ms: PROCESS 696 ADDED TO READY QUEUE
17ms: PROCESS 741 ADDED TO READY QUEUE
17ms: PROCESS 751 ADDED TO READY QUEUE
17ms: PROCESS 752 ADDED TO READY QUEUE
17ms: PROCESS 764 ADDED TO READY QUEUE
17ms: PROCESS 774 ADDED TO READY QUEUE
17ms: PROCESS 778 ADDED TO READY QUEUE
17ms: PROCESS 783 ADDED TO READY QUEUE
17ms: PROCESS 815 ADDED TO READY QUEUE
17ms: PROCESS 819 ADDED TO READY QUEUE
17ms: PROCESS 828 ADDED TO READY QUEUE
17ms: PROCESS 831 ADDED TO READY QUEUE
17ms: PROCESS 846 ADDED TO READY QUEUE
17ms: PROCESS 857 ADDED TO READY QUEUE
17ms: PROCESS 873 ADDED TO READY QUEUE
17ms: PROCESS 880 ADDED TO READY QUEUE
17ms: PROCESS 882 ADDED TO READY QUEUE
17ms: PROCESS 941 ADDED TO READY QUEUE
17ms: PROCESS 963 ADDED TO READY QUEUE
17ms: PROCESS 976 ADDED TO READY QUEUE
17ms: PROCESS 22 SENT TO IO QUEUE
17ms: PROCESS 23 DISPATCHED TO CPU
18ms: PROCESS 91 ADDED TO READY QUEUE
18ms: PROCESS 94 ADDED TO READY QUEUE
18ms: PROCESS 155 ADDED TO READY QUEUE
18ms: PROCESS 182 ADDED TO READY QUEUE
18ms: PROCESS 204 ADDED TO READY QUEUE
18ms: PROCESS 209 ADDED TO READY QUEUE
18ms: PROCESS 258 ADDED TO READY QUEUE
18ms: PROCESS 278 ADDED TO READY QUEUE
18ms: PROCESS 325 ADDED TO READY QUEUE
18ms: PROCESS 327 ADDED TO READY QUEUE
18ms: PROCESS 340 ADDED TO READY QUEUE
18ms: PROCESS 353 ADDED TO READY QUEUE
18ms: PROCESS 356 ADDED TO READY QUEUE
18ms: PROCESS 368 ADDED TO READY QUEUE
18ms: PROCESS 438 ADDED TO READY QUEUE
18ms: PROCESS 497 ADDED TO READY QUEUE
18ms: PROCESS 515 ADDED TO READY QUEUE
18ms: PROCESS 589 ADDED TO READY QUEUE
18ms: PROCESS 596 ADDED TO READY QUEUE
18ms: PROCESS 597 ADDED TO READY QUEUE
18ms: PROCESS 631 ADDED TO READY QUEUE
18ms: PROCESS 639 ADDED TO READY QUEUE
18ms: PROCESS 644 ADDED TO READY QUEUE
18ms: PROCESS 645 ADDED TO READY QUEUE
18ms: PROCESS 647 ADDED TO READY QUEUE
18ms: PROCESS 648 ADDED TO READY QUEUE
18ms: PROCESS 690 ADDED TO READY QUEUE
18ms: PROCESS 705 ADDED TO READY QUEUE
18ms: PROCESS 725 ADDED TO READY QUEUE
18ms: PROCESS 748 ADDED TO READY QUEUE
18ms: PROCESS 763 ADDED TO READY QUEUE
18ms: PROCESS 814 ADDED TO READY QUEUE
18ms: PROCESS 918 ADDED TO READY QUEUE
18ms: PROCESS 921 ADDED TO READY QUEUE
18ms: PROCESS 928 ADDED TO READY QUEUE
18ms: PROCESS 955 ADDED TO READY QUEUE
18ms: PROCESS 957 ADDED TO READY QUEUE
18ms: PROCESS 969 ADDED TO READY QUEUE
18ms: PROCESS 970 ADDED TO READY QUEUE
18ms: PROCESS 977 ADDED TO READY QUEUE
18ms: PROCESS 984 ADDED TO READY QUEUE
19ms: PROCESS 16 ADDED TO READY QUEUE
19ms: PROCESS 18 ADDED TO READY QUEUE
19ms: PROCESS 24 ADDED TO READY QUEUE
19ms: PROCESS 29 ADDED TO READY QUEUE
19ms: PROCESS 33 ADDED TO READY QUEUE
19ms: PROCESS 58 ADDED TO READY QUEUE
19ms: PROCESS 80 ADDED TO READY QUEUE
19ms: PROCESS 97 ADDED TO READY QUEUE
19ms: PROCESS 99 ADDED TO READY QUEUE
19ms: PROCESS 114 ADDED TO READY QUEUE
19ms: PROCESS 130 ADDED TO READY QUEUE
19ms: PROCESS 154 ADDED TO READY QUEUE
19ms: PROCESS 206 ADDED TO READY QUEUE
19ms: PROCESS 208 ADDED TO READY QUEUE
19ms: PROCESS 310 ADDED TO READY QUEUE
19ms: PROCESS 349 ADDED TO READY QUEUE
19ms: PROCESS 376 ADDED TO READY QUEUE
19ms: PROCESS 399 ADDED TO READY QUEUE
19ms: PROCESS 419 ADDED TO READY QUEUE
19ms: PROCESS 420 ADDED TO READY QUEUE
19ms: PROCESS 433 ADDED TO READY QUEUE
19ms: PROCESS 441 ADDED TO READY QUEUE
19ms: PROCESS 459 ADDED TO READY QUEUE
19ms: PROCESS 466 ADDED TO READY QUEUE
19ms: PROCESS 509 ADDED TO READY QUEUE
19ms: PROCESS 557 ADDED TO READY QUEUE
19ms: PROCESS 614 ADDED TO READY QUEUE
19ms: PROCESS 710 ADDED TO READY QUEUE
19ms: PROCESS 726 ADDED TO READY QUEUE
19ms: PROCESS 746 ADDED TO READY QUEUE
19ms: PROCESS 800 ADDED TO READY QUEUE
19ms: PROCESS 801 ADDED TO READY QUEUE
19ms: PROCESS 821 ADDED TO READY QUEUE
19ms: PROCESS 848 ADDED TO READY QUEUE
19ms: PROCESS 869 ADDED TO READY QUEUE
19ms: PROCESS 890 ADDED TO READY QUEUE
19ms: PROCESS 899 ADDED TO READY QUEUE
19ms: PROCESS 924 ADDED TO READY QUEUE
20ms: PROCESS 3 ADDED TO READY QUEUE
20ms: PROCESS 27 ADDED TO READY QUEUE
20ms: PROCESS 82 ADDED TO READY QUEUE
20ms: PROCESS 120 ADDED TO READY QUEUE
20ms: PROCESS 160 ADDED TO READY QUEUE
20ms: PROCESS 189 ADDED TO READY QUEUE
20ms: PROCESS 197 ADDED TO READY QUEUE
20ms: PROCESS 201 ADDED TO READY QUEUE
20ms: PROCESS 261 ADDED TO READY QUEUE
20ms: PROCESS 262 ADDED TO READY QUEUE
20ms: PROCESS 287 ADDED TO READY QUEUE
20ms: PROCESS 330 ADDED TO READY QUEUE
20ms: PROCESS 337 ADDED TO READY QUEUE
20ms: PROCESS 347 ADDED TO READY QUEUE
20ms: PROCESS 404 ADDED TO READY QUEUE
20ms: PROCESS 423 ADDED TO READY QUEUE
20ms: PROCESS 432 ADDED TO READY QUEUE
20ms: PROCESS 493 ADDED TO READY QUEUE
20ms: PROCESS 496 ADDED TO READY QUEUE
20ms: PROCESS 504 ADDED TO READY QUEUE
20ms: PROCESS 510 ADDED TO READY QUEUE
20ms: PROCESS 539 ADDED TO READY QUEUE
20ms: PROCESS 572 ADDED TO READY QUEUE
20ms: PROCESS 580 ADDED TO READY QUEUE
20ms: PROCESS 585 ADDED TO READY QUEUE
20ms: PROCESS 615 ADDED TO READY QUEUE
20ms: PROCESS 620 ADDED TO READY QUEUE
20ms: PROCESS 628 ADDED TO READY QUEUE
20ms: PROCESS 640 ADDED TO READY QUEUE
20ms: PROCESS 689 ADDED TO READY QUEUE
20ms: PROCESS 720 ADDED TO READY QUEUE
20ms: PROCESS 742 ADDED TO READY QUEUE
20ms: PROCESS 772 ADDED TO READY QUEUE
20ms: PROCESS 773 ADDED TO READY QUEUE
20ms: PROCESS 794 ADDED TO READY QUEUE
20ms: PROCESS 806 ADDED TO READY QUEUE
20ms: PROCESS 824 ADDED TO READY QUEUE
20ms: PROCESS 835 ADDED TO READY QUEUE
20ms: PROCESS 870 ADDED TO READY QUEUE
20ms: PROCESS 878 ADDED TO READY QUEUE
20ms: PROCESS 925 ADDED TO READY QUEUE
20ms: PROCESS 932 ADDED TO READY QUEUE
20ms: PROCESS 982 ADDED TO READY QUEUE
20ms: PROCESS 996 ADDED TO READY QUEUE
21ms: PROCESS 32 ADDED TO READY QUEUE
21ms: PROCESS 35 ADDED TO READY QUEUE
21ms: PROCESS 65 ADDED TO READY QUEUE
21ms: PROCESS 72 ADDED TO READY QUEUE
21ms: PROCESS 104 ADDED TO READY QUEUE
21ms: PROCESS 111 ADDED TO READY QUEUE
21ms: PROCESS 156 ADDED TO READY QUEUE
21ms: PROCESS 158 ADDED TO READY QUEUE
21ms: PROCESS 212 ADDED TO READY QUEUE
21ms: PROCESS 224 ADDED TO READY QUEUE
21ms: PROCESS 231 ADDED TO READY QUEUE
21ms: PROCESS 236 ADDED TO READY QUEUE
21ms: PROCESS 248 ADDED TO READY QUEUE
21ms: PROCESS 250 ADDED TO READY QUEUE
21ms: PROCESS 263 ADDED TO READY QUEUE
21ms: PROCESS 270 ADDED TO READY QUEUE
21ms: PROCESS 272 ADDED TO READY QUEUE
21ms: PROCESS 374 ADDED TO READY QUEUE
21ms: PROCESS 378 ADDED TO READY QUEUE
21ms: PROCESS 382 ADDED TO READY QUEUE
21ms: PROCESS 402 ADDED TO READY QUEUE
21ms: PROCESS 425 ADDED TO READY QUEUE
21ms: PROCESS 486 ADDED TO READY QUEUE
21ms: PROCESS 488 ADDED TO READY QUEUE
21ms: PROCESS 502 ADDED TO READY QUEUE
21ms: PROCESS 525 ADDED TO READY QUEUE
21ms: PROCESS 541 ADDED TO READY QUEUE
21ms: PROCESS 553 ADDED TO READY QUEUE
21ms: PROCESS 598 ADDED TO READY QUEUE
21ms: PROCESS 609 ADDED TO READY QUEUE
21ms: PROCESS 625 ADDED TO READY QUEUE
21ms: PROCESS 660 ADDED TO READY QUEUE
21ms: PROCESS 665 ADDED TO READY QUEUE
21ms: PROCESS 724 ADDED TO READY QUEUE
21ms: PROCESS 775 ADDED TO READY QUEUE
21ms: PROCESS 833 ADDED TO READY QUEUE
21ms: PROCESS 879 ADDED TO READY QUEUE
21ms: PROCESS 922 ADDED TO READY QUEUE
21ms: PROCESS 942 ADDED TO READY QUEUE
21ms: PROCESS 975 ADDED TO READY QUEUE
21ms: PROCESS 979 ADDED TO READY QUEUE
22ms: PROCESS 17 ADDED TO READY QUEUE
22ms: PROCESS 48 ADDED TO READY QUEUE
22ms: PROCESS 66 ADDED TO READY QUEUE
22ms: PROCESS 69 ADDED TO READY QUEUE
22ms: PROCESS 74 ADDED TO READY QUEUE
22ms: PROCESS 89 ADDED TO READY QUEUE
22ms: PROCESS 96 ADDED TO READY QUEUE
22ms: PROCESS 106 ADDED TO READY QUEUE
22ms: PROCESS 116 ADDED TO READY QUEUE
22ms: PROCESS 147 ADDED TO READY QUEUE
22ms: PROCESS 172 ADDED TO READY QUEUE
22ms: PROCESS 191 ADDED TO READY QUEUE
22ms: PROCESS 203 ADDED TO READY QUEUE
22ms: PROCESS 260 ADDED TO READY QUEUE
22ms: PROCESS 283 ADDED TO READY QUEUE
22ms: PROCESS 288 ADDED TO READY QUEUE
22ms: PROCESS 295 ADDED TO READY QUEUE
22ms: PROCESS 296 ADDED TO READY QUEUE
22ms: PROCESS 335 ADDED TO READY QUEUE
22ms: PROCESS 342 ADDED TO READY QUEUE
22ms: PROCESS 345 ADDED TO READY QUEUE
22ms: PROCESS 372 ADDED TO READY QUEUE
22ms: PROCESS 387 ADDED TO READY QUEUE
22ms: PROCESS 470 ADDED TO READY QUEUE
22ms: PROCESS 491 ADDED TO READY QUEUE
22ms: PROCESS 518 ADDED TO READY QUEUE
22ms: PROCESS 527 ADDED TO READY QUEUE
22ms: PROCESS 555 ADDED TO READY QUEUE
22ms: PROCESS 561 ADDED TO READY QUEUE
22ms: PROCESS 569 ADDED TO READY QUEUE
22ms: PROCESS 594 ADDED TO READY QUEUE
22ms: PROCESS 634 ADDED TO READY QUEUE
22ms: PROCESS 636 ADDED TO READY QUEUE
22ms: PROCESS 678 ADDED TO READY QUEUE
22ms: PROCESS 708 ADDED TO READY QUEUE
22ms: PROCESS 714 ADDED TO READY QUEUE
22ms: PROCESS 729 ADDED TO READY QUEUE
22ms: PROCESS 896 ADDED TO READY QUEUE
22ms: PROCESS 901 ADDED TO READY QUEUE
22ms: PROCESS 994 ADDED TO READY QUEUE
22ms: PROCESS 995 ADDED TO READY QUEUE
23ms: PROCESS 19 ADDED TO READY QUEUE
23ms: PROCESS 20 ADDED TO READY QUEUE
23ms: PROCESS 127 ADDED TO READY QUEUE
23ms: PROCESS 152 ADDED TO READY QUEUE
23ms: PROCESS 179 ADDED TO READY QUEUE
23ms: PROCESS 190 ADDED TO READY QUEUE
23ms: PROCESS 230 ADDED TO READY QUEUE
23ms: PROCESS 237 ADDED TO READY QUEUE
23ms: PROCESS 242 ADDED TO READY QUEUE
23ms: PROCESS 259 ADDED TO READY QUEUE
23ms: PROCESS 291 ADDED TO READY QUEUE
23ms: PROCESS 294 ADDED TO READY QUEUE
23ms: PROCESS 297 ADDED TO READY QUEUE
23ms: PROCESS 334 ADDED TO READY QUEUE
23ms: PROCESS 352 ADDED TO READY QUEUE
23ms: PROCESS 354 ADDED TO READY QUEUE
23ms: PROCESS 363 ADDED TO READY QUEUE
23ms: PROCESS 366 ADDED TO READY QUEUE
23ms: PROCESS 388 ADDED TO READY QUEUE
23ms: PROCESS 394 ADDED TO READY QUEUE
23ms: PROCESS 396 ADDED TO READY QUEUE
23ms: PROCESS 405 ADDED TO READY QUEUE
23ms: PROCESS 417 ADDED TO READY QUEUE
23ms: PROCESS 445 ADDED TO READY QUEUE
23ms: PROCESS 449 ADDED TO READY QUEUE
23ms: PROCESS 472 ADDED TO READY QUEUE
23ms: PROCESS 476 ADDED TO READY QUEUE
23ms: PROCESS 556 ADDED TO READY QUEUE
23ms: PROCESS 560 ADDED TO READY QUEUE
23ms: PROCESS 565 ADDED TO READY QUEUE
23ms: PROCESS 570 ADDED TO READY QUEUE
23ms: PROCESS 575 ADDED TO READY QUEUE
23ms: PROCESS 595 ADDED TO READY QUEUE
23ms: PROCESS 599 ADDED TO READY QUEUE
23ms: PROCESS 661 ADDED TO READY QUEUE
23ms: PROCESS 706 ADDED TO READY QUEUE
23ms: PROCESS 727 ADDED TO READY QUEUE
23ms: PROCESS 793 ADDED TO READY QUEUE
23ms: PROCESS 799 ADDED TO READY QUEUE
23ms: PROCESS 826 ADDED TO READY QUEUE
23ms: PROCESS 868 ADDED TO READY QUEUE
23ms: PROCESS 877 ADDED TO READY QUEUE
23ms: PROCESS 912 ADDED TO READY QUEUE
23ms: PROCESS 920 ADDED TO READY QUEUE
23ms: PROCESS 934 ADDED TO READY QUEUE
23ms: PROCESS 935 ADDED TO READY QUEUE
24ms: PROCESS 30 ADDED TO READY QUEUE
24ms: PROCESS 47 ADDED TO READY QUEUE
24ms: PROCESS 133 ADDED TO READY QUEUE
24ms: PROCESS 134 ADDED TO READY QUEUE
24ms: PROCESS 142 ADDED TO READY QUEUE
24ms: PROCESS 144 ADDED TO READY QUEUE
24ms: PROCESS 183 ADDED TO READY QUEUE
24ms: PROCESS 184 ADDED TO READY QUEUE
24ms: PROCESS 186 ADDED TO READY QUEUE
24ms: PROCESS 243 ADDED TO READY QUEUE
24ms: PROCESS 256 ADDED TO READY QUEUE
24ms: PROCESS 281 ADDED TO READY QUEUE
24ms: PROCESS 293 ADDED TO READY QUEUE
24ms: PROCESS 303 ADDED TO READY QUEUE
24ms: PROCESS 346 ADDED TO READY QUEUE
24ms: PROCESS 428 ADDED TO READY QUEUE
24ms: PROCESS 431 ADDED TO READY QUEUE
24ms: PROCESS 447 ADDED TO READY QUEUE
24ms: PROCESS 448 ADDED TO READY QUEUE
24ms: PROCESS 551 ADDED TO READY QUEUE
24ms: PROCESS 558 ADDED TO READY QUEUE
24ms: PROCESS 566 ADDED TO READY QUEUE
24ms: PROCESS 582 ADDED TO READY QUEUE
24ms: PROCESS 605 ADDED TO READY QUEUE
24ms: PROCESS 610 ADDED TO READY QUEUE
24ms: PROCESS 638 ADDED TO READY QUEUE
24ms: PROCESS 687 ADDED TO READY QUEUE
24ms: PROCESS 688 ADDED TO READY QUEUE
24ms: PROCESS 704 ADDED TO READY QUEUE
24ms: PROCESS 784 ADDED TO READY QUEUE
24ms: PROCESS 789 ADDED TO READY QUEUE
24ms: PROCESS 851 ADDED TO READY QUEUE
24ms: PROCESS 852 ADDED TO READY QUEUE
24ms: PROCESS 875 ADDED TO READY QUEUE
24ms: PROCESS 889 ADDED TO READY QUEUE
24ms: PROCESS 907 ADDED TO READY QUEUE
24ms: PROCESS 911 ADDED TO READY QUEUE
24ms: PROCESS 929 ADDED TO READY QUEUE
24ms: PROCESS 962 ADDED TO READY QUEUE
24ms: PROCESS 983 ADDED TO READY QUEUE
24ms: PROCESS 986 ADDED TO READY QUEUE
24ms: PROCESS 988 ADDED TO READY QUEUE
25ms: PROCESS 95 ADDED TO READY QUEUE
25ms: PROCESS 149 ADDED TO READY QUEUE
25ms: PROCESS 161 ADDED TO READY QUEUE
25ms: PROCESS 170 ADDED TO READY QUEUE
25ms: PROCESS 177 ADDED TO READY QUEUE
25ms: PROCESS 221 ADDED TO READY QUEUE
25ms: PROCESS 226 ADDED TO READY QUEUE
25ms: PROCESS 233 ADDED TO READY QUEUE
25ms: PROCESS 240 ADDED TO READY QUEUE
25ms: PROCESS 266 ADDED TO READY QUEUE
25ms: PROCESS 308 ADDED TO READY QUEUE
25ms: PROCESS 344 ADDED TO READY QUEUE
25ms: PROCESS 355 ADDED TO READY QUEUE
25ms: PROCESS 361 ADDED TO READY QUEUE
25ms: PROCESS 364 ADDED TO READY QUEUE
25ms: PROCESS 367 ADDED TO READY QUEUE
25ms: PROCESS 386 ADDED TO READY QUEUE
25ms: PROCESS 392 ADDED TO READY QUEUE
25ms: PROCESS 414 ADDED TO READY QUEUE
25ms: PROCESS 461 ADDED TO READY QUEUE
25ms: PROCESS 490 ADDED TO READY QUEUE
25ms: PROCESS 506 ADDED TO READY QUEUE
25ms: PROCESS 520 ADDED TO READY QUEUE
25ms: PROCESS 522 ADDED TO READY QUEUE
25ms: PROCESS 532 ADDED TO READY QUEUE
25ms: PROCESS 540 ADDED TO READY QUEUE
25ms: PROCESS 583 ADDED TO READY QUEUE
25ms: PROCESS 608 ADDED TO READY QUEUE
25ms: PROCESS 624 ADDED TO READY QUEUE
25ms: PROCESS 681 ADDED TO READY QUEUE
25ms: PROCESS 711 ADDED TO READY QUEUE
25ms: PROCESS 718 ADDED TO READY QUEUE
25ms: PROCESS 723 ADDED TO READY QUEUE
25ms: PROCESS 743 ADDED TO READY QUEUE
25ms: PROCESS 804 ADDED TO READY QUEUE
25ms: PROCESS 805 ADDED TO READY QUEUE
25ms: PROCESS 817 ADDED TO READY QUEUE
25ms: PROCESS 830 ADDED TO READY QUEUE
25ms: PROCESS 843 ADDED TO READY QUEUE
25ms: PROCESS 847 ADDED TO READY QUEUE
25ms: PROCESS 883 ADDED TO READY QUEUE
25ms: PROCESS 906 ADDED TO READY QUEUE
25ms: PROCESS 936 ADDED TO READY QUEUE
25ms: PROCESS 946 ADDED TO READY QUEUE
25ms: PROCESS 964 ADDED TO READY QUEUE
25ms: PROCESS 990 ADDED TO READY QUEUE
25ms: PROCESS 999 ADDED TO READY QUEUE
42ms: PROCESS 23 SENT TO IO QUEUE
42ms: PROCESS 45 DISPATCHED TO CPU
42ms: PROCESS 22 ADDED TO READY QUEUE
42ms: PROCESS 22 DONE WITH IO
56ms: PROCESS 45 SENT TO IO QUEUE
56ms: PROCESS 107 DISPATCHED TO CPU
56ms: PROCESS 23 ADDED TO READY QUEUE
56ms: PROCESS 23 DONE WITH IO
57ms: PROCESS 45 ADDED TO READY QUEUE
57ms: PROCESS 45 DONE WITH IO
80ms: PROCESS 107 SENT TO IO QUEUE
80ms: PROCESS 109 DISPATCHED TO CPU
81ms: PROCESS 107 ADDED TO READY QUEUE
81ms: PROCESS 107 DONE WITH IO
86ms: PROCESS 109 SENT TO IO QUEUE
86ms: PROCESS 113 DISPATCHED TO CPU
103ms: PROCESS 109 ADDED TO READY QUEUE
103ms: PROCESS 109 DONE WITH IO
107ms: PROCESS 113 SENT TO IO QUEUE
107ms: PROCESS 119 DISPATCHED TO CPU
109ms: PROCESS 113 ADDED TO READY QUEUE
109ms: PROCESS 113 DONE WITH IO
112ms: PROCESS 119 SENT TO IO QUEUE
112ms: PROCESS 138 DISPATCHED TO CPU
114ms: PROCESS 119 ADDED TO READY QUEUE
114ms: PROCESS 119 DONE WITH IO
129ms: PROCESS 138 SENT TO IO QUEUE
129ms: PROCESS 143 DISPATCHED TO CPU
142ms: PROCESS 143 SENT TO IO QUEUE
142ms: PROCESS 168 DISPATCHED TO CPU
150ms: PROCESS 138 ADDED TO READY QUEUE
150ms: PROCESS 138 DONE WITH IO
153ms: PROCESS 143 ADDED TO READY QUEUE
153ms: PROCESS 143 DONE WITH IO
159ms: PROCESS 168 SENT TO IO QUEUE
159ms: PROCESS 219 DISPATCHED TO CPU
162ms: PROCESS 168 ADDED TO READY QUEUE
162ms: PROCESS 168 DONE WITH IO
175ms: PROCESS 219 SENT TO IO QUEUE
175ms: PROCESS 225 DISPATCHED TO CPU
192ms: PROCESS 225 SENT TO IO QUEUE
192ms: PROCESS 241 DISPATCHED TO CPU
197ms: PROCESS 219 ADDED TO READY QUEUE
197ms: PROCESS 219 DONE WITH IO
199ms: PROCESS 225 ADDED TO READY QUEUE
199ms: PROCESS 225 DONE WITH IO
214ms: PROCESS 241 SENT TO IO QUEUE
214ms: PROCESS 322 DISPATCHED TO CPU
226ms: PROCESS 322 SENT TO IO QUEUE
226ms: PROCESS 343 DISPATCHED TO CPU
235ms: PROCESS 241 ADDED TO READY QUEUE
235ms: PROCESS 241 DONE WITH IO
238ms: PROCESS 343 SENT TO IO QUEUE
238ms: PROCESS 350 DISPATCHED TO CPU
240ms: PROCESS 350 FINISHED, TURNAROUND: 0ms, CPU WAIT: 239ms, IO WAIT: 0ms
240ms: PROCESS 362 DISPATCHED TO CPU
250ms: PROCESS 322 ADDED TO READY QUEUE
250ms: PROCESS 322 DONE WITH IO
251ms: PROCESS 362 SENT TO IO QUEUE
251ms: PROCESS 369 DISPATCHED TO CPU
261ms: PROCESS 369 SENT TO IO QUEUE
261ms: PROCESS 377 DISPATCHED TO CPU
268ms: PROCESS 377 SENT TO IO QUEUE
268ms: PROCESS 452 DISPATCHED TO CPU
272ms: PROCESS 343 ADDED TO READY QUEUE
272ms: PROCESS 343 DONE WITH IO
282ms: PROCESS 362 ADDED TO READY QUEUE
282ms: PROCESS 362 DONE WITH IO
286ms: PROCESS 452 SENT TO IO QUEUE
286ms: PROCESS 592 DISPATCHED TO CPU
291ms: PROCESS 592 SENT TO IO QUEUE
291ms: PROCESS 618 DISPATCHED TO CPU
297ms: PROCESS 369 ADDED TO READY QUEUE
297ms: PROCESS 369 DONE WITH IO
299ms: PROCESS 618 SENT TO IO QUEUE
299ms: PROCESS 657 DISPATCHED TO CPU
299ms: PROCESS 377 ADDED TO READY QUEUE
299ms: PROCESS 377 DONE WITH IO
311ms: PROCESS 452 ADDED TO READY QUEUE
311ms: PROCESS 452 DONE WITH IO
323ms: PROCESS 657 SENT TO IO QUEUE
323ms: PROCESS 663 DISPATCHED TO CPU
331ms: PROCESS 592 ADDED TO READY QUEUE
331ms: PROCESS 592 DONE WITH IO
339ms: PROCESS 663 SENT TO IO QUEUE
339ms: PROCESS 669 DISPATCHED TO CPU
340ms: PROCESS 669 SENT TO IO QUEUE
340ms: PROCESS 685 DISPATCHED TO CPU
342ms: PROCESS 685 SENT TO IO QUEUE
342ms: PROCESS 698 DISPATCHED TO CPU
353ms: PROCESS 618 ADDED TO READY QUEUE
353ms: PROCESS 618 DONE WITH IO
364ms: PROCESS 657 ADDED TO READY QUEUE
364ms: PROCESS 657 DONE WITH IO
367ms: PROCESS 698 SENT TO IO QUEUE
367ms: PROCESS 715 DISPATCHED TO CPU
373ms: PROCESS 663 ADDED TO READY QUEUE
373ms: PROCESS 663 DONE WITH IO
376ms: PROCESS 669 ADDED TO READY QUEUE
376ms: PROCESS 669 DONE WITH IO
385ms: PROCESS 715 SENT TO IO QUEUE
385ms: PROCESS 728 DISPATCHED TO CPU
398ms: PROCESS 685 ADDED TO READY QUEUE
398ms: PROCESS 685 DONE WITH IO
401ms: PROCESS 728 SENT TO IO QUEUE
401ms: PROCESS 733 DISPATCHED TO CPU
419ms: PROCESS 733 SENT TO IO QUEUE
419ms: PROCESS 740 DISPATCHED TO CPU
422ms: PROCESS 698 ADDED TO READY QUEUE
422ms: PROCESS 698 DONE WITH IO
432ms: PROCESS 740 SENT TO IO QUEUE
432ms: PROCESS 754 DISPATCHED TO CPU
437ms: PROCESS 715 ADDED TO READY QUEUE
437ms: PROCESS 715 DONE WITH IO
439ms: PROCESS 754 SENT TO IO QUEUE
439ms: PROCESS 771 DISPATCHED TO CPU
445ms: PROCESS 728 ADDED TO READY QUEUE
445ms: PROCESS 728 DONE WITH IO
456ms: PROCESS 771 SENT TO IO QUEUE
456ms: PROCESS 785 DISPATCHED TO CPU
459ms: PROCESS 733 ADDED TO READY QUEUE
459ms: PROCESS 733 DONE WITH IO
464ms: PROCESS 740 ADDED TO READY QUEUE
464ms: PROCESS 740 DONE WITH IO
465ms: PROCESS 754 ADDED TO READY QUEUE
465ms: PROCESS 754 DONE WITH IO
471ms: PROCESS 785 SENT TO IO QUEUE
471ms: PROCESS 820 DISPATCHED TO CPU
472ms: PROCESS 771 ADDED TO READY QUEUE
472ms: PROCESS 771 DONE WITH IO
480ms: PROCESS 785 ADDED TO READY QUEUE
480ms: PROCESS 785 DONE WITH IO
496ms: PROCESS 820 SENT TO IO QUEUE
496ms: PROCESS 822 DISPATCHED TO CPU
499ms: PROCESS 822 FINISHED, TURNAROUND: 0ms, CPU WAIT: 497ms, IO WAIT: 0ms
499ms: PROCESS 827 DISPATCHED TO CPU
507ms: PROCESS 820 ADDED TO READY QUEUE
507ms: PROCESS 820 DONE WITH IO
519ms: PROCESS 827 SENT TO IO QUEUE
519ms: PROCESS 840 DISPATCHED TO CPU
529ms: PROCESS 827 ADDED TO READY QUEUE
529ms: PROCESS 827 DONE WITH IO
531ms: PROCESS 840 SENT TO IO QUEUE
531ms: PROCESS 853 DISPATCHED TO CPU
552ms: PROCESS 840 ADDED TO READY QUEUE
552ms: PROCESS 840 DONE WITH IO
555ms: PROCESS 853 SENT TO IO QUEUE
555ms: PROCESS 926 DISPATCHED TO CPU
560ms: PROCESS 853 ADDED TO READY QUEUE
560ms: PROCESS 853 DONE WITH IO
568ms: PROCESS 926 SENT TO IO QUEUE
568ms: PROCESS 960 DISPATCHED TO CPU
580ms: PROCESS 960 SENT TO IO QUEUE
580ms: PROCESS 9 DISPATCHED TO CPU
591ms: PROCESS 926 ADDED TO READY QUEUE
591ms: PROCESS 926 DONE WITH IO
593ms: PROCESS 9 SENT TO IO QUEUE
593ms: PROCESS 36 DISPATCHED TO CPU
593ms: PROCESS 960 ADDED TO READY QUEUE
593ms: PROCESS 960 DONE WITH IO
596ms: PROCESS 9 ADDED TO READY QUEUE
596ms: PROCESS 9 DONE WITH IO
617ms: PROCESS 36 SENT TO IO QUEUE
617ms: PROCESS 39 DISPATCHED TO CPU
624ms: PROCESS 39 SENT TO IO QUEUE
624ms: PROCESS 136 DISPATCHED TO CPU
632ms: PROCESS 36 ADDED TO READY QUEUE
632ms: PROCESS 36 DONE WITH IO
640ms: PROCESS 136 SENT TO IO QUEUE
640ms: PROCESS 139 DISPATCHED TO CPU
642ms: PROCESS 39 ADDED TO READY QUEUE
642ms: PROCESS 39 DONE WITH IO
646ms: PROCESS 139 SENT TO IO QUEUE
646ms: PROCESS 146 DISPATCHED TO CPU
649ms: PROCESS 136 ADDED TO READY QUEUE
649ms: PROCESS 136 DONE WITH IO
655ms: PROCESS 139 ADDED TO READY QUEUE
655ms: PROCESS 139 DONE WITH IO
663ms: PROCESS 146 SENT TO IO QUEUE
663ms: PROCESS 169 DISPATCHED TO CPU
677ms: PROCESS 146 ADDED TO READY QUEUE
677ms: PROCESS 146 DONE WITH IO
686ms: PROCESS 169 SENT TO IO QUEUE
686ms: PROCESS 174 DISPATCHED TO CPU
697ms: PROCESS 174 SENT TO IO QUEUE
697ms: PROCESS 239 DISPATCHED TO CPU
698ms: PROCESS 169 ADDED TO READY QUEUE
698ms: PROCESS 169 DONE WITH IO
705ms: PROCESS 239 SENT TO IO QUEUE
705ms: PROCESS 254 DISPATCHED TO CPU
718ms: PROCESS 174 ADDED TO READY QUEUE
718ms: PROCESS 174 DONE WITH IO
727ms: PROCESS 254 SENT TO IO QUEUE
727ms: PROCESS 274 DISPATCHED TO CPU
733ms: PROCESS 239 ADDED TO READY QUEUE
733ms: PROCESS 239 DONE WITH IO
739ms: PROCESS 254 ADDED TO READY QUEUE
739ms: PROCESS 254 DONE WITH IO
747ms: PROCESS 274 SENT TO IO QUEUE
747ms: PROCESS 298 DISPATCHED TO CPU
755ms: PROCESS 274 ADDED TO READY QUEUE
755ms: PROCESS 274 DONE WITH IO
762ms: PROCESS 298 SENT TO IO QUEUE
762ms: PROCESS 305 DISPATCHED TO CPU
763ms: PROCESS 305 SENT TO IO QUEUE
763ms: PROCESS 316 DISPATCHED TO CPU
774ms: PROCESS 298 ADDED TO READY QUEUE
774ms: PROCESS 298 DONE WITH IO
788ms: PROCESS 316 SENT TO IO QUEUE
788ms: PROCESS 331 DISPATCHED TO CPU
791ms: PROCESS 331 SENT TO IO QUEUE
791ms: PROCESS 384 DISPATCHED TO CPU
795ms: PROCESS 305 ADDED TO READY QUEUE
795ms: PROCESS 305 DONE WITH IO
798ms: PROCESS 316 ADDED TO READY QUEUE
798ms: PROCESS 316 DONE WITH IO
812ms: PROCESS 384 SENT TO IO QUEUE
812ms: PROCESS 469 DISPATCHED TO CPU
816ms: PROCESS 331 ADDED TO READY QUEUE
816ms: PROCESS 331 DONE WITH IO
823ms: PROCESS 469 SENT TO IO QUEUE
823ms: PROCESS 548 DISPATCHED TO CPU
832ms: PROCESS 384 ADDED TO READY QUEUE
832ms: PROCESS 384 DONE WITH IO
843ms: PROCESS 548 SENT TO IO QUEUE
843ms: PROCESS 576 DISPATCHED TO CPU
854ms: PROCESS 469 ADDED TO READY QUEUE
854ms: PROCESS 469 DONE WITH IO
864ms: PROCESS 576 SENT TO IO QUEUE
864ms: PROCESS 622 DISPATCHED TO CPU
872ms: PROCESS 622 SENT TO IO QUEUE
872ms: PROCESS 623 DISPATCHED TO CPU
876ms: PROCESS 548 ADDED TO READY QUEUE
876ms: PROCESS 548 DONE WITH IO
891ms: PROCESS 623 SENT TO IO QUEUE
891ms: PROCESS 635 DISPATCHED TO CPU
891ms: PROCESS 576 ADDED TO READY QUEUE
891ms: PROCESS 576 DONE WITH IO
910ms: PROCESS 622 ADDED TO READY QUEUE
910ms: PROCESS 622 DONE WITH IO
916ms: PROCESS 635 SENT TO IO QUEUE
916ms: PROCESS 667 DISPATCHED TO CPU
919ms: PROCESS 667 SENT TO IO QUEUE
919ms: PROCESS 697 DISPATCHED TO CPU
929ms: PROCESS 623 ADDED TO READY QUEUE
929ms: PROCESS 623 DONE WITH IO
930ms: PROCESS 697 SENT TO IO QUEUE
930ms: PROCESS 703 DISPATCHED TO CPU
941ms: PROCESS 703 SENT TO IO QUEUE
941ms: PROCESS 716 DISPATCHED TO CPU
944ms: PROCESS 716 FINISHED, TURNAROUND: 0ms, CPU WAIT: 941ms, IO WAIT: 0ms
944ms: PROCESS 719 DISPATCHED TO CPU
948ms: PROCESS 635 ADDED TO READY QUEUE
948ms: PROCESS 635 DONE WITH IO
957ms: PROCESS 667 ADDED TO READY QUEUE
957ms: PROCESS 667 DONE WITH IO
958ms: PROCESS 719 SENT TO IO QUEUE
958ms: PROCESS 737 DISPATCHED TO CPU
975ms: PROCESS 737 SENT TO IO QUEUE
975ms: PROCESS 756 DISPATCHED TO CPU
977ms: PROCESS 697 ADDED TO READY QUEUE
977ms: PROCESS 697 DONE WITH IO
993ms: PROCESS 703 ADDED TO READY QUEUE
993ms: PROCESS 703 DONE WITH IO
999ms: PROCESS 756 SENT TO IO QUEUE
999ms: PROCESS 758 DISPATCHED TO CPU
1011ms: PROCESS 719 ADDED TO READY QUEUE
1011ms: PROCESS 719 DONE WITH IO
1017ms: PROCESS 758 SENT TO IO QUEUE
1017ms: PROCESS 766 DISPATCHED TO CPU
1030ms: PROCESS 766 SENT TO IO QUEUE
1030ms: PROCESS 780 DISPATCHED TO CPU
1030ms: PROCESS 737 ADDED TO READY QUEUE
1030ms: PROCESS 737 DONE WITH IO
1037ms: PROCESS 780 FINISHED, TURNAROUND: 0ms, CPU WAIT: 1030ms, IO WAIT: 0ms
1037ms: PROCESS 786 DISPATCHED TO CPU
1050ms: PROCESS 756 ADDED TO READY QUEUE
1050ms: PROCESS 756 DONE WITH IO
1051ms: PROCESS 786 SENT TO IO QUEUE
1051ms: PROCESS 813 DISPATCHED TO CPU
1072ms: PROCESS 813 SENT TO IO QUEUE
1072ms: PROCESS 816 DISPATCHED TO CPU
1073ms: PROCESS 758 ADDED TO READY QUEUE
1073ms: PROCESS 758 DONE WITH IO
1088ms: PROCESS 816 SENT TO IO QUEUE
1088ms: PROCESS 881 DISPATCHED TO CPU
1091ms: PROCESS 881 SENT TO IO QUEUE
1091ms: PROCESS 902 DISPATCHED TO CPU
1098ms: PROCESS 766 ADDED TO READY QUEUE
1098ms: PROCESS 766 DONE WITH IO
1099ms: PROCESS 786 ADDED TO READY QUEUE
1099ms: PROCESS 786 DONE WITH IO
1104ms: PROCESS 902 SENT TO IO QUEUE
1104ms: PROCESS 905 DISPATCHED TO CPU
1114ms: PROCESS 905 SENT TO IO QUEUE
1114ms: PROCESS 908 DISPATCHED TO CPU
1123ms: PROCESS 813 ADDED TO READY QUEUE
1123ms: PROCESS 813 DONE WITH IO
1126ms: PROCESS 908 SENT TO IO QUEUE
1126ms: PROCESS 915 DISPATCHED TO CPU
1129ms: PROCESS 816 ADDED TO READY QUEUE
1129ms: PROCESS 816 DONE WITH IO
1143ms: PROCESS 915 SENT TO IO QUEUE
1143ms: PROCESS 919 DISPATCHED TO CPU
1150ms: PROCESS 881 ADDED TO READY QUEUE
1150ms: PROCESS 881 DONE WITH IO
1153ms: PROCESS 919 SENT TO IO QUEUE
1153ms: PROCESS 959 DISPATCHED TO CPU
1163ms: PROCESS 902 ADDED TO READY QUEUE
1163ms: PROCESS 902 DONE WITH IO
1168ms: PROCESS 905 ADDED TO READY QUEUE
1168ms: PROCESS 905 DONE WITH IO
1178ms: PROCESS 959 SENT TO IO QUEUE
1178ms: PROCESS 55 DISPATCHED TO CPU
1181ms: PROCESS 908 ADDED TO READY QUEUE
1181ms: PROCESS 908 DONE WITH IO
1196ms: PROCESS 915 ADDED TO READY QUEUE
1196ms: PROCESS 915 DONE WITH IO
1198ms: PROCESS 55 SENT TO IO QUEUE
1198ms: PROCESS 110 DISPATCHED TO CPU
1213ms: PROCESS 919 ADDED TO READY QUEUE
1213ms: PROCESS 919 DONE WITH IO
1217ms: PROCESS 110 SENT TO IO QUEUE
1217ms: PROCESS 137 DISPATCHED TO CPU
1226ms: PROCESS 137 SENT TO IO QUEUE
1226ms: PROCESS 140 DISPATCHED TO CPU
1231ms: PROCESS 959 ADDED TO READY QUEUE
1231ms: PROCESS 959 DONE WITH IO
1232ms: PROCESS 140 SENT TO IO QUEUE
1232ms: PROCESS 171 DISPATCHED TO CPU
1233ms: PROCESS 171 SENT TO IO QUEUE
1233ms: PROCESS 194 DISPATCHED TO CPU
1241ms: PROCESS 194 SENT TO IO QUEUE
1241ms: PROCESS 215 DISPATCHED TO CPU
1249ms: PROCESS 215 SENT TO IO QUEUE
1249ms: PROCESS 289 DISPATCHED TO CPU
1255ms: PROCESS 55 ADDED TO READY QUEUE
1255ms: PROCESS 55 DONE WITH IO
1256ms: PROCESS 110 ADDED TO READY QUEUE
1256ms: PROCESS 110 DONE WITH IO
1273ms: PROCESS 289 SENT TO IO QUEUE
1273ms: PROCESS 328 DISPATCHED TO CPU
1279ms: PROCESS 137 ADDED TO READY QUEUE
1279ms: PROCESS 137 DONE WITH IO
1281ms: PROCESS 328 SENT TO IO QUEUE
1281ms: PROCESS 338 DISPATCHED TO CPU
1299ms: PROCESS 338 SENT TO IO QUEUE
1299ms: PROCESS 359 DISPATCHED TO CPU
1302ms: PROCESS 140 ADDED TO READY QUEUE
1302ms: PROCESS 140 DONE WITH IO
1307ms: PROCESS 359 SENT TO IO QUEUE
1307ms: PROCESS 360 DISPATCHED TO CPU
1316ms: PROCESS 171 ADDED TO READY QUEUE
1316ms: PROCESS 171 DONE WITH IO
1317ms: PROCESS 360 SENT TO IO QUEUE
1317ms: PROCESS 415 DISPATCHED TO CPU
1323ms: PROCESS 415 SENT TO IO QUEUE
1323ms: PROCESS 436 DISPATCHED TO CPU
1330ms: PROCESS 436 SENT TO IO QUEUE
1330ms: PROCESS 437 DISPATCHED TO CPU
1338ms: PROCESS 194 ADDED TO READY QUEUE
1338ms: PROCESS 194 DONE WITH IO
1343ms: PROCESS 215 ADDED TO READY QUEUE
1343ms: PROCESS 215 DONE WITH IO
1355ms: PROCESS 437 SENT TO IO QUEUE
1355ms: PROCESS 440 DISPATCHED TO CPU
1362ms: PROCESS 289 ADDED TO READY QUEUE
1362ms: PROCESS 289 DONE WITH IO
1364ms: PROCESS 328 ADDED TO READY QUEUE
1364ms: PROCESS 328 DONE WITH IO
1379ms: PROCESS 440 SENT TO IO QUEUE
1379ms: PROCESS 455 DISPATCHED TO CPU
1383ms: PROCESS 338 ADDED TO READY QUEUE
1383ms: PROCESS 338 DONE WITH IO
1391ms: PROCESS 455 FINISHED, TURNAROUND: 0ms, CPU WAIT: 1378ms, IO WAIT: 0ms
1391ms: PROCESS 468 DISPATCHED TO CPU
1394ms: PROCESS 359 ADDED TO READY QUEUE
1394ms: PROCESS 359 DONE WITH IO
1410ms: PROCESS 468 SENT TO IO QUEUE
1410ms: PROCESS 499 DISPATCHED TO CPU
1413ms: PROCESS 360 ADDED TO READY QUEUE
1413ms: PROCESS 360 DONE WITH IO
1424ms: PROCESS 415 ADDED TO READY QUEUE
1424ms: PROCESS 415 DONE WITH IO
1429ms: PROCESS 499 SENT TO IO QUEUE
1429ms: PROCESS 505 DISPATCHED TO CPU
1436ms: PROCESS 436 ADDED TO READY QUEUE
1436ms: PROCESS 436 DONE WITH IO
1445ms: PROCESS 505 SENT TO IO QUEUE
1445ms: PROCESS 507 DISPATCHED TO CPU
1450ms: PROCESS 437 ADDED TO READY QUEUE
1450ms: PROCESS 437 DONE WITH IO
1456ms: PROCESS 507 SENT TO IO QUEUE
1456ms: PROCESS 530 DISPATCHED TO CPU
1469ms: PROCESS 440 ADDED TO READY QUEUE
1469ms: PROCESS 440 DONE WITH IO
1481ms: PROCESS 530 SENT TO IO QUEUE
1481ms: PROCESS 531 DISPATCHED TO CPU
1487ms: PROCESS 531 SENT TO IO QUEUE
1487ms: PROCESS 562 DISPATCHED TO CPU
1487ms: PROCESS 468 ADDED TO READY QUEUE
1487ms: PROCESS 468 DONE WITH IO
1489ms: PROCESS 562 SENT TO IO QUEUE
1489ms: PROCESS 591 DISPATCHED TO CPU
1500ms: PROCESS 499 ADDED TO READY QUEUE
1500ms: PROCESS 499 DONE WITH IO
1503ms: PROCESS 591 FINISHED, TURNAROUND: 0ms, CPU WAIT: 1488ms, IO WAIT: 0ms
1503ms: PROCESS 601 DISPATCHED TO CPU
1506ms: PROCESS 505 ADDED TO READY QUEUE
1506ms: PROCESS 505 DONE WITH IO
1519ms: PROCESS 507 ADDED TO READY QUEUE
1519ms: PROCESS 507 DONE WITH IO
1526ms: PROCESS 601 SENT TO IO QUEUE
1526ms: PROCESS 653 DISPATCHED TO CPU
1526ms: PROCESS 530 ADDED TO READY QUEUE
1526ms: PROCESS 530 DONE WITH IO
1532ms: PROCESS 653 SENT TO IO QUEUE
1532ms: PROCESS 673 DISPATCHED TO CPU
1533ms: PROCESS 673 SENT TO IO QUEUE
1533ms: PROCESS 707 DISPATCHED TO CPU
1551ms: PROCESS 531 ADDED TO READY QUEUE
1551ms: PROCESS 531 DONE WITH IO
1554ms: PROCESS 707 SENT TO IO QUEUE
1554ms: PROCESS 712 DISPATCHED TO CPU
1567ms: PROCESS 562 ADDED TO READY QUEUE
1567ms: PROCESS 562 DONE WITH IO
1577ms: PROCESS 712 SENT TO IO QUEUE
1577ms: PROCESS 739 DISPATCHED TO CPU
1590ms: PROCESS 601 ADDED TO READY QUEUE
1590ms: PROCESS 601 DONE WITH IO
1591ms: PROCESS 739 SENT TO IO QUEUE
1591ms: PROCESS 790 DISPATCHED TO CPU
1605ms: PROCESS 790 SENT TO IO QUEUE
1605ms: PROCESS 829 DISPATCHED TO CPU
1612ms: PROCESS 829 SENT TO IO QUEUE
1612ms: PROCESS 832 DISPATCHED TO CPU
1614ms: PROCESS 653 ADDED TO READY QUEUE
1614ms: PROCESS 653 DONE WITH IO
1624ms: PROCESS 673 ADDED TO READY QUEUE
1624ms: PROCESS 673 DONE WITH IO
1625ms: PROCESS 707 ADDED TO READY QUEUE
1625ms: PROCESS 707 DONE WITH IO
1632ms: PROCESS 832 SENT TO IO QUEUE
1632ms: PROCESS 838 DISPATCHED TO CPU
1634ms: PROCESS 712 ADDED TO READY QUEUE
1634ms: PROCESS 712 DONE WITH IO
1643ms: PROCESS 838 SENT TO IO QUEUE
1643ms: PROCESS 849 DISPATCHED TO CPU
1652ms: PROCESS 739 ADDED TO READY QUEUE
1652ms: PROCESS 739 DONE WITH IO
1657ms: PROCESS 790 ADDED TO READY QUEUE
1657ms: PROCESS 790 DONE WITH IO
1665ms: PROCESS 849 SENT TO IO QUEUE
1665ms: PROCESS 861 DISPATCHED TO CPU
1674ms: PROCESS 829 ADDED TO READY QUEUE
1674ms: PROCESS 829 DONE WITH IO
1683ms: PROCESS 861 SENT TO IO QUEUE
1683ms: PROCESS 892 DISPATCHED TO CPU
1691ms: PROCESS 832 ADDED TO READY QUEUE
1691ms: PROCESS 832 DONE WITH IO
1698ms: PROCESS 892 SENT TO IO QUEUE
1698ms: PROCESS 895 DISPATCHED TO CPU
1705ms: PROCESS 895 SENT TO IO QUEUE
1705ms: PROCESS 998 DISPATCHED TO CPU
1715ms: PROCESS 998 SENT TO IO QUEUE
1715ms: PROCESS 4 DISPATCHED TO CPU
1715ms: PROCESS 838 ADDED TO READY QUEUE
1715ms: PROCESS 838 DONE WITH IO
1725ms: PROCESS 849 ADDED TO READY QUEUE
1725ms: PROCESS 849 DONE WITH IO
1740ms: PROCESS 4 SENT TO IO QUEUE
1740ms: PROCESS 21 DISPATCHED TO CPU
1748ms: PROCESS 861 ADDED TO READY QUEUE
1748ms: PROCESS 861 DONE WITH IO
1756ms: PROCESS 892 ADDED TO READY QUEUE
1756ms: PROCESS 892 DONE WITH IO
1759ms: PROCESS 895 ADDED TO READY QUEUE
1759ms: PROCESS 895 DONE WITH IO
1761ms: PROCESS 21 SENT TO IO QUEUE
1761ms: PROCESS 38 DISPATCHED TO CPU
1774ms: PROCESS 38 SENT TO IO QUEUE
1774ms: PROCESS 46 DISPATCHED TO CPU
1781ms: PROCESS 998 ADDED TO READY QUEUE
1781ms: PROCESS 998 DONE WITH IO
1786ms: PROCESS 46 SENT TO IO QUEUE
1786ms: PROCESS 57 DISPATCHED TO CPU
1798ms: PROCESS 57 SENT TO IO QUEUE
1798ms: PROCESS 62 DISPATCHED TO CPU
1799ms: PROCESS 4 ADDED TO READY QUEUE
1799ms: PROCESS 4 DONE WITH IO
1802ms: PROCESS 62 SENT TO IO QUEUE
1802ms: PROCESS 63 DISPATCHED TO CPU
1805ms: PROCESS 21 ADDED TO READY QUEUE
1805ms: PROCESS 21 DONE WITH IO
1827ms: PROCESS 63 SENT TO IO QUEUE
1827ms: PROCESS 75 DISPATCHED TO CPU
1828ms: PROCESS 38 ADDED TO READY QUEUE
1828ms: PROCESS 38 DONE WITH IO
1851ms: PROCESS 75 SENT TO IO QUEUE
1851ms: PROCESS 121 DISPATCHED TO CPU
1852ms: PROCESS 46 ADDED TO READY QUEUE
