0ms: PROCESS 0 ADDED TO READY QUEUE
0ms: PROCESS 1 ADDED TO READY QUEUE
0ms: PROCESS 2 ADDED TO READY QUEUE
0ms: PROCESS 0 DISPATCHED TO CPU
2ms: PROCESS 0 PREMPTED
2ms: PROCESS 1 DISPATCHED TO CPU
2ms: PROCESS 0 ADDED TO READY QUEUE
4ms: PROCESS 1 PREMPTED
4ms: PROCESS 2 DISPATCHED TO CPU
4ms: PROCESS 1 ADDED TO READY QUEUE
6ms: PROCESS 2 PREMPTED
6ms: PROCESS 0 DISPATCHED TO CPU
6ms: PROCESS 2 ADDED TO READY QUEUE
8ms: PROCESS 0 PREMPTED
8ms: PROCESS 1 DISPATCHED TO CPU
8ms: PROCESS 0 ADDED TO READY QUEUE
10ms: PROCESS 1 PREMPTED
10ms: PROCESS 2 DISPATCHED TO CPU
10ms: PROCESS 1 ADDED TO READY QUEUE
12ms: PROCESS 2 PREMPTED
12ms: PROCESS 0 DISPATCHED TO CPU
12ms: PROCESS 2 ADDED TO READY QUEUE
14ms: PROCESS 0 PREMPTED
14ms: PROCESS 1 DISPATCHED TO CPU
14ms: PROCESS 0 ADDED TO READY QUEUE
16ms: PROCESS 1 PREMPTED
16ms: PROCESS 2 DISPATCHED TO CPU
16ms: PROCESS 1 ADDED TO READY QUEUE
18ms: PROCESS 2 PREMPTED
18ms: PROCESS 0 DISPATCHED TO CPU
18ms: PROCESS 2 ADDED TO READY QUEUE
20ms: PROCESS 0 PREMPTED
20ms: PROCESS 1 DISPATCHED TO CPU
20ms: PROCESS 0 ADDED TO READY QUEUE
22ms: PROCESS 1 PREMPTED
22ms: PROCESS 2 DISPATCHED TO CPU
22ms: PROCESS 1 ADDED TO READY QUEUE
24ms: PROCESS 2 PREMPTED
24ms: PROCESS 0 DISPATCHED TO CPU
24ms: PROCESS 2 ADDED TO READY QUEUE
26ms: PROCESS 0 PREMPTED
26ms: PROCESS 1 DISPATCHED TO CPU
26ms: PROCESS 0 ADDED TO READY QUEUE
28ms: PROCESS 1 PREMPTED
28ms: PROCESS 2 DISPATCHED TO CPU
28ms: PROCESS 1 ADDED TO READY QUEUE
30ms: PROCESS 2 PREMPTED
30ms: PROCESS 0 DISPATCHED TO CPU
30ms: PROCESS 2 ADDED TO READY QUEUE
32ms: PROCESS 0 PREMPTED
32ms: PROCESS 1 DISPATCHED TO CPU
32ms: PROCESS 0 ADDED TO READY QUEUE
34ms: PROCESS 1 PREMPTED
34ms: PROCESS 2 DISPATCHED TO CPU
34ms: PROCESS 1 ADDED TO READY QUEUE
36ms: PROCESS 2 PREMPTED
36ms: PROCESS 0 DISPATCHED TO CPU
36ms: PROCESS 2 ADDED TO READY QUEUE
38ms: PROCESS 0 PREMPTED
38ms: PROCESS 1 DISPATCHED TO CPU
38ms: PROCESS 0 ADDED TO READY QUEUE
40ms: PROCESS 1 PREMPTED
40ms: PROCESS 2 DISPATCHED TO CPU
40ms: PROCESS 1 ADDED TO READY QUEUE
42ms: PROCESS 2 PREMPTED
42ms: PROCESS 0 DISPATCHED TO CPU
42ms: PROCESS 2 ADDED TO READY QUEUE
43ms: PROCESS 0 FINISHED, TURNAROUND: 0ms, CPU WAIT: 29ms, IO WAIT: 0ms
43ms: PROCESS 1 DISPATCHED TO CPU
46ms: PROCESS 1 PREMPTED
46ms: PROCESS 2 DISPATCHED TO CPU
46ms: PROCESS 1 ADDED TO READY QUEUE
48ms: PROCESS 2 PREMPTED
48ms: PROCESS 1 DISPATCHED TO CPU
48ms: PROCESS 2 ADDED TO READY QUEUE
49ms: PROCESS 1 FINISHED, TURNAROUND: 0ms, CPU WAIT: 32ms, IO WAIT: 0ms
49ms: PROCESS 2 DISPATCHED TO CPU
51ms: PROCESS 2 FINISHED, TURNAROUND: 0ms, CPU WAIT: 34ms, IO WAIT: 0ms
