0ms: PROCESS 1 ADDED TO READY QUEUE
0ms: PROCESS 1 DISPATCHED TO CPU
5ms: PROCESS 2 ADDED TO READY QUEUE
6ms: PROCESS 3 ADDED TO READY QUEUE
8ms: PROCESS 5 ADDED TO READY QUEUE
12ms: PROCESS 1 FINISHED, TURNAROUND: 13ms, CPU WAIT: 1ms, IO WAIT: 0ms
12ms: PROCESS 2 DISPATCHED TO CPU
14ms: PROCESS 0 ADDED TO READY QUEUE
14ms: PROCESS 4 ADDED TO READY QUEUE
26ms: PROCESS 2 SENT TO IO QUEUE
26ms: PROCESS 3 DISPATCHED TO CPU
42ms: PROCESS 3 SENT TO IO QUEUE
42ms: PROCESS 5 DISPATCHED TO CPU
46ms: PROCESS 2 ADDED TO READY QUEUE
46ms: PROCESS 2 DONE WITH IO
49ms: PROCESS 5 FINISHED, TURNAROUND: 42ms, CPU WAIT: 35ms, IO WAIT: 0ms
49ms: PROCESS 0 DISPATCHED TO CPU
51ms: PROCESS 0 SENT TO IO QUEUE
51ms: PROCESS 4 DISPATCHED TO CPU
54ms: PROCESS 3 ADDED TO READY QUEUE
54ms: PROCESS 3 DONE WITH IO
67ms: PROCESS 4 SENT TO IO QUEUE
67ms: PROCESS 2 DISPATCHED TO CPU
77ms: PROCESS 0 ADDED TO READY QUEUE
77ms: PROCESS 0 DONE WITH IO
78ms: PROCESS 2 SENT TO IO QUEUE
78ms: PROCESS 3 DISPATCHED TO CPU
78ms: PROCESS 4 ADDED TO READY QUEUE
78ms: PROCESS 4 DONE WITH IO
85ms: PROCESS 3 SENT TO IO QUEUE
85ms: PROCESS 0 DISPATCHED TO CPU
99ms: PROCESS 2 ADDED TO READY QUEUE
99ms: PROCESS 2 DONE WITH IO
101ms: PROCESS 3 ADDED TO READY QUEUE
101ms: PROCESS 3 DONE WITH IO
107ms: PROCESS 0 FINISHED, TURNAROUND: 94ms, CPU WAIT: 44ms, IO WAIT: 26ms
107ms: PROCESS 4 DISPATCHED TO CPU
110ms: PROCESS 4 FINISHED, TURNAROUND: 97ms, CPU WAIT: 67ms, IO WAIT: 11ms
110ms: PROCESS 2 DISPATCHED TO CPU
134ms: PROCESS 2 SENT TO IO QUEUE
134ms: PROCESS 3 DISPATCHED TO CPU
135ms: PROCESS 2 ADDED TO READY QUEUE
135ms: PROCESS 2 DONE WITH IO
153ms: PROCESS 3 SENT TO IO QUEUE
153ms: PROCESS 2 DISPATCHED TO CPU
156ms: PROCESS 3 ADDED TO READY QUEUE
156ms: PROCESS 3 DONE WITH IO
175ms: PROCESS 2 SENT TO IO QUEUE
175ms: PROCESS 3 DISPATCHED TO CPU
191ms: PROCESS 2 ADDED TO READY QUEUE
191ms: PROCESS 2 DONE WITH IO
192ms: PROCESS 3 SENT TO IO QUEUE
192ms: PROCESS 2 DISPATCHED TO CPU
198ms: PROCESS 2 SENT TO IO QUEUE
200ms: PROCESS 3 ADDED TO READY QUEUE
200ms: PROCESS 3 DONE WITH IO
201ms: PROCESS 3 DISPATCHED TO CPU
221ms: PROCESS 3 SENT TO IO QUEUE
224ms: PROCESS 2 ADDED TO READY QUEUE
224ms: PROCESS 2 DONE WITH IO
225ms: PROCESS 2 DISPATCHED TO CPU
226ms: PROCESS 3 ADDED TO READY QUEUE
226ms: PROCESS 3 DONE WITH IO
231ms: PROCESS 2 SENT TO IO QUEUE
231ms: PROCESS 3 DISPATCHED TO CPU
233ms: PROCESS 2 ADDED TO READY QUEUE
233ms: PROCESS 2 DONE WITH IO
247ms: PROCESS 3 SENT TO IO QUEUE
247ms: PROCESS 2 DISPATCHED TO CPU
249ms: PROCESS 3 ADDED TO READY QUEUE
249ms: PROCESS 3 DONE WITH IO
272ms: PROCESS 2 FINISHED, TURNAROUND: 268ms, CPU WAIT: 74ms, IO WAIT: 86ms
272ms: PROCESS 3 DISPATCHED TO CPU
284ms: PROCESS 3 FINISHED, TURNAROUND: 279ms, CPU WAIT: 126ms, IO WAIT: 46ms
