0ms: PROCESS 4 ADDED TO READY QUEUE
0ms: PROCESS 4 DISPATCHED TO CPU
1ms: PROCESS 0 ADDED TO READY QUEUE
1ms: PROCESS 4 SENT TO IO QUEUE
1ms: PROCESS 0 DISPATCHED TO CPU
2ms: PROCESS 2 ADDED TO READY QUEUE
3ms: PROCESS 8 ADDED TO READY QUEUE
5ms: PROCESS 7 ADDED TO READY QUEUE
5ms: PROCESS 0 SENT TO IO QUEUE
5ms: PROCESS 2 DISPATCHED TO CPU
13ms: PROCESS 9 ADDED TO READY QUEUE
15ms: PROCESS 1 ADDED TO READY QUEUE
15ms: PROCESS 6 ADDED TO READY QUEUE
16ms: PROCESS 5 ADDED TO READY QUEUE
16ms: PROCESS 4 ADDED TO READY QUEUE
16ms: PROCESS 4 DONE WITH IO
19ms: PROCESS 3 ADDED TO READY QUEUE
19ms: PROCESS 2 SENT TO IO QUEUE
19ms: PROCESS 8 DISPATCHED TO CPU
19ms: PROCESS 0 ADDED TO READY QUEUE
19ms: PROCESS 0 DONE WITH IO
32ms: PROCESS 8 SENT TO IO QUEUE
32ms: PROCESS 7 DISPATCHED TO CPU
39ms: PROCESS 2 ADDED TO READY QUEUE
39ms: PROCESS 2 DONE WITH IO
46ms: PROCESS 7 SENT TO IO QUEUE
46ms: PROCESS 9 DISPATCHED TO CPU
52ms: PROCESS 8 ADDED TO READY QUEUE
52ms: PROCESS 8 DONE WITH IO
56ms: PROCESS 7 ADDED TO READY QUEUE
56ms: PROCESS 7 DONE WITH IO
61ms: PROCESS 9 SENT TO IO QUEUE
61ms: PROCESS 1 DISPATCHED TO CPU
85ms: PROCESS 1 FINISHED, TURNAROUND: 0ms, CPU WAIT: 47ms, IO WAIT: 0ms
85ms: PROCESS 6 DISPATCHED TO CPU
85ms: PROCESS 9 ADDED TO READY QUEUE
85ms: PROCESS 9 DONE WITH IO
108ms: PROCESS 6 SENT TO IO QUEUE
108ms: PROCESS 5 DISPATCHED TO CPU
119ms: PROCESS 6 ADDED TO READY QUEUE
119ms: PROCESS 6 DONE WITH IO
121ms: PROCESS 5 SENT TO IO QUEUE
121ms: PROCESS 4 DISPATCHED TO CPU
124ms: PROCESS 5 ADDED TO READY QUEUE
124ms: PROCESS 5 DONE WITH IO
132ms: PROCESS 4 SENT TO IO QUEUE
132ms: PROCESS 3 DISPATCHED TO CPU
138ms: PROCESS 4 ADDED TO READY QUEUE
138ms: PROCESS 4 DONE WITH IO
156ms: PROCESS 3 FINISHED, TURNAROUND: 0ms, CPU WAIT: 114ms, IO WAIT: 0ms
156ms: PROCESS 0 DISPATCHED TO CPU
166ms: PROCESS 0 SENT TO IO QUEUE
166ms: PROCESS 2 DISPATCHED TO CPU
167ms: PROCESS 0 ADDED TO READY QUEUE
167ms: PROCESS 0 DONE WITH IO
186ms: PROCESS 2 SENT TO IO QUEUE
186ms: PROCESS 8 DISPATCHED TO CPU
202ms: PROCESS 8 SENT TO IO QUEUE
202ms: PROCESS 7 DISPATCHED TO CPU
205ms: PROCESS 2 ADDED TO READY QUEUE
205ms: PROCESS 2 DONE WITH IO
210ms: PROCESS 7 SENT TO IO QUEUE
210ms: PROCESS 9 DISPATCHED TO CPU
226ms: PROCESS 8 ADDED TO READY QUEUE
226ms: PROCESS 8 DONE WITH IO
234ms: PROCESS 9 SENT TO IO QUEUE
234ms: PROCESS 6 DISPATCHED TO CPU
245ms: PROCESS 7 ADDED TO READY QUEUE
245ms: PROCESS 7 DONE WITH IO
249ms: PROCESS 6 SENT TO IO QUEUE
249ms: PROCESS 5 DISPATCHED TO CPU
252ms: PROCESS 5 SENT TO IO QUEUE
252ms: PROCESS 4 DISPATCHED TO CPU
264ms: PROCESS 4 SENT TO IO QUEUE
264ms: PROCESS 0 DISPATCHED TO CPU
265ms: PROCESS 9 ADDED TO READY QUEUE
265ms: PROCESS 9 DONE WITH IO
274ms: PROCESS 6 ADDED TO READY QUEUE
274ms: PROCESS 6 DONE WITH IO
283ms: PROCESS 5 ADDED TO READY QUEUE
283ms: PROCESS 5 DONE WITH IO
284ms: PROCESS 0 FINISHED, TURNAROUND: 0ms, CPU WAIT: 235ms, IO WAIT: 15ms
284ms: PROCESS 2 DISPATCHED TO CPU
299ms: PROCESS 4 ADDED TO READY QUEUE
299ms: PROCESS 4 DONE WITH IO
303ms: PROCESS 2 SENT TO IO QUEUE
303ms: PROCESS 8 DISPATCHED TO CPU
324ms: PROCESS 8 SENT TO IO QUEUE
324ms: PROCESS 7 DISPATCHED TO CPU
324ms: PROCESS 2 ADDED TO READY QUEUE
324ms: PROCESS 2 DONE WITH IO
327ms: PROCESS 7 SENT TO IO QUEUE
327ms: PROCESS 9 DISPATCHED TO CPU
345ms: PROCESS 8 ADDED TO READY QUEUE
345ms: PROCESS 8 DONE WITH IO
348ms: PROCESS 9 SENT TO IO QUEUE
348ms: PROCESS 6 DISPATCHED TO CPU
351ms: PROCESS 7 ADDED TO READY QUEUE
351ms: PROCESS 7 DONE WITH IO
358ms: PROCESS 9 ADDED TO READY QUEUE
358ms: PROCESS 9 DONE WITH IO
359ms: PROCESS 6 FINISHED, TURNAROUND: 0ms, CPU WAIT: 260ms, IO WAIT: 36ms
359ms: PROCESS 5 DISPATCHED TO CPU
374ms: PROCESS 5 FINISHED, TURNAROUND: 0ms, CPU WAIT: 294ms, IO WAIT: 34ms
374ms: PROCESS 4 DISPATCHED TO CPU
379ms: PROCESS 4 SENT TO IO QUEUE
379ms: PROCESS 2 DISPATCHED TO CPU
386ms: PROCESS 4 ADDED TO READY QUEUE
386ms: PROCESS 4 DONE WITH IO
399ms: PROCESS 2 SENT TO IO QUEUE
399ms: PROCESS 8 DISPATCHED TO CPU
401ms: PROCESS 2 ADDED TO READY QUEUE
401ms: PROCESS 2 DONE WITH IO
409ms: PROCESS 8 SENT TO IO QUEUE
409ms: PROCESS 7 DISPATCHED TO CPU
410ms: PROCESS 8 ADDED TO READY QUEUE
410ms: PROCESS 8 DONE WITH IO
412ms: PROCESS 7 SENT TO IO QUEUE
412ms: PROCESS 9 DISPATCHED TO CPU
419ms: PROCESS 7 ADDED TO READY QUEUE
419ms: PROCESS 7 DONE WITH IO
436ms: PROCESS 9 SENT TO IO QUEUE
436ms: PROCESS 4 DISPATCHED TO CPU
444ms: PROCESS 4 FINISHED, TURNAROUND: 0ms, CPU WAIT: 345ms, IO WAIT: 63ms
444ms: PROCESS 2 DISPATCHED TO CPU
448ms: PROCESS 9 ADDED TO READY QUEUE
448ms: PROCESS 9 DONE WITH IO
468ms: PROCESS 2 SENT TO IO QUEUE
468ms: PROCESS 8 DISPATCHED TO CPU
475ms: PROCESS 8 SENT TO IO QUEUE
475ms: PROCESS 7 DISPATCHED TO CPU
483ms: PROCESS 7 SENT TO IO QUEUE
483ms: PROCESS 9 DISPATCHED TO CPU
485ms: PROCESS 2 ADDED TO READY QUEUE
485ms: PROCESS 2 DONE WITH IO
495ms: PROCESS 8 ADDED TO READY QUEUE
495ms: PROCESS 8 DONE WITH IO
501ms: PROCESS 9 SENT TO IO QUEUE
501ms: PROCESS 2 DISPATCHED TO CPU
507ms: PROCESS 7 ADDED TO READY QUEUE
507ms: PROCESS 7 DONE WITH IO
513ms: PROCESS 2 SENT TO IO QUEUE
513ms: PROCESS 8 DISPATCHED TO CPU
519ms: PROCESS 9 ADDED TO READY QUEUE
519ms: PROCESS 9 DONE WITH IO
520ms: PROCESS 2 ADDED TO READY QUEUE
520ms: PROCESS 2 DONE WITH IO
524ms: PROCESS 8 FINISHED, TURNAROUND: 0ms, CPU WAIT: 358ms, IO WAIT: 86ms
524ms: PROCESS 7 DISPATCHED TO CPU
547ms: PROCESS 7 SENT TO IO QUEUE
547ms: PROCESS 9 DISPATCHED TO CPU
553ms: PROCESS 9 SENT TO IO QUEUE
553ms: PROCESS 2 DISPATCHED TO CPU
555ms: PROCESS 7 ADDED TO READY QUEUE
555ms: PROCESS 7 DONE WITH IO
568ms: PROCESS 2 SENT TO IO QUEUE
568ms: PROCESS 7 DISPATCHED TO CPU
569ms: PROCESS 7 SENT TO IO QUEUE
574ms: PROCESS 9 ADDED TO READY QUEUE
574ms: PROCESS 9 DONE WITH IO
575ms: PROCESS 9 DISPATCHED TO CPU
586ms: PROCESS 9 SENT TO IO QUEUE
586ms: PROCESS 2 ADDED TO READY QUEUE
586ms: PROCESS 2 DONE WITH IO
587ms: PROCESS 2 DISPATCHED TO CPU
605ms: PROCESS 7 ADDED TO READY QUEUE
605ms: PROCESS 7 DONE WITH IO
607ms: PROCESS 2 SENT TO IO QUEUE
607ms: PROCESS 7 DISPATCHED TO CPU
619ms: PROCESS 7 SENT TO IO QUEUE
620ms: PROCESS 9 ADDED TO READY QUEUE
620ms: PROCESS 9 DONE WITH IO
621ms: PROCESS 9 DISPATCHED TO CPU
621ms: PROCESS 2 ADDED TO READY QUEUE
621ms: PROCESS 2 DONE WITH IO
629ms: PROCESS 7 ADDED TO READY QUEUE
629ms: PROCESS 7 DONE WITH IO
635ms: PROCESS 9 FINISHED, TURNAROUND: 0ms, CPU WAIT: 340ms, IO WAIT: 150ms
635ms: PROCESS 2 DISPATCHED TO CPU
660ms: PROCESS 2 SENT TO IO QUEUE
660ms: PROCESS 7 DISPATCHED TO CPU
672ms: PROCESS 2 ADDED TO READY QUEUE
672ms: PROCESS 2 DONE WITH IO
682ms: PROCESS 7 SENT TO IO QUEUE
682ms: PROCESS 2 DISPATCHED TO CPU
688ms: PROCESS 7 ADDED TO READY QUEUE
688ms: PROCESS 7 DONE WITH IO
706ms: PROCESS 2 SENT TO IO QUEUE
706ms: PROCESS 7 DISPATCHED TO CPU
707ms: PROCESS 2 ADDED TO READY QUEUE
707ms: PROCESS 2 DONE WITH IO
710ms: PROCESS 7 FINISHED, TURNAROUND: 0ms, CPU WAIT: 448ms, IO WAIT: 160ms
710ms: PROCESS 2 DISPATCHED TO CPU
711ms: PROCESS 2 FINISHED, TURNAROUND: 0ms, CPU WAIT: 385ms, IO WAIT: 131ms
