4ms: PROCESS 0 ADDED TO READY QUEUE
4ms: PROCESS 0 DISPATCHED TO CPU
15ms: PROCESS 1 ADDED TO READY QUEUE
19ms: PROCESS 0 SENT TO IO QUEUE
19ms: PROCESS 1 DISPATCHED TO CPU
27ms: PROCESS 1 SENT TO IO QUEUE
39ms: PROCESS 0 ADDED TO READY QUEUE
39ms: PROCESS 0 DONE WITH IO
40ms: PROCESS 0 DISPATCHED TO CPU
53ms: PROCESS 1 ADDED TO READY QUEUE
53ms: PROCESS 1 DONE WITH IO
64ms: PROCESS 0 SENT TO IO QUEUE
64ms: PROCESS 1 DISPATCHED TO CPU
67ms: PROCESS 0 ADDED TO READY QUEUE
67ms: PROCESS 0 DONE WITH IO
89ms: PROCESS 1 SENT TO IO QUEUE
89ms: PROCESS 0 DISPATCHED TO CPU
97ms: PROCESS 0 SENT TO IO QUEUE
97ms: PROCESS 1 ADDED TO READY QUEUE
97ms: PROCESS 1 DONE WITH IO
98ms: PROCESS 1 DISPATCHED TO CPU
99ms: PROCESS 1 SENT TO IO QUEUE
115ms: PROCESS 0 ADDED TO READY QUEUE
115ms: PROCESS 0 DONE WITH IO
116ms: PROCESS 0 DISPATCHED TO CPU
127ms: PROCESS 1 ADDED TO READY QUEUE
127ms: PROCESS 1 DONE WITH IO
139ms: PROCESS 0 SENT TO IO QUEUE
139ms: PROCESS 1 DISPATCHED TO CPU
144ms: PROCESS 0 ADDED TO READY QUEUE
144ms: PROCESS 0 DONE WITH IO
147ms: PROCESS 1 SENT TO IO QUEUE
147ms: PROCESS 0 DISPATCHED TO CPU
156ms: PROCESS 0 SENT TO IO QUEUE
171ms: PROCESS 1 ADDED TO READY QUEUE
171ms: PROCESS 1 DONE WITH IO
172ms: PROCESS 1 DISPATCHED TO CPU
182ms: PROCESS 1 SENT TO IO QUEUE
191ms: PROCESS 0 ADDED TO READY QUEUE
191ms: PROCESS 0 DONE WITH IO
192ms: PROCESS 0 DISPATCHED TO CPU
205ms: PROCESS 0 SENT TO IO QUEUE
209ms: PROCESS 1 ADDED TO READY QUEUE
209ms: PROCESS 1 DONE WITH IO
210ms: PROCESS 1 DISPATCHED TO CPU
211ms: PROCESS 0 ADDED TO READY QUEUE
211ms: PROCESS 0 DONE WITH IO
229ms: PROCESS 1 SENT TO IO QUEUE
229ms: PROCESS 0 DISPATCHED TO CPU
250ms: PROCESS 0 SENT TO IO QUEUE
252ms: PROCESS 1 ADDED TO READY QUEUE
252ms: PROCESS 1 DONE WITH IO
253ms: PROCESS 1 DISPATCHED TO CPU
271ms: PROCESS 0 ADDED TO READY QUEUE
271ms: PROCESS 0 DONE WITH IO
273ms: PROCESS 1 SENT TO IO QUEUE
273ms: PROCESS 0 DISPATCHED TO CPU
274ms: PROCESS 1 ADDED TO READY QUEUE
274ms: PROCESS 1 DONE WITH IO
287ms: PROCESS 0 SENT TO IO QUEUE
287ms: PROCESS 1 DISPATCHED TO CPU
304ms: PROCESS 1 SENT TO IO QUEUE
307ms: PROCESS 0 ADDED TO READY QUEUE
307ms: PROCESS 0 DONE WITH IO
308ms: PROCESS 0 DISPATCHED TO CPU
320ms: PROCESS 0 SENT TO IO QUEUE
320ms: PROCESS 1 ADDED TO READY QUEUE
320ms: PROCESS 1 DONE WITH IO
321ms: PROCESS 1 DISPATCHED TO CPU
333ms: PROCESS 1 SENT TO IO QUEUE
335ms: PROCESS 0 ADDED TO READY QUEUE
335ms: PROCESS 0 DONE WITH IO
336ms: PROCESS 0 DISPATCHED TO CPU
345ms: PROCESS 1 ADDED TO READY QUEUE
345ms: PROCESS 1 DONE WITH IO
353ms: PROCESS 0 SENT TO IO QUEUE
353ms: PROCESS 1 DISPATCHED TO CPU
360ms: PROCESS 1 FINISHED, TURNAROUND: 0ms, CPU WAIT: 54ms, IO WAIT: 165ms
360ms: PROCESS 0 ADDED TO READY QUEUE
360ms: PROCESS 0 DONE WITH IO
361ms: PROCESS 0 DISPATCHED TO CPU
380ms: PROCESS 0 FINISHED, TURNAROUND: 0ms, CPU WAIT: 52ms, IO WAIT: 150ms
