3ms: PROCESS 2 ADDED TO READY QUEUE
3ms: PROCESS 2 DISPATCHED TO CPU
5ms: PROCESS 0 ADDED TO READY QUEUE
17ms: PROCESS 3 ADDED TO READY QUEUE
18ms: PROCESS 4 ADDED TO READY QUEUE
21ms: PROCESS 1 ADDED TO READY QUEUE
25ms: PROCESS 2 SENT TO IO QUEUE
25ms: PROCESS 0 DISPATCHED TO CPU
34ms: PROCESS 0 SENT TO IO QUEUE
34ms: PROCESS 3 DISPATCHED TO CPU
37ms: PROCESS 2 ADDED TO READY QUEUE
37ms: PROCESS 2 DONE WITH IO
45ms: PROCESS 3 SENT TO IO QUEUE
45ms: PROCESS 4 DISPATCHED TO CPU
53ms: PROCESS 0 ADDED TO READY QUEUE
53ms: PROCESS 0 DONE WITH IO
54ms: PROCESS 4 SENT TO IO QUEUE
54ms: PROCESS 1 DISPATCHED TO CPU
55ms: PROCESS 3 ADDED TO READY QUEUE
55ms: PROCESS 3 DONE WITH IO
59ms: PROCESS 4 ADDED TO READY QUEUE
59ms: PROCESS 4 DONE WITH IO
76ms: PROCESS 1 SENT TO IO QUEUE
76ms: PROCESS 2 DISPATCHED TO CPU
78ms: PROCESS 1 ADDED TO READY QUEUE
78ms: PROCESS 1 DONE WITH IO
95ms: PROCESS 2 SENT TO IO QUEUE
95ms: PROCESS 0 DISPATCHED TO CPU
97ms: PROCESS 2 ADDED TO READY QUEUE
97ms: PROCESS 2 DONE WITH IO
113ms: PROCESS 0 SENT TO IO QUEUE
113ms: PROCESS 3 DISPATCHED TO CPU
124ms: PROCESS 3 SENT TO IO QUEUE
124ms: PROCESS 4 DISPATCHED TO CPU
127ms: PROCESS 4 SENT TO IO QUEUE
127ms: PROCESS 1 DISPATCHED TO CPU
130ms: PROCESS 1 SENT TO IO QUEUE
130ms: PROCESS 2 DISPATCHED TO CPU
136ms: PROCESS 0 ADDED TO READY QUEUE
136ms: PROCESS 0 DONE WITH IO
145ms: PROCESS 3 ADDED TO READY QUEUE
145ms: PROCESS 3 DONE WITH IO
149ms: PROCESS 2 SENT TO IO QUEUE
149ms: PROCESS 0 DISPATCHED TO CPU
160ms: PROCESS 4 ADDED TO READY QUEUE
160ms: PROCESS 4 DONE WITH IO
164ms: PROCESS 0 SENT TO IO QUEUE
164ms: PROCESS 3 DISPATCHED TO CPU
170ms: PROCESS 1 ADDED TO READY QUEUE
170ms: PROCESS 1 DONE WITH IO
181ms: PROCESS 3 SENT TO IO QUEUE
181ms: PROCESS 4 DISPATCHED TO CPU
191ms: PROCESS 2 ADDED TO READY QUEUE
191ms: PROCESS 2 DONE WITH IO
200ms: PROCESS 4 SENT TO IO QUEUE
200ms: PROCESS 1 DISPATCHED TO CPU
204ms: PROCESS 1 FINISHED, TURNAROUND: 0ms, CPU WAIT: 113ms, IO WAIT: 42ms
204ms: PROCESS 2 DISPATCHED TO CPU
206ms: PROCESS 0 ADDED TO READY QUEUE
206ms: PROCESS 0 DONE WITH IO
210ms: PROCESS 2 SENT TO IO QUEUE
210ms: PROCESS 0 DISPATCHED TO CPU
211ms: PROCESS 3 ADDED TO READY QUEUE
211ms: PROCESS 3 DONE WITH IO
217ms: PROCESS 0 SENT TO IO QUEUE
217ms: PROCESS 3 DISPATCHED TO CPU
217ms: PROCESS 4 ADDED TO READY QUEUE
217ms: PROCESS 4 DONE WITH IO
220ms: PROCESS 2 ADDED TO READY QUEUE
220ms: PROCESS 2 DONE WITH IO
226ms: PROCESS 3 SENT TO IO QUEUE
226ms: PROCESS 4 DISPATCHED TO CPU
238ms: PROCESS 0 ADDED TO READY QUEUE
238ms: PROCESS 0 DONE WITH IO
241ms: PROCESS 4 SENT TO IO QUEUE
241ms: PROCESS 2 DISPATCHED TO CPU
251ms: PROCESS 3 ADDED TO READY QUEUE
251ms: PROCESS 3 DONE WITH IO
260ms: PROCESS 2 SENT TO IO QUEUE
260ms: PROCESS 0 DISPATCHED TO CPU
262ms: PROCESS 0 SENT TO IO QUEUE
262ms: PROCESS 3 DISPATCHED TO CPU
268ms: PROCESS 4 ADDED TO READY QUEUE
268ms: PROCESS 4 DONE WITH IO
273ms: PROCESS 3 SENT TO IO QUEUE
273ms: PROCESS 4 DISPATCHED TO CPU
286ms: PROCESS 4 SENT TO IO QUEUE
290ms: PROCESS 2 ADDED TO READY QUEUE
290ms: PROCESS 2 DONE WITH IO
291ms: PROCESS 2 DISPATCHED TO CPU
299ms: PROCESS 0 ADDED TO READY QUEUE
299ms: PROCESS 0 DONE WITH IO
302ms: PROCESS 2 SENT TO IO QUEUE
302ms: PROCESS 0 DISPATCHED TO CPU
313ms: PROCESS 0 FINISHED, TURNAROUND: 0ms, CPU WAIT: 105ms, IO WAIT: 142ms
313ms: PROCESS 3 ADDED TO READY QUEUE
313ms: PROCESS 3 DONE WITH IO
314ms: PROCESS 3 DISPATCHED TO CPU
326ms: PROCESS 3 SENT TO IO QUEUE
337ms: PROCESS 4 ADDED TO READY QUEUE
337ms: PROCESS 4 DONE WITH IO
338ms: PROCESS 4 DISPATCHED TO CPU
356ms: PROCESS 2 ADDED TO READY QUEUE
356ms: PROCESS 2 DONE WITH IO
362ms: PROCESS 4 SENT TO IO QUEUE
362ms: PROCESS 2 DISPATCHED TO CPU
368ms: PROCESS 3 ADDED TO READY QUEUE
368ms: PROCESS 3 DONE WITH IO
380ms: PROCESS 4 ADDED TO READY QUEUE
380ms: PROCESS 4 DONE WITH IO
382ms: PROCESS 2 SENT TO IO QUEUE
382ms: PROCESS 3 DISPATCHED TO CPU
388ms: PROCESS 3 SENT TO IO QUEUE
388ms: PROCESS 4 DISPATCHED TO CPU
404ms: PROCESS 4 SENT TO IO QUEUE
405ms: PROCESS 2 ADDED TO READY QUEUE
405ms: PROCESS 2 DONE WITH IO
406ms: PROCESS 2 DISPATCHED TO CPU
425ms: PROCESS 3 ADDED TO READY QUEUE
425ms: PROCESS 3 DONE WITH IO
429ms: PROCESS 2 SENT TO IO QUEUE
429ms: PROCESS 3 DISPATCHED TO CPU
446ms: PROCESS 4 ADDED TO READY QUEUE
446ms: PROCESS 4 DONE WITH IO
448ms: PROCESS 3 FINISHED, TURNAROUND: 0ms, CPU WAIT: 131ms, IO WAIT: 205ms
448ms: PROCESS 4 DISPATCHED TO CPU
451ms: PROCESS 2 ADDED TO READY QUEUE
451ms: PROCESS 2 DONE WITH IO
462ms: PROCESS 4 SENT TO IO QUEUE
462ms: PROCESS 2 DISPATCHED TO CPU
464ms: PROCESS 2 FINISHED, TURNAROUND: 0ms, CPU WAIT: 126ms, IO WAIT: 195ms
482ms: PROCESS 4 ADDED TO READY QUEUE
482ms: PROCESS 4 DONE WITH IO
483ms: PROCESS 4 DISPATCHED TO CPU
496ms: PROCESS 4 SENT TO IO QUEUE
518ms: PROCESS 4 ADDED TO READY QUEUE
518ms: PROCESS 4 DONE WITH IO
519ms: PROCESS 4 DISPATCHED TO CPU
527ms: PROCESS 4 FINISHED, TURNAROUND: 0ms, CPU WAIT: 141ms, IO WAIT: 235ms
