8ms: PROCESS 0 ADDED TO READY QUEUE
8ms: PROCESS 0 DISPATCHED TO CPU
16ms: PROCESS 0 SENT TO IO QUEUE
22ms: PROCESS 1 ADDED TO READY QUEUE
22ms: PROCESS 1 DISPATCHED TO CPU
25ms: PROCESS 0 ADDED TO READY QUEUE
25ms: PROCESS 0 DONE WITH IO
26ms: PROCESS 1 SENT TO IO QUEUE
26ms: PROCESS 0 DISPATCHED TO CPU
27ms: PROCESS 1 ADDED TO READY QUEUE
27ms: PROCESS 1 DONE WITH IO
44ms: PROCESS 0 SENT TO IO QUEUE
44ms: PROCESS 1 DISPATCHED TO CPU
47ms: PROCESS 1 SENT TO IO QUEUE
53ms: PROCESS 0 ADDED TO READY QUEUE
53ms: PROCESS 0 DONE WITH IO
54ms: PROCESS 0 DISPATCHED TO CPU
58ms: PROCESS 1 ADDED TO READY QUEUE
58ms: PROCESS 1 DONE WITH IO
74ms: PROCESS 0 SENT TO IO QUEUE
74ms: PROCESS 1 DISPATCHED TO CPU
90ms: PROCESS 1 SENT TO IO QUEUE
90ms: PROCESS 0 ADDED TO READY QUEUE
90ms: PROCESS 0 DONE WITH IO
91ms: PROCESS 0 DISPATCHED TO CPU
92ms: PROCESS 0 SENT TO IO QUEUE
97ms: PROCESS 1 ADDED TO READY QUEUE
97ms: PROCESS 1 DONE WITH IO
98ms: PROCESS 1 DISPATCHED TO CPU
116ms: PROCESS 0 ADDED TO READY QUEUE
116ms: PROCESS 0 DONE WITH IO
119ms: PROCESS 1 SENT TO IO QUEUE
119ms: PROCESS 0 DISPATCHED TO CPU
120ms: PROCESS 0 SENT TO IO QUEUE
132ms: PROCESS 1 ADDED TO READY QUEUE
132ms: PROCESS 1 DONE WITH IO
133ms: PROCESS 1 DISPATCHED TO CPU
145ms: PROCESS 0 ADDED TO READY QUEUE
145ms: PROCESS 0 DONE WITH IO
150ms: PROCESS 1 SENT TO IO QUEUE
150ms: PROCESS 0 DISPATCHED TO CPU
161ms: PROCESS 1 ADDED TO READY QUEUE
161ms: PROCESS 1 DONE WITH IO
165ms: PROCESS 0 SENT TO IO QUEUE
165ms: PROCESS 1 DISPATCHED TO CPU
167ms: PROCESS 1 SENT TO IO QUEUE
187ms: PROCESS 0 ADDED TO READY QUEUE
187ms: PROCESS 0 DONE WITH IO
188ms: PROCESS 0 DISPATCHED TO CPU
203ms: PROCESS 0 SENT TO IO QUEUE
207ms: PROCESS 1 ADDED TO READY QUEUE
207ms: PROCESS 1 DONE WITH IO
208ms: PROCESS 1 DISPATCHED TO CPU
225ms: PROCESS 1 SENT TO IO QUEUE
228ms: PROCESS 0 ADDED TO READY QUEUE
228ms: PROCESS 0 DONE WITH IO
229ms: PROCESS 0 DISPATCHED TO CPU
232ms: PROCESS 1 ADDED TO READY QUEUE
232ms: PROCESS 1 DONE WITH IO
236ms: PROCESS 0 SENT TO IO QUEUE
236ms: PROCESS 1 DISPATCHED TO CPU
240ms: PROCESS 0 ADDED TO READY QUEUE
240ms: PROCESS 0 DONE WITH IO
246ms: PROCESS 1 SENT TO IO QUEUE
246ms: PROCESS 0 DISPATCHED TO CPU
252ms: PROCESS 1 ADDED TO READY QUEUE
252ms: PROCESS 1 DONE WITH IO
254ms: PROCESS 0 SENT TO IO QUEUE
254ms: PROCESS 1 DISPATCHED TO CPU
271ms: PROCESS 0 ADDED TO READY QUEUE
271ms: PROCESS 0 DONE WITH IO
274ms: PROCESS 1 SENT TO IO QUEUE
274ms: PROCESS 0 DISPATCHED TO CPU
289ms: PROCESS 0 SENT TO IO QUEUE
299ms: PROCESS 1 ADDED TO READY QUEUE
299ms: PROCESS 1 DONE WITH IO
300ms: PROCESS 1 DISPATCHED TO CPU
310ms: PROCESS 0 ADDED TO READY QUEUE
310ms: PROCESS 0 DONE WITH IO
319ms: PROCESS 1 FINISHED, TURNAROUND: 298ms, CPU WAIT: 48ms, IO WAIT: 121ms
319ms: PROCESS 0 DISPATCHED TO CPU
333ms: PROCESS 0 FINISHED, TURNAROUND: 326ms, CPU WAIT: 32ms, IO WAIT: 172ms
